
# Created by Ruins mod version 15.0 Ingame Parser
# authoring Player: SunsOfOld

weight=100
embed_into_distance=6
acceptable_target_blocks=
unacceptable_target_blocks=flowing_water,water,flowing_lava,lava
dimensions=11,7,7
allowable_overhang=0
max_leveling=3
leveling_buffer=0
preserve_water=0
preserve_lava=0
uniqueMinDistance=1000000
preventRotation=1

rule1=0,100,preserveBlock
rule2=0,100,UndergroundBiomes:metamorphicCobblestone-1
rule3=0,100,IInventory;minecraft:chest;Backpack:backpack#{backpack-UID:"7f910d19-92c5-4691-b48b-e643ae691c52",name:"item.backpack.green.name",}#3#13-4
rule4=0,100,minecraft:ladder-5
rule5=0,100,GardenStuff:moss_brick-1
rule6=0,100,minecraft:water-8
rule7=0,100,minecraft:gravel-0
rule8=0,100,GardenStuff:moss_brick-2
rule9=0,100,GardenStuff:moss_brick-6
rule10=0,100,GardenStuff:moss_brick-4
rule11=0,100,GardenStuff:moss_brick-3
rule12=0,100,GardenStuff:moss_brick-0
rule13=0,100,minecraft:water-0
rule14=0,100,minecraft:web-0
rule15=0,100,GardenStuff:fence-3

layer
1,1,1,1,1,1,1
1,1,2,2,2,2,1
1,1,2,2,2,2,1
1,1,2,2,2,2,1
1,1,2,2,2,2,1
1,1,1,1,1,1,1
1,1,1,1,1,1,1
endlayer

layer
1,1,1,1,1,1,1
1,1,2,2,2,2,1
1,1,2,0,0,2,1
1,1,2,3,0,2,1
1,1,2,2,2,2,1
1,1,1,1,1,1,1
1,1,1,1,1,1,1
endlayer

layer
1,1,1,1,1,1,1
1,1,2,2,2,2,1
1,1,2,0,0,2,1
1,1,2,0,0,2,1
1,1,2,2,2,2,1
1,1,1,1,1,1,1
1,1,1,1,1,1,1
endlayer

layer
1,1,1,1,1,1,1
1,1,2,2,2,2,1
1,1,2,0,4,2,1
1,1,2,0,0,2,1
1,1,2,2,2,2,1
1,1,1,1,1,1,1
1,1,1,1,1,1,1
endlayer

layer
1,1,1,1,1,1,1
1,1,2,2,2,2,1
1,1,2,2,0,2,1
1,1,2,2,2,2,1
1,1,2,2,2,2,1
1,1,1,1,1,1,1
1,1,1,1,1,1,1
endlayer

layer
1,1,1,1,1,1,1
1,1,2,2,2,2,1
1,7,2,6,5,2,1
1,1,2,7,6,2,1
7,1,2,2,2,2,1
1,1,1,1,1,1,1
7,1,1,1,7,1,1
endlayer

layer
0,11,10,5,8,9,8
0,10,12,9,9,12,5
5,0,8,13,13,8,10
0,5,7,13,13,9,8
0,12,12,9,8,5,5
5,10,11,7,12,10,11
0,0,0,10,0,0,0
endlayer

layer
0,0,0,0,0,0,0
0,0,8,14,12,9,0
0,0,0,0,0,5,0
0,7,0,0,0,9,0
0,0,5,0,5,9,0
0,0,0,0,0,0,0
0,0,0,0,0,0,0
endlayer

layer
0,0,0,0,0,0,0
0,0,15,0,14,15,0
0,0,0,0,0,14,0
0,0,0,0,0,0,0
0,0,15,0,0,15,0
0,0,0,0,0,0,0
0,0,0,0,0,0,0
endlayer

layer
0,0,0,0,0,0,0
0,0,15,15,15,15,0
0,0,0,0,0,15,0
0,0,0,0,0,15,0
0,0,15,0,15,15,0
0,0,0,0,0,0,0
0,0,0,0,0,0,0
endlayer

layer
0,0,0,0,0,0,0
0,0,12,10,11,5,0
0,0,0,5,14,9,0
0,0,0,0,12,11,0
0,0,0,0,10,11,0
0,0,0,0,0,0,0
0,0,0,0,0,0,0
endlayer

