
# Created by Ruins mod version 15.0 Ingame Parser
# authoring Player: SunsOfOld

weight=100
embed_into_distance=4
acceptable_target_blocks=
unacceptable_target_blocks=flowing_water,water,flowing_lava,lava
dimensions=9,7,6
allowable_overhang=0
max_leveling=3
leveling_buffer=0
preserve_water=0
preserve_lava=0
uniqueMinDistance=1000000
preventRotation=1

rule1=0,100,preserveBlock
rule2=0,100,UndergroundBiomes:metamorphicCobblestone-1
rule3=0,100,minecraft:gravel-0
rule4=0,100,IInventory;minecraft:chest;Backpack:backpack#{backpack-UID:"a6cb2b61-5637-4626-99bb-6df1ab654d85",name:"item.backpack.green.name",}#3#0-5
rule5=0,100,chisel:mossy_cobblestone-12
rule6=0,100,minecraft:stonebrick-1
rule7=0,100,chisel:mossy_cobblestone-1
rule8=0,100,GardenStuff:moss_brick-4
rule9=0,100,minecraft:stonebrick-2
rule10=0,100,chisel:mossy_cobblestone-4
rule11=0,100,minecraft:oak_stairs-2
rule12=0,100,minecraft:oak_stairs-1
rule13=0,100,minecraft:oak_stairs-3

layer
1,1,1,1,1,1
1,2,2,2,2,1
1,2,2,2,2,1
1,2,2,2,2,1
1,2,2,2,2,1
1,2,2,2,2,1
1,1,1,1,1,1
endlayer

layer
1,1,1,1,1,1
1,2,2,2,2,1
1,2,4,3,2,1
1,2,2,3,2,1
1,2,3,3,2,1
1,2,2,2,2,1
1,1,1,1,1,1
endlayer

layer
1,1,1,1,1,1
1,2,2,2,2,1
1,2,3,3,2,1
1,2,0,0,2,1
1,2,0,0,2,1
1,2,2,2,2,1
1,1,1,1,1,1
endlayer

layer
3,1,1,3,1,3
1,2,2,2,2,1
1,2,3,0,2,1
3,2,0,0,2,1
1,2,0,0,2,1
1,2,2,2,2,3
1,1,1,1,1,1
endlayer

layer
0,3,0,0,0,0
0,5,7,6,5,0
0,7,0,5,2,3
0,8,5,5,2,3
3,6,5,5,3,3
0,5,10,9,5,0
3,0,13,12,11,0
endlayer

layer
0,0,0,0,0,0
0,10,0,3,8,0
0,3,0,0,10,0
0,0,0,3,3,0
0,0,0,0,8,0
0,3,6,0,6,0
0,0,0,0,0,0
endlayer

layer
0,0,0,0,0,0
0,0,0,0,3,0
0,0,0,0,9,0
0,0,0,0,0,0
0,0,0,0,6,0
0,0,3,0,3,0
0,0,0,0,0,0
endlayer

layer
0,0,0,0,0,0
0,0,0,0,0,0
0,0,0,0,7,0
0,0,0,0,6,0
0,0,0,0,0,0
0,0,0,0,0,0
0,0,0,0,0,0
endlayer

layer
0,0,0,0,0,0
0,0,0,0,0,0
0,0,0,0,0,0
0,0,0,0,3,0
0,0,0,0,0,0
0,0,0,0,0,0
0,0,0,0,0,0
endlayer

