
# Created by Ruins mod version 15.0 Ingame Parser
# authoring Player: SunsOfOld

weight=100
embed_into_distance=8
acceptable_target_blocks=
unacceptable_target_blocks=flowing_water,water,flowing_lava,lava
dimensions=16,34,20
allowable_overhang=0
max_leveling=6
leveling_buffer=0
preserve_water=0
preserve_lava=0
uniqueMinDistance=1000000
preventRotation=1

rule1=0,100,preserveBlock
rule2=0,100,BiomesOPlenty:ashStone-0
rule3=0,100,minecraft:lava-0
rule4=0,100,minecraft:lava-2
rule5=2,100,minecraft:redstone_torch-3
rule6=0,100,minecraft:sticky_piston-11
rule7=2,100,minecraft:piston_head-11
rule8=2,100,minecraft:piston_head-10
rule9=0,100,minecraft:sticky_piston-10
rule10=2,100,minecraft:redstone_torch-4
rule11=0,100,minecraft:grass-0
rule12=0,100,chisel:fantasyblock-2
rule13=0,100,chisel:grimstone-12
rule14=0,100,minecraft:redstone_wire-0
rule15=0,100,minecraft:wooden_pressure_plate-0
rule16=0,100,minecraft:unpowered_repeater-3
rule17=0,100,minecraft:unpowered_repeater-1
rule18=1,100,minecraft:torch-5
rule19=0,100,minecraft:iron_bars-0
rule20=0,100,IInventory;minecraft:trapped_chest;plantmegapack:bambooTropicalBluePole#1#0#22-4
rule21=0,100,minecraft:trapped_chest-4
rule22=0,100,minecraft:quartz_stairs-7
rule23=0,100,minecraft:quartz_stairs-6
rule24=0,100,minecraft:quartz_stairs-2
rule25=0,100,minecraft:quartz_stairs-3
rule26=0,100,minecraft:quartz_stairs-1
rule27=0,100,minecraft:stone_slab-7
rule28=0,100,minecraft:stone_slab-15
rule29=0,100,minecraft:quartz_stairs-0

layer
1,1,1,1,1,1,1,1,1,1,1,1,1,1,1,1,1,1,1,1
1,1,1,1,1,1,1,1,1,1,1,1,1,1,1,1,1,1,1,1
1,1,1,1,1,1,1,1,1,1,1,1,1,1,1,1,1,1,1,1
1,1,1,1,1,1,1,1,1,1,1,1,1,1,1,1,1,1,1,1
1,1,1,1,1,1,1,1,1,1,1,1,1,1,1,1,1,1,1,1
1,1,1,1,1,1,1,1,1,1,1,1,1,1,1,1,1,1,1,1
1,1,1,1,1,1,1,1,1,1,1,1,1,1,1,1,1,1,1,1
1,1,1,1,1,1,1,1,1,2,2,1,1,1,1,1,1,1,1,1
1,1,1,1,1,1,1,1,1,2,2,1,1,1,1,1,1,1,1,1
1,1,1,1,1,1,1,1,1,2,2,1,1,1,1,1,1,1,1,1
1,1,1,1,1,1,1,1,1,2,2,1,1,1,1,1,1,1,1,1
1,1,1,1,1,1,1,1,1,2,2,1,1,1,1,1,1,1,1,1
1,1,1,1,1,1,1,1,1,2,2,1,1,1,1,1,1,1,1,1
1,1,1,1,1,1,1,1,1,2,2,1,1,1,1,1,1,1,1,1
1,1,1,1,1,1,1,1,1,2,2,1,1,1,1,1,1,1,1,1
1,1,1,1,1,1,1,1,1,2,2,1,1,1,1,1,1,1,1,1
1,1,1,1,1,1,1,1,1,2,2,1,1,1,1,1,1,1,1,1
1,1,1,1,1,1,1,1,1,2,2,1,1,1,1,1,1,1,1,1
1,1,1,1,1,1,1,1,1,2,2,1,1,1,1,1,1,1,1,1
1,1,1,1,1,1,1,1,1,2,2,1,1,1,1,1,1,1,1,1
1,1,1,1,1,1,1,1,1,2,2,1,1,1,1,1,1,1,1,1
1,1,1,1,1,1,1,1,1,2,2,1,1,1,1,1,1,1,1,1
1,1,1,1,1,1,1,1,1,1,1,1,1,1,1,1,1,1,1,1
1,1,1,1,1,1,1,1,1,1,1,1,1,1,1,1,1,1,1,1
1,1,1,1,1,1,1,1,1,1,1,1,1,1,1,1,1,1,1,1
1,1,1,1,1,1,1,1,1,1,1,1,1,1,1,1,1,1,1,1
1,1,1,1,1,1,1,1,1,1,1,1,1,1,1,1,1,1,1,1
1,1,1,1,1,1,1,1,1,1,1,1,1,1,1,1,1,1,1,1
1,1,1,1,1,1,1,1,1,1,1,1,1,1,1,1,1,1,1,1
1,1,1,1,1,1,1,1,1,1,1,1,1,1,1,1,1,1,1,1
1,1,1,1,1,1,1,1,1,1,1,1,1,1,1,1,1,1,1,1
1,1,1,1,1,1,1,1,1,1,1,1,1,1,1,1,1,1,1,1
1,1,1,1,1,1,1,1,1,1,1,1,1,1,1,1,1,1,1,1
1,1,1,1,1,1,1,1,1,1,1,1,1,1,1,1,1,1,1,1
endlayer

layer
1,1,1,1,1,1,1,1,1,1,1,1,1,1,1,1,1,1,1,1
1,1,1,1,1,1,1,1,1,1,1,1,1,1,1,1,1,1,1,1
1,1,1,1,1,1,1,1,1,1,1,1,1,1,1,1,1,1,1,1
1,1,1,1,1,1,1,1,1,1,1,1,1,1,1,1,1,1,1,1
1,1,1,1,1,1,1,1,1,1,1,1,1,1,1,1,1,1,1,1
1,1,1,1,1,1,1,1,1,1,1,1,1,1,1,1,1,1,1,1
1,1,1,1,1,1,1,1,1,1,1,1,1,1,1,1,1,1,1,1
1,1,1,1,1,1,1,1,2,2,2,2,1,1,1,1,1,1,1,1
1,1,1,1,1,1,1,1,2,3,3,2,1,1,1,1,1,1,1,1
1,1,1,1,1,1,1,1,2,3,3,2,1,1,1,1,1,1,1,1
1,1,1,1,1,1,1,1,2,3,3,2,1,1,1,1,1,1,1,1
1,1,1,1,1,1,1,1,2,3,3,2,1,1,1,1,1,1,1,1
1,1,1,1,1,1,1,1,2,3,3,2,1,1,1,1,1,1,1,1
1,1,1,1,1,1,1,1,2,3,3,2,1,1,1,1,1,1,1,1
1,1,1,1,1,1,1,1,2,3,3,2,1,1,1,1,1,1,1,1
1,1,1,1,1,1,1,1,2,3,3,2,1,1,1,1,1,1,1,1
1,1,1,1,1,1,1,1,2,3,3,2,1,1,1,1,1,1,1,1
1,1,1,1,1,1,1,1,2,3,3,2,1,1,1,1,1,1,1,1
1,1,1,1,1,1,1,1,2,3,3,2,1,1,1,1,1,1,1,1
1,1,1,1,1,1,1,1,2,3,4,2,1,1,1,1,1,1,1,1
1,1,1,1,1,1,1,1,2,3,3,2,1,1,1,1,1,1,1,1
1,1,1,1,1,1,1,1,2,2,2,2,1,1,1,1,1,1,1,1
1,1,1,1,1,1,1,1,1,1,1,1,1,1,1,1,1,1,1,1
1,1,1,1,1,1,1,1,1,1,1,1,1,1,1,1,1,1,1,1
1,1,1,1,1,1,1,1,1,1,1,1,1,1,1,1,1,1,1,1
1,1,1,1,1,1,1,1,1,1,1,1,1,1,1,1,1,1,1,1
1,1,1,1,1,1,1,1,1,1,1,1,1,1,1,1,1,1,1,1
1,1,1,1,1,1,1,1,1,1,1,1,1,1,1,1,1,1,1,1
1,1,1,1,1,1,1,1,1,1,1,1,1,1,1,1,1,1,1,1
1,1,1,1,1,1,1,1,1,1,1,1,1,1,1,1,1,1,1,1
1,1,1,1,1,1,1,1,1,1,1,1,1,1,1,1,1,1,1,1
1,1,1,1,1,1,1,1,1,1,1,1,1,1,1,1,1,1,1,1
1,1,1,1,1,1,1,1,1,1,1,1,1,1,1,1,1,1,1,1
1,1,1,1,1,1,1,1,1,1,1,1,1,1,1,1,1,1,1,1
endlayer

layer
1,1,1,1,1,1,1,1,1,1,1,1,1,1,1,1,1,1,1,1
1,1,1,1,1,1,1,1,1,1,1,1,1,1,1,1,1,1,1,1
1,1,1,1,1,1,1,1,1,1,1,1,1,1,1,1,1,1,1,1
1,1,1,1,1,1,1,1,1,1,1,1,1,1,1,1,1,1,1,1
1,1,1,1,1,1,1,1,1,1,1,1,1,1,1,1,1,1,1,1
1,1,1,1,1,1,1,1,1,1,1,1,1,1,1,1,1,1,1,1
1,1,1,1,1,1,1,1,1,1,1,1,1,1,1,1,1,1,1,1
1,1,1,1,1,1,1,1,2,2,2,2,1,1,1,1,1,1,1,1
1,1,1,1,1,1,1,1,2,0,0,2,1,1,1,1,1,1,1,1
1,1,1,1,1,1,1,1,2,0,0,2,1,1,1,1,1,1,1,1
1,1,1,1,1,1,1,1,2,0,0,2,1,1,1,1,1,1,1,1
1,1,1,1,1,1,1,1,2,0,0,2,1,1,1,1,1,1,1,1
1,1,1,1,1,1,1,1,2,0,0,2,1,1,1,1,1,1,1,1
1,1,1,1,1,1,1,1,2,0,0,2,1,1,1,1,1,1,1,1
1,1,1,1,1,1,1,1,2,0,0,2,1,1,1,1,1,1,1,1
1,1,1,1,1,1,1,1,2,0,0,2,1,1,1,1,1,1,1,1
1,1,1,1,1,1,1,1,2,0,0,2,1,1,1,1,1,1,1,1
1,1,1,1,1,1,1,1,2,0,0,2,1,1,1,1,1,1,1,1
1,1,1,1,1,1,1,1,2,0,0,2,1,1,1,1,1,1,1,1
1,1,1,1,1,1,1,1,2,0,0,2,1,1,1,1,1,1,1,1
1,1,1,1,1,1,1,1,2,0,0,2,1,1,1,1,1,1,1,1
1,1,1,1,1,1,1,1,2,2,2,2,1,1,1,1,1,1,1,1
1,1,1,1,1,1,1,1,1,1,1,1,1,1,1,1,1,1,1,1
1,1,1,1,1,1,1,1,1,1,1,1,1,1,1,1,1,1,1,1
1,1,1,1,1,1,1,1,1,1,1,1,1,1,1,1,1,1,1,1
1,1,1,1,1,1,1,1,1,1,1,1,1,1,1,1,1,1,1,1
1,1,1,1,1,1,1,1,1,1,1,1,1,1,1,1,1,1,1,1
1,1,1,1,1,1,1,1,1,1,1,1,1,1,1,1,1,1,1,1
1,1,1,1,1,1,1,1,1,1,1,1,1,1,1,1,1,1,1,1
1,1,1,1,1,1,1,1,1,1,1,1,1,1,1,1,1,1,1,1
1,1,1,1,1,1,1,1,1,1,1,1,1,1,1,1,1,1,1,1
1,1,1,1,1,1,1,1,1,1,1,1,1,1,1,1,1,1,1,1
1,1,1,1,1,1,1,1,1,1,1,1,1,1,1,1,1,1,1,1
1,1,1,1,1,1,1,1,1,1,1,1,1,1,1,1,1,1,1,1
endlayer

layer
1,1,1,1,1,1,1,1,1,1,1,1,1,1,1,1,1,1,1,1
1,1,1,1,1,1,1,1,1,1,1,1,1,1,1,1,1,1,1,1
1,1,1,1,1,1,1,1,1,1,1,1,1,1,1,1,1,1,1,1
1,1,1,1,1,1,1,1,1,1,1,1,1,1,1,1,1,1,1,1
1,1,1,1,1,1,1,1,1,1,1,1,1,1,1,1,1,1,1,1
1,1,1,1,1,1,1,1,1,1,1,1,1,1,1,1,1,1,1,1
1,1,1,1,1,1,1,1,1,1,1,1,1,1,1,1,1,1,1,1
1,1,1,1,1,1,1,1,2,2,2,2,1,1,1,1,1,1,1,1
1,1,1,1,1,1,1,1,2,0,0,2,1,1,1,1,1,1,1,1
1,1,1,1,1,1,1,1,2,0,0,2,1,1,1,1,1,1,1,1
1,1,1,1,1,1,1,1,2,0,0,2,1,1,1,1,1,1,1,1
1,1,1,1,1,1,1,1,2,0,0,2,1,1,1,1,1,1,1,1
1,1,1,1,1,1,1,1,2,0,0,2,1,1,1,1,1,1,1,1
1,1,1,1,1,1,1,1,2,0,0,2,1,1,1,1,1,1,1,1
1,1,1,1,1,1,1,1,2,0,0,2,1,1,1,1,1,1,1,1
1,1,1,1,1,1,1,1,2,0,0,2,1,1,1,1,1,1,1,1
1,1,1,1,1,1,1,1,2,0,0,2,1,1,1,1,1,1,1,1
1,1,1,1,1,1,1,1,2,0,0,2,1,1,1,1,1,1,1,1
1,1,1,1,1,1,1,1,2,0,0,2,1,1,1,1,1,1,1,1
1,1,1,1,1,1,1,1,2,0,0,2,1,1,1,1,1,1,1,1
1,1,1,1,1,1,1,1,2,0,0,2,1,1,1,1,1,1,1,1
1,1,1,1,1,1,1,1,2,2,2,2,1,1,1,1,1,1,1,1
1,1,1,1,1,1,1,1,1,1,1,1,1,1,1,1,1,1,1,1
1,1,1,1,1,1,1,1,1,1,1,1,1,1,1,1,1,1,1,1
1,1,1,1,1,1,1,1,1,1,1,1,1,1,1,1,1,1,1,1
1,1,1,1,1,1,1,1,1,1,1,1,1,1,1,1,1,1,1,1
1,1,1,1,1,1,1,1,1,1,1,1,1,1,1,1,1,1,1,1
1,1,1,1,1,1,1,1,1,1,1,1,1,1,1,1,1,1,1,1
1,1,1,1,1,1,1,1,1,1,1,1,1,1,1,1,1,1,1,1
1,1,1,1,1,1,1,1,1,1,1,1,1,1,1,1,1,1,1,1
1,1,1,1,1,1,1,1,1,1,1,1,1,1,1,1,1,1,1,1
1,1,1,1,1,1,1,1,1,1,1,1,1,1,1,1,1,1,1,1
1,1,1,1,1,1,1,1,1,1,1,1,1,1,1,1,1,1,1,1
1,1,1,1,1,1,1,1,1,1,1,1,1,1,1,1,1,1,1,1
endlayer

layer
1,1,1,1,1,1,1,1,1,1,1,1,1,1,1,1,1,1,1,1
1,1,1,1,1,1,1,1,1,1,1,1,1,1,1,1,1,1,1,1
1,1,1,1,1,1,1,1,1,1,1,1,1,1,1,1,1,1,1,1
1,1,1,1,1,1,1,1,1,1,1,1,1,1,1,1,1,1,1,1
1,1,1,1,1,1,1,1,1,1,1,1,1,1,1,1,1,1,1,1
1,1,1,1,1,1,1,1,1,1,1,1,1,1,1,1,1,1,1,1
1,1,1,1,1,1,1,1,1,1,1,1,1,1,1,1,1,1,1,1
1,1,1,1,1,1,1,1,2,2,2,2,1,1,1,1,1,1,1,1
1,1,1,1,1,1,1,1,2,0,0,2,1,1,1,1,1,1,1,1
1,1,1,1,1,1,1,1,2,0,0,2,1,1,1,1,1,1,1,1
1,1,1,1,1,1,1,1,2,0,0,2,1,1,1,1,1,1,1,1
1,1,1,1,1,1,1,1,2,0,0,2,1,1,1,1,1,1,1,1
1,1,1,1,1,1,1,1,2,0,0,2,1,1,1,1,1,1,1,1
1,1,1,1,1,1,1,1,2,0,0,2,1,1,1,1,1,1,1,1
1,1,1,1,1,1,1,1,2,0,0,2,1,1,1,1,1,1,1,1
1,1,1,1,1,1,1,1,2,0,0,2,1,1,1,1,1,1,1,1
1,1,1,1,1,1,1,1,2,0,0,2,1,1,1,1,1,1,1,1
1,1,1,1,1,1,1,1,2,0,0,2,1,1,1,1,1,1,1,1
1,1,1,1,1,1,1,1,2,0,0,2,1,1,1,1,1,1,1,1
1,1,1,1,1,1,1,1,2,0,0,2,1,1,1,1,1,1,1,1
1,1,1,1,1,1,1,1,2,0,0,2,1,1,1,1,1,1,1,1
1,1,1,1,1,1,1,1,2,2,2,2,1,1,1,1,1,1,1,1
1,1,1,1,1,1,1,1,1,1,1,1,1,1,1,1,1,1,1,1
1,1,1,1,1,1,1,1,1,1,1,1,1,1,1,1,1,1,1,1
1,1,1,1,1,1,1,1,1,1,1,1,1,1,1,1,1,1,1,1
1,1,1,1,1,1,1,1,1,1,1,1,1,1,1,1,1,1,1,1
1,1,1,1,1,1,1,1,1,1,1,1,1,1,1,1,1,1,1,1
1,1,1,1,1,1,1,1,1,1,1,1,1,1,1,1,1,1,1,1
1,1,1,1,1,1,1,1,1,1,1,1,1,1,1,1,1,1,1,1
1,1,1,1,1,1,1,1,1,1,1,1,1,1,1,1,1,1,1,1
1,1,1,1,1,1,1,1,1,1,1,1,1,1,1,1,1,1,1,1
1,1,1,1,1,1,1,1,1,1,1,1,1,1,1,1,1,1,1,1
1,1,1,1,1,1,1,1,1,1,1,1,1,1,1,1,1,1,1,1
1,1,1,1,1,1,1,1,1,1,1,1,1,1,1,1,1,1,1,1
endlayer

layer
1,1,1,1,1,1,1,1,1,1,1,1,1,1,1,1,1,1,1,1
1,1,1,1,1,1,1,1,1,1,1,1,1,1,1,1,1,1,1,1
1,1,1,1,1,1,1,1,1,1,1,1,1,1,1,1,1,1,1,1
1,1,1,1,1,1,1,1,1,1,1,1,1,1,1,1,1,1,1,1
1,1,1,1,1,1,1,1,1,1,1,1,1,1,1,1,1,1,1,1
1,1,1,1,1,1,1,1,1,1,1,1,1,1,1,1,1,1,1,1
1,1,1,1,1,1,1,1,1,1,1,1,1,1,1,1,1,1,1,1
1,1,1,1,1,1,1,1,2,2,2,2,1,1,1,1,1,1,1,1
1,1,1,1,1,1,1,1,2,0,0,2,1,1,1,1,1,1,1,1
1,1,1,1,1,1,1,1,2,0,0,2,1,1,1,1,1,1,1,1
1,1,1,1,1,1,1,1,2,0,0,2,1,1,1,1,1,1,1,1
1,1,1,1,1,1,1,1,2,0,0,2,1,1,1,1,1,1,1,1
1,1,1,1,1,1,1,1,2,0,0,2,1,1,1,1,1,1,1,1
1,1,1,1,1,1,1,1,2,0,0,2,1,1,1,1,1,1,1,1
1,1,1,1,1,1,1,1,2,0,0,2,1,1,1,1,1,1,1,1
1,1,1,1,1,1,1,1,2,0,0,2,1,1,1,1,1,1,1,1
1,1,1,1,1,1,1,1,2,0,0,2,1,1,1,1,1,1,1,1
1,1,1,1,1,1,1,1,2,0,0,2,1,1,1,1,1,1,1,1
1,1,1,1,1,1,1,1,2,0,0,2,1,1,1,1,1,1,1,1
1,1,1,1,1,1,1,1,2,0,0,2,1,1,1,1,1,1,1,1
1,1,1,1,1,1,1,1,2,0,0,2,1,1,1,1,1,1,1,1
1,1,1,1,1,1,1,1,2,2,2,2,1,1,1,1,1,1,1,1
1,1,1,1,1,1,1,1,1,1,1,1,1,1,1,1,1,1,1,1
1,1,1,1,1,1,1,1,1,1,1,1,1,1,1,1,1,1,1,1
1,1,1,1,1,1,1,1,1,1,1,1,1,1,1,1,1,1,1,1
1,1,1,1,1,1,1,1,1,1,1,1,1,1,1,1,1,1,1,1
1,1,1,1,1,1,1,1,1,1,1,1,1,1,1,1,1,1,1,1
1,1,1,1,1,1,1,1,1,1,1,1,1,1,1,1,1,1,1,1
1,1,1,1,1,1,1,1,1,1,1,1,1,1,1,1,1,1,1,1
1,1,1,1,1,1,1,1,1,1,1,1,1,1,1,1,1,1,1,1
1,1,1,1,1,1,1,1,1,1,1,1,1,1,1,1,1,1,1,1
1,1,1,1,1,1,1,1,1,1,1,1,1,1,1,1,1,1,1,1
1,1,1,1,1,1,1,1,1,1,1,1,1,1,1,1,1,1,1,1
1,1,1,1,1,1,1,1,1,1,1,1,1,1,1,1,1,1,1,1
endlayer

layer
1,1,1,1,1,1,1,1,1,1,1,1,1,1,1,1,1,1,1,1
1,1,1,1,1,1,1,1,1,1,1,1,1,1,1,1,1,1,1,1
1,1,1,1,1,1,1,1,1,1,1,1,1,1,1,1,1,1,1,1
1,1,1,1,1,1,1,1,1,1,1,1,1,1,1,1,1,1,1,1
1,1,1,1,1,1,1,1,1,1,1,1,1,1,1,1,1,1,1,1
1,1,1,1,1,1,1,1,1,1,1,1,1,1,1,1,1,1,1,1
1,1,1,1,1,1,1,1,1,1,1,1,1,1,1,1,1,1,1,1
1,1,1,1,1,1,2,1,2,2,2,2,1,2,1,1,1,1,1,1
1,1,1,1,1,1,2,0,2,0,0,2,0,2,1,1,1,1,1,1
1,1,1,1,1,1,2,0,2,0,0,2,0,2,1,1,1,1,1,1
1,1,1,1,1,1,2,0,2,0,0,2,0,2,1,1,1,1,1,1
1,1,1,1,1,1,2,0,2,0,0,2,0,2,1,1,1,1,1,1
1,1,1,1,1,1,2,0,2,0,0,2,0,2,1,1,1,1,1,1
1,1,1,1,1,1,2,0,2,0,0,2,0,2,1,1,1,1,1,1
1,1,1,1,1,1,2,0,2,0,0,2,0,2,1,1,1,1,1,1
1,1,1,1,1,1,2,0,2,0,0,2,0,2,1,1,1,1,1,1
1,1,1,1,1,1,2,0,2,0,0,2,0,2,1,1,1,1,1,1
1,1,1,1,1,1,2,0,2,0,0,2,0,2,1,1,1,1,1,1
1,1,1,1,1,1,2,0,2,0,0,2,0,2,1,1,1,1,1,1
1,1,1,1,1,1,2,0,2,0,0,2,0,2,1,1,1,1,1,1
1,1,1,1,1,1,2,0,2,0,0,2,0,2,1,1,1,1,1,1
1,1,1,1,1,1,1,1,2,2,2,2,1,1,1,1,1,1,1,1
1,1,1,1,1,1,1,1,1,1,1,1,1,1,1,1,1,1,1,1
1,1,1,1,1,1,1,1,1,1,1,1,1,1,1,1,1,1,1,1
1,1,1,1,1,1,1,1,1,1,1,1,1,1,1,1,1,1,1,1
1,1,1,1,1,1,1,1,1,1,1,1,1,1,1,1,1,1,1,1
1,1,1,1,1,1,1,1,1,1,1,1,1,1,1,1,1,1,1,1
1,1,1,1,1,1,1,1,1,1,1,1,1,1,1,1,1,1,1,1
1,1,1,1,1,1,1,1,1,1,1,1,1,1,1,1,1,1,1,1
1,1,1,1,1,1,1,1,1,1,1,1,1,1,1,1,1,1,1,1
1,1,1,1,1,1,1,1,1,1,1,1,1,1,1,1,1,1,1,1
1,1,1,1,1,1,1,1,1,1,1,1,1,1,1,1,1,1,1,1
1,1,1,1,1,1,1,1,1,1,1,1,1,1,1,1,1,1,1,1
1,1,1,1,1,1,1,1,1,1,1,1,1,1,1,1,1,1,1,1
endlayer

layer
2,2,2,2,2,2,2,2,2,2,2,2,2,2,2,2,2,2,2,2
2,2,2,2,2,2,2,2,2,2,2,2,2,2,2,2,2,2,2,2
2,2,2,2,2,2,2,2,2,2,2,2,2,2,2,2,2,2,2,2
2,2,2,2,2,2,2,2,2,2,2,2,2,2,2,2,2,2,2,2
2,2,2,2,2,2,2,2,2,2,2,2,2,2,2,2,2,2,2,2
2,2,2,2,2,2,2,2,2,2,2,2,2,2,2,2,2,2,2,2
2,2,2,2,2,2,2,2,2,2,2,2,2,2,2,2,2,2,2,2
2,2,2,2,2,2,2,2,2,2,2,2,2,2,2,2,2,2,2,2
2,2,2,2,2,2,10,9,8,2,2,7,6,5,2,0,2,2,2,2
2,2,2,2,2,2,10,9,8,2,2,7,6,5,2,2,2,2,2,2
2,2,2,2,2,2,10,9,8,2,2,7,6,5,2,2,2,2,2,2
2,2,2,2,2,2,10,9,8,2,2,7,6,5,2,2,2,2,2,2
2,2,2,2,2,2,10,9,8,2,2,7,6,5,2,2,2,2,2,2
2,2,2,2,2,2,10,9,8,2,2,7,6,5,2,2,2,2,2,2
2,2,2,2,2,2,10,9,8,2,2,7,6,5,2,2,2,2,2,2
2,2,2,2,2,2,10,9,8,2,2,7,6,5,2,2,2,2,2,2
2,2,2,2,2,2,10,9,8,2,2,7,6,5,2,2,2,2,2,2
2,2,2,2,2,2,10,9,8,2,2,7,6,5,2,2,2,2,2,2
2,2,2,2,2,2,10,9,8,2,2,7,6,5,2,2,2,2,2,2
2,2,2,2,2,2,10,9,8,2,2,7,6,5,2,2,2,2,2,2
2,2,2,2,2,2,10,9,8,2,2,7,6,5,2,2,2,2,2,2
2,2,2,2,2,2,2,2,2,2,2,2,2,2,2,2,2,2,2,2
2,2,2,2,2,2,2,2,2,2,2,2,2,2,2,2,2,2,2,2
2,2,2,2,2,2,2,2,2,2,2,2,2,2,2,2,2,2,2,2
2,2,2,2,2,2,2,2,2,2,2,2,2,2,2,2,2,2,2,2
2,2,2,2,2,2,2,2,2,2,2,2,2,2,2,2,2,2,2,2
2,2,2,2,2,2,2,2,2,2,2,2,2,2,2,2,2,2,2,2
2,2,2,2,2,2,2,2,2,2,2,2,2,2,2,2,2,2,2,2
2,2,2,2,2,2,2,2,2,2,2,2,2,2,2,2,2,2,2,2
2,2,2,2,2,2,2,2,2,2,2,2,2,2,2,2,2,2,2,2
2,2,2,2,2,2,2,2,2,2,2,2,2,2,2,2,2,2,2,2
11,11,11,11,11,11,11,11,2,2,2,2,11,11,11,11,11,11,11,11
11,11,11,11,11,11,11,11,2,2,2,2,11,11,11,11,11,11,11,11
11,11,11,11,11,11,11,11,2,2,2,2,11,11,11,11,11,11,11,11
endlayer

layer
12,13,13,13,12,13,13,13,12,13,13,12,13,13,13,12,13,13,13,12
13,13,13,0,0,0,0,0,13,0,0,13,0,0,0,0,0,13,13,13
13,13,0,0,0,0,0,0,13,0,0,13,0,0,0,0,0,0,13,13
12,0,0,0,0,13,0,0,13,0,0,13,0,0,13,0,0,0,0,12
13,0,0,0,0,13,0,0,0,0,0,0,0,0,13,0,0,0,0,13
13,0,0,0,13,13,0,0,13,13,13,13,0,0,13,13,0,0,0,13
12,0,0,13,0,0,0,0,0,13,13,0,0,0,0,0,13,0,0,12
13,0,0,13,0,2,13,0,0,0,0,0,0,13,2,0,13,0,0,13
13,0,0,2,13,14,0,13,13,0,0,13,13,0,14,13,2,0,0,13
12,0,0,2,0,14,0,0,2,0,0,2,0,0,14,0,2,0,0,12
13,0,0,13,15,14,0,0,2,0,0,2,0,0,14,15,13,0,0,13
13,0,0,2,0,14,0,0,2,0,0,2,0,0,14,0,2,0,0,13
12,0,0,2,15,14,0,0,2,0,0,2,0,0,14,15,2,0,0,12
13,0,0,13,0,14,0,2,2,0,0,2,2,0,14,0,13,0,0,13
13,0,0,2,15,14,0,0,2,0,0,2,0,0,14,15,2,0,0,13
12,0,0,2,0,14,0,0,2,0,0,2,2,0,14,0,2,0,0,12
13,0,0,13,0,14,0,0,2,0,0,2,0,0,14,0,13,0,0,13
13,0,0,2,14,14,0,0,2,0,0,2,0,0,14,14,2,0,0,13
12,0,0,2,16,14,0,0,2,0,0,2,0,0,14,16,2,0,0,12
13,0,0,13,16,14,0,0,2,0,0,2,0,0,14,16,13,0,0,13
13,0,0,2,16,14,0,2,2,0,0,2,0,0,14,16,2,0,0,13
12,0,0,2,14,0,0,0,2,13,13,2,13,0,0,14,2,0,0,12
13,0,0,13,14,0,0,0,0,14,0,0,0,0,0,14,13,0,0,13
13,0,0,13,14,14,14,14,0,17,0,0,14,14,14,14,13,0,0,13
12,0,0,13,0,15,0,14,14,14,14,14,14,0,15,0,13,0,0,12
13,0,0,0,13,13,13,13,13,13,13,13,13,13,13,13,0,0,0,13
13,0,0,13,0,0,0,0,0,0,0,0,0,0,0,0,13,0,0,13
12,0,0,13,0,0,13,13,13,0,0,13,13,13,0,0,13,0,0,12
13,0,0,0,0,0,0,0,13,0,0,13,0,0,0,0,0,0,0,13
13,13,0,0,0,0,0,0,13,0,0,13,0,0,0,0,0,0,13,13
12,13,13,13,12,13,13,13,12,0,0,12,13,13,13,12,13,13,13,12
0,0,0,0,0,0,0,0,0,0,0,0,0,0,0,0,0,0,0,0
0,0,0,0,0,0,0,0,0,0,0,0,0,0,0,0,0,0,0,0
0,0,0,0,0,0,0,0,12,0,0,12,0,0,0,0,0,0,0,0
endlayer

layer
12,13,13,13,12,13,13,13,12,13,13,12,13,13,13,12,13,13,13,12
13,13,13,0,0,0,0,0,13,0,0,13,0,0,0,0,0,13,13,13
13,13,0,0,0,0,0,0,13,0,0,13,0,0,0,0,0,0,13,13
12,0,0,0,0,13,0,0,13,0,0,13,0,0,13,0,0,0,0,12
13,0,0,0,0,13,0,0,0,0,0,0,0,0,13,0,0,0,0,13
13,0,0,0,13,13,0,0,13,13,13,13,0,0,13,13,0,0,0,13
12,0,0,13,0,0,0,0,0,13,13,0,0,0,0,0,13,0,0,12
13,0,0,13,0,2,13,0,0,0,0,0,0,13,2,0,13,0,0,13
13,0,0,2,13,0,2,13,13,0,0,13,13,2,0,13,2,0,0,13
12,0,0,2,0,0,2,2,2,0,0,2,2,2,0,0,2,0,0,12
13,0,0,13,0,0,2,2,2,0,0,2,2,2,0,0,13,0,0,13
13,0,0,2,0,0,2,2,2,0,0,2,2,2,0,0,2,0,0,13
12,0,0,2,0,0,2,2,2,0,0,2,2,2,0,0,2,0,0,12
13,0,0,13,0,0,2,18,19,0,0,19,18,2,0,0,13,0,0,13
13,0,0,2,0,0,2,2,2,0,0,2,2,2,0,0,2,0,0,13
12,0,0,2,0,0,2,2,2,0,0,2,2,2,0,0,2,0,0,12
13,0,0,13,0,0,2,2,2,0,0,2,2,2,0,0,13,0,0,13
13,0,0,2,0,0,2,2,2,0,0,2,2,2,0,0,2,0,0,13
12,0,0,2,0,0,2,2,2,0,0,2,2,2,0,0,2,0,0,12
13,0,0,13,0,0,2,2,2,0,0,2,0,0,0,0,13,0,0,13
13,0,0,2,0,0,2,2,2,0,0,2,2,2,0,0,2,0,0,13
12,0,0,2,0,0,0,0,2,21,20,2,2,0,0,0,2,0,0,12
13,0,0,13,0,0,0,0,0,2,2,0,0,0,0,0,13,0,0,13
13,0,0,13,0,0,0,0,0,0,0,0,0,0,0,0,13,0,0,13
12,0,0,13,0,0,0,0,0,0,0,0,0,0,0,0,13,0,0,12
13,0,0,0,13,13,13,13,13,13,13,13,13,13,13,13,0,0,0,13
13,0,0,13,0,0,0,0,0,0,0,0,0,0,0,0,13,0,0,13
12,0,0,13,0,0,13,13,13,0,0,13,13,13,0,0,13,0,0,12
13,0,0,0,0,0,0,0,13,0,0,13,0,0,0,0,0,0,0,13
13,13,0,0,0,0,0,0,13,0,0,13,0,0,0,0,0,0,13,13
12,13,13,13,12,13,13,13,12,0,0,12,13,13,13,12,13,13,13,12
0,0,0,0,0,0,0,0,0,0,0,0,0,0,0,0,0,0,0,0
0,0,0,0,0,0,0,0,0,0,0,0,0,0,0,0,0,0,0,0
0,0,0,0,0,0,0,0,12,0,0,12,0,0,0,0,0,0,0,0
endlayer

layer
12,23,13,22,12,23,13,22,12,13,13,12,23,13,22,12,23,13,22,12
13,13,13,0,0,0,0,0,13,0,0,13,0,0,0,0,0,13,13,13
13,13,0,0,0,0,0,0,13,0,0,13,0,0,0,0,0,0,13,13
12,0,0,0,0,13,0,0,13,0,0,13,0,0,13,0,0,0,0,12
13,0,0,0,0,13,0,0,0,0,0,0,0,0,13,0,0,0,0,13
13,0,0,0,13,13,0,0,13,13,13,13,0,0,13,13,0,0,0,13
12,0,0,13,0,0,0,0,0,13,13,0,0,0,0,0,13,0,0,12
13,0,0,13,0,2,13,0,0,0,0,0,0,13,2,0,13,0,0,13
13,0,0,2,13,0,2,13,13,0,0,13,13,2,0,13,2,0,0,13
12,0,0,2,0,0,2,2,2,0,0,2,2,2,0,0,2,0,0,12
13,0,0,13,0,0,2,2,2,0,0,2,2,2,0,0,13,0,0,13
13,0,0,2,0,0,2,2,2,0,0,2,2,2,0,0,2,0,0,13
12,0,0,2,0,0,2,2,2,0,0,2,2,2,0,0,2,0,0,12
13,0,0,13,0,0,2,2,2,0,0,2,2,2,0,0,13,0,0,13
13,0,0,2,0,0,2,2,2,0,0,2,2,2,0,0,2,0,0,13
12,0,0,2,0,0,2,2,2,0,0,2,2,2,0,0,2,0,0,12
13,0,0,13,0,0,2,2,2,0,0,2,2,2,0,0,13,0,0,13
13,0,0,2,0,0,2,2,2,0,0,2,2,2,0,0,2,0,0,13
12,0,0,2,0,0,2,2,2,0,0,2,2,2,0,0,2,0,0,12
13,0,0,13,0,0,2,2,2,0,0,2,0,2,0,0,13,0,0,13
13,0,0,2,0,0,2,2,2,0,0,2,2,2,0,0,2,0,0,13
12,0,0,2,0,0,0,2,2,0,0,2,2,2,0,0,2,0,0,12
13,0,0,13,0,0,0,2,2,2,2,2,2,2,0,0,13,0,0,13
13,0,0,13,0,0,0,0,2,2,2,2,0,0,0,0,13,0,0,13
12,0,0,13,0,0,0,0,0,0,0,0,0,0,0,0,13,0,0,12
13,0,0,0,13,13,13,13,13,13,13,13,13,13,13,13,0,0,0,13
13,0,0,13,0,0,0,0,0,0,0,0,0,0,0,0,13,0,0,13
12,0,0,13,0,0,13,13,13,0,0,13,13,13,0,0,13,0,0,12
13,0,0,0,0,0,0,0,13,0,0,13,0,0,0,0,0,0,0,13
13,13,0,0,0,0,0,0,13,0,0,13,0,0,0,0,0,0,13,13
12,23,13,22,12,23,13,22,12,0,0,12,23,13,22,12,23,13,22,12
0,0,0,0,0,0,0,0,0,0,0,0,0,0,0,0,0,0,0,0
0,0,0,0,0,0,0,0,0,0,0,0,0,0,0,0,0,0,0,0
0,0,0,0,0,0,0,0,12,0,0,12,0,0,0,0,0,0,0,0
endlayer

layer
12,12,12,12,12,12,12,12,12,12,12,12,12,12,12,12,12,12,12,12
12,13,13,13,13,13,13,13,13,13,13,13,13,13,13,13,13,13,13,12
12,13,13,13,13,13,13,13,13,13,13,13,13,13,13,13,13,13,13,12
12,13,13,13,13,13,13,13,13,13,13,13,13,13,13,13,13,13,13,12
12,13,13,13,13,13,13,13,13,13,13,13,13,13,13,13,13,13,13,12
12,13,13,13,13,13,13,13,13,13,13,13,13,13,13,13,13,13,13,12
12,13,13,13,13,13,13,13,13,13,13,13,13,13,13,13,13,13,13,12
12,13,13,13,13,13,13,13,13,13,13,13,13,13,13,13,13,13,13,12
12,13,13,13,13,0,0,13,13,13,13,13,13,0,0,13,13,13,13,12
12,13,13,13,0,0,0,0,13,13,13,13,0,0,0,0,13,13,13,12
12,13,13,13,0,0,0,0,13,13,13,13,0,0,0,0,13,13,13,12
12,13,13,13,0,0,0,0,13,13,13,13,0,0,0,0,13,13,13,12
12,13,13,13,0,0,0,0,13,13,13,13,0,0,0,0,13,13,13,12
12,13,13,13,0,0,0,0,13,13,13,13,0,0,0,0,13,13,13,12
12,13,13,13,0,0,0,0,13,13,13,13,0,0,0,0,13,13,13,12
12,13,13,13,0,0,0,0,13,13,13,13,0,0,0,0,13,13,13,12
12,13,13,13,0,0,0,0,13,13,13,13,0,0,0,0,13,13,13,12
12,13,13,13,0,0,0,0,13,13,13,13,0,0,0,0,13,13,13,12
12,13,13,13,0,0,0,0,13,13,13,13,0,0,0,0,13,13,13,12
12,13,13,13,0,0,0,0,13,13,13,13,0,0,0,0,13,13,13,12
12,13,13,13,0,0,0,0,13,13,13,13,0,0,0,0,13,13,13,12
12,13,13,13,0,0,0,0,13,13,13,13,0,0,0,0,13,13,13,12
12,13,13,13,0,0,0,0,13,13,13,13,0,0,0,0,13,13,13,12
12,13,13,13,0,0,0,0,13,13,13,13,0,0,0,0,13,13,13,12
12,13,13,13,0,0,0,0,0,0,0,0,0,0,0,0,13,13,13,12
12,13,13,13,13,13,13,0,0,0,0,0,0,13,13,13,13,13,13,12
12,13,13,13,13,13,13,13,13,13,13,13,13,0,0,0,13,13,13,12
12,13,13,13,13,13,13,13,13,0,0,13,13,13,0,0,13,13,13,12
12,13,13,13,13,13,13,13,13,0,0,13,0,0,0,0,13,13,13,12
12,13,13,13,13,13,13,13,13,0,0,13,13,13,13,13,13,13,13,12
12,12,12,12,12,12,12,12,12,0,0,12,12,12,12,12,12,12,12,12
0,0,0,0,0,0,0,0,25,0,0,24,0,0,0,0,0,0,0,0
0,0,0,0,0,0,0,0,25,0,0,24,0,0,0,0,0,0,0,0
0,0,0,0,0,0,0,0,26,26,26,26,0,0,0,0,0,0,0,0
endlayer

layer
12,12,24,27,27,27,27,25,12,12,12,12,12,12,24,27,27,25,12,12
12,0,0,0,0,0,0,0,0,0,0,0,0,0,0,0,0,0,0,12
26,0,0,0,0,0,0,0,0,0,0,0,0,0,0,0,0,0,0,26
27,0,0,0,0,0,0,0,0,0,0,0,0,0,0,0,0,0,0,27
27,0,0,0,0,0,0,0,0,0,0,0,0,0,0,0,0,0,0,27
27,0,0,0,0,0,0,0,0,0,0,0,0,0,0,0,0,0,0,27
27,0,28,28,28,28,28,28,28,28,28,28,28,28,28,28,28,28,0,27
27,0,28,13,13,13,13,13,13,13,13,13,13,13,13,13,13,28,0,27
27,0,28,13,13,13,13,13,13,0,0,13,13,13,13,13,13,28,0,27
27,0,28,13,13,13,13,13,13,0,0,13,13,13,13,13,13,28,0,27
27,0,28,13,13,13,13,13,13,0,0,13,13,13,13,13,13,28,0,27
27,0,28,13,13,13,13,13,13,0,0,13,13,13,13,13,13,28,0,27
27,0,28,13,13,13,13,13,13,0,0,13,13,13,13,13,13,28,0,27
29,0,28,13,13,13,13,13,13,0,0,13,13,13,13,13,13,28,0,29
12,0,28,13,13,13,13,13,13,0,0,13,13,13,13,13,13,28,0,12
12,0,28,13,13,13,13,13,13,0,0,13,13,13,13,13,13,28,0,12
12,0,28,13,13,13,13,13,13,0,0,13,13,13,13,13,13,28,0,12
26,0,28,13,13,13,13,13,13,0,0,13,13,13,13,13,13,28,0,26
27,0,28,13,13,13,13,13,13,0,0,13,13,13,13,13,13,28,0,27
27,0,28,13,13,13,13,13,13,0,0,13,13,13,13,13,13,28,0,27
27,0,28,13,13,13,13,13,13,0,0,13,13,13,13,13,13,28,0,27
27,0,28,13,13,13,13,13,13,0,0,13,13,13,13,13,13,28,0,27
27,0,28,13,13,13,13,13,13,0,0,13,13,13,13,13,13,28,0,27
27,0,28,13,13,13,13,13,13,0,0,13,13,13,13,13,13,28,0,27
27,0,28,13,13,13,13,13,13,13,13,13,13,13,13,13,13,28,0,27
27,0,28,13,13,13,13,13,13,13,13,13,13,13,13,13,13,28,0,27
27,0,28,28,28,13,13,13,13,13,13,13,13,13,13,13,28,28,0,27
27,0,0,0,28,13,13,13,13,13,13,13,13,13,13,13,28,0,0,27
29,0,0,0,28,13,13,13,13,13,13,13,13,13,13,13,28,0,0,29
12,0,0,0,28,28,28,28,28,13,13,28,28,28,28,28,28,0,0,12
12,12,24,27,27,27,25,12,12,12,12,12,12,24,27,27,27,25,12,12
0,0,0,0,0,0,0,0,0,27,27,0,0,0,0,0,0,0,0,0
0,0,0,0,0,0,0,0,0,27,27,0,0,0,0,0,0,0,0,0
0,0,0,0,0,0,0,0,0,0,0,0,0,0,0,0,0,0,0,0
endlayer

layer
12,24,0,0,0,0,0,0,25,12,12,12,12,24,0,0,0,0,25,12
26,0,0,0,0,0,0,0,0,0,0,0,0,0,0,0,0,0,0,26
0,0,0,0,0,0,0,0,0,0,0,0,0,0,0,0,0,0,0,0
0,0,0,0,0,0,0,0,0,0,0,0,0,0,0,0,0,0,0,0
0,0,0,0,0,0,0,0,0,0,0,0,0,0,0,0,0,0,0,0
0,0,0,0,0,0,0,0,0,0,0,0,0,0,0,0,0,0,0,0
0,0,0,0,0,0,0,0,0,0,0,0,0,0,0,0,0,0,0,0
0,0,0,27,27,27,27,27,27,27,27,27,27,27,27,27,27,0,0,0
0,0,0,27,0,0,0,0,0,0,0,0,0,0,0,0,27,0,0,0
0,0,0,27,0,0,0,0,0,0,0,0,0,0,0,0,27,0,0,0
0,0,0,27,0,0,0,0,0,0,0,0,0,0,0,0,27,0,0,0
0,0,0,27,0,0,0,0,0,0,0,0,0,0,0,0,27,0,0,0
0,0,0,27,0,0,0,0,0,0,0,0,0,0,0,0,27,0,0,0
0,0,0,27,0,0,0,0,0,0,0,0,0,0,0,0,27,0,0,0
29,0,0,27,0,0,0,0,0,0,0,0,0,0,0,0,27,0,0,29
12,0,0,27,0,0,0,0,0,0,0,0,0,0,0,0,27,0,0,12
26,0,0,27,0,0,0,0,0,0,0,0,0,0,0,0,27,0,0,26
0,0,0,27,0,0,0,0,0,0,0,0,0,0,0,0,27,0,0,0
0,0,0,27,0,0,0,0,0,0,0,0,0,0,0,0,27,0,0,0
0,0,0,27,0,0,0,0,0,0,0,0,0,0,0,0,27,0,0,0
0,0,0,27,0,0,0,0,0,0,0,0,0,0,0,0,27,0,0,0
0,0,0,27,0,0,0,0,0,0,0,0,0,0,0,0,27,0,0,0
0,0,0,27,0,0,0,0,0,0,0,0,0,0,0,0,27,0,0,0
0,0,0,27,0,0,0,0,0,0,0,0,0,0,0,0,27,0,0,0
0,0,0,27,0,0,0,0,0,0,0,0,0,0,0,0,27,0,0,0
0,0,0,27,27,27,0,0,0,0,0,0,0,0,0,27,27,0,0,0
0,0,0,0,27,27,0,0,0,0,0,0,0,0,0,27,27,0,0,0
0,0,0,0,0,27,0,0,0,0,0,0,0,0,0,27,0,0,0,0
0,0,0,0,0,27,27,27,27,27,27,27,27,27,27,27,0,0,0,0
29,0,0,0,0,0,0,0,0,0,0,0,0,0,0,0,0,0,0,29
12,24,0,0,0,0,0,25,12,12,12,12,24,0,0,0,0,0,25,12
0,0,0,0,0,0,0,0,0,0,0,0,0,0,0,0,0,0,0,0
0,0,0,0,0,0,0,0,0,0,0,0,0,0,0,0,0,0,0,0
0,0,0,0,0,0,0,0,0,0,0,0,0,0,0,0,0,0,0,0
endlayer

layer
27,0,0,0,0,0,0,0,0,25,12,12,24,0,0,0,0,0,0,27
0,0,0,0,0,0,0,0,0,0,0,0,0,0,0,0,0,0,0,0
0,0,0,0,0,0,0,0,0,0,0,0,0,0,0,0,0,0,0,0
0,0,0,0,0,0,0,0,0,0,0,0,0,0,0,0,0,0,0,0
0,0,0,0,0,0,0,0,0,0,0,0,0,0,0,0,0,0,0,0
0,0,0,0,0,0,0,0,0,0,0,0,0,0,0,0,0,0,0,0
0,0,0,0,0,0,0,0,0,0,0,0,0,0,0,0,0,0,0,0
0,0,0,0,0,0,0,0,0,0,0,0,0,0,0,0,0,0,0,0
0,0,0,0,0,0,0,0,0,0,0,0,0,0,0,0,0,0,0,0
0,0,0,0,0,0,0,0,0,0,0,0,0,0,0,0,0,0,0,0
0,0,0,0,0,0,0,0,0,0,0,0,0,0,0,0,0,0,0,0
0,0,0,0,0,0,0,0,0,0,0,0,0,0,0,0,0,0,0,0
0,0,0,0,0,0,0,0,0,0,0,0,0,0,0,0,0,0,0,0
0,0,0,0,0,0,0,0,0,0,0,0,0,0,0,0,0,0,0,0
0,0,0,0,0,0,0,0,0,0,0,0,0,0,0,0,0,0,0,0
27,0,0,0,0,0,0,0,0,0,0,0,0,0,0,0,0,0,0,27
0,0,0,0,0,0,0,0,0,0,0,0,0,0,0,0,0,0,0,0
0,0,0,0,0,0,0,0,0,0,0,0,0,0,0,0,0,0,0,0
0,0,0,0,0,0,0,0,0,0,0,0,0,0,0,0,0,0,0,0
0,0,0,0,0,0,0,0,0,0,0,0,0,0,0,0,0,0,0,0
0,0,0,0,0,0,0,0,0,0,0,0,0,0,0,0,0,0,0,0
0,0,0,0,0,0,0,0,0,0,0,0,0,0,0,0,0,0,0,0
0,0,0,0,0,0,0,0,0,0,0,0,0,0,0,0,0,0,0,0
0,0,0,0,0,0,0,0,0,0,0,0,0,0,0,0,0,0,0,0
0,0,0,0,0,0,0,0,0,0,0,0,0,0,0,0,0,0,0,0
0,0,0,0,0,0,0,0,0,0,0,0,0,0,0,0,0,0,0,0
0,0,0,0,0,0,0,0,0,0,0,0,0,0,0,0,0,0,0,0
0,0,0,0,0,0,0,0,0,0,0,0,0,0,0,0,0,0,0,0
0,0,0,0,0,0,0,0,0,0,0,0,0,0,0,0,0,0,0,0
0,0,0,0,0,0,0,0,0,0,0,0,0,0,0,0,0,0,0,0
27,0,0,0,0,0,0,0,25,12,12,24,0,0,0,0,0,0,0,27
0,0,0,0,0,0,0,0,0,0,0,0,0,0,0,0,0,0,0,0
0,0,0,0,0,0,0,0,0,0,0,0,0,0,0,0,0,0,0,0
0,0,0,0,0,0,0,0,0,0,0,0,0,0,0,0,0,0,0,0
endlayer

layer
0,0,0,0,0,0,0,0,0,0,25,24,0,0,0,0,0,0,0,0
0,0,0,0,0,0,0,0,0,0,0,0,0,0,0,0,0,0,0,0
0,0,0,0,0,0,0,0,0,0,0,0,0,0,0,0,0,0,0,0
0,0,0,0,0,0,0,0,0,0,0,0,0,0,0,0,0,0,0,0
0,0,0,0,0,0,0,0,0,0,0,0,0,0,0,0,0,0,0,0
0,0,0,0,0,0,0,0,0,0,0,0,0,0,0,0,0,0,0,0
0,0,0,0,0,0,0,0,0,0,0,0,0,0,0,0,0,0,0,0
0,0,0,0,0,0,0,0,0,0,0,0,0,0,0,0,0,0,0,0
0,0,0,0,0,0,0,0,0,0,0,0,0,0,0,0,0,0,0,0
0,0,0,0,0,0,0,0,0,0,0,0,0,0,0,0,0,0,0,0
0,0,0,0,0,0,0,0,0,0,0,0,0,0,0,0,0,0,0,0
0,0,0,0,0,0,0,0,0,0,0,0,0,0,0,0,0,0,0,0
0,0,0,0,0,0,0,0,0,0,0,0,0,0,0,0,0,0,0,0
0,0,0,0,0,0,0,0,0,0,0,0,0,0,0,0,0,0,0,0
0,0,0,0,0,0,0,0,0,0,0,0,0,0,0,0,0,0,0,0
0,0,0,0,0,0,0,0,0,0,0,0,0,0,0,0,0,0,0,0
0,0,0,0,0,0,0,0,0,0,0,0,0,0,0,0,0,0,0,0
0,0,0,0,0,0,0,0,0,0,0,0,0,0,0,0,0,0,0,0
0,0,0,0,0,0,0,0,0,0,0,0,0,0,0,0,0,0,0,0
0,0,0,0,0,0,0,0,0,0,0,0,0,0,0,0,0,0,0,0
0,0,0,0,0,0,0,0,0,0,0,0,0,0,0,0,0,0,0,0
0,0,0,0,0,0,0,0,0,0,0,0,0,0,0,0,0,0,0,0
0,0,0,0,0,0,0,0,0,0,0,0,0,0,0,0,0,0,0,0
0,0,0,0,0,0,0,0,0,0,0,0,0,0,0,0,0,0,0,0
0,0,0,0,0,0,0,0,0,0,0,0,0,0,0,0,0,0,0,0
0,0,0,0,0,0,0,0,0,0,0,0,0,0,0,0,0,0,0,0
0,0,0,0,0,0,0,0,0,0,0,0,0,0,0,0,0,0,0,0
0,0,0,0,0,0,0,0,0,0,0,0,0,0,0,0,0,0,0,0
0,0,0,0,0,0,0,0,0,0,0,0,0,0,0,0,0,0,0,0
0,0,0,0,0,0,0,0,0,0,0,0,0,0,0,0,0,0,0,0
0,0,0,0,0,0,0,0,0,25,24,0,0,0,0,0,0,0,0,0
0,0,0,0,0,0,0,0,0,0,0,0,0,0,0,0,0,0,0,0
0,0,0,0,0,0,0,0,0,0,0,0,0,0,0,0,0,0,0,0
0,0,0,0,0,0,0,0,0,0,0,0,0,0,0,0,0,0,0,0
endlayer

