
# Created by Ruins mod version 15.0 Ingame Parser
# authoring Player: SunsOfOld

weight=100
embed_into_distance=6
acceptable_target_blocks=
unacceptable_target_blocks=flowing_water,water,flowing_lava,lava
dimensions=35,21,28
allowable_overhang=0
max_leveling=6
leveling_buffer=0
preserve_water=0
preserve_lava=0
uniqueMinDistance=1000000
preventRotation=1

rule1=0,100,preserveBlock
rule2=0,100,minecraft:bedrock-0
rule3=0,100,CommandBlock:/testfor @p[r=16]:@
rule4=0,100,minecraft:unpowered_comparator-2
rule5=0,100,minecraft:unpowered_repeater-2
rule6=0,100,minecraft:redstone_wire-0
rule7=0,100,minecraft:powered_repeater-3
rule8=0,100,CommandBlock:/summon Villager ~ ~7 ~ {CustomName:"I Need More Powah!!",CustomNameVisible:1,Profession:1,Offers:{Recipes:[{rewardExp:0b,maxUses:2147483647,uses:0,buy:{id:1491,Count:12},sell:{id:376,Count:1}},{rewardExp:0b,maxUses:2147483647,uses:0,buy:{id:1491,Count:12},sell:{id:378,Count:1}},{rewardExp:0b,maxUses:2147483647,uses:0,buy:{id:1491,Count:12},sell:{id:377,Count:1}},{rewardExp:0b,maxUses:2147483647,uses:0,buy:{id:1491,Count:12},sell:{id:382,Count:1}},{rewardExp:0b,maxUses:2147483647,uses:0,buy:{id:1491,Count:16},sell:{id:370,Count:1}},{rewardExp:0b,maxUses:2147483647,uses:0,buy:{id:5072,Count:6},sell:{id:4175,Count:1}},{rewardExp:0b,maxUses:2147483647,uses:0,buy:{id:5073,Count:6},sell:{Count:1,id:403,tag:{StoredEnchantments:[{id:51,lvl:1}]}}}]}}:@
rule9=0,100,minecraft:unlit_redstone_torch-4
rule10=0,100,CommandBlock:/setblock ~ ~ ~ 152:@
rule11=0,100,minecraft:powered_repeater-1
rule12=0,100,minecraft:unpowered_repeater-1
rule13=0,100,minecraft:redstone_wire-15
rule14=0,100,minecraft:redstone_wire-14
rule15=0,100,minecraft:redstone_wire-13
rule16=0,100,minecraft:redstone_wire-12
rule17=2,100,minecraft:torch-1
rule18=2,100,minecraft:torch-2
rule19=0,100,chisel:glass-10
rule20=0,100,IInventory;HopperDuctMod:gratedHopper;minecraft:glass_bottle#2#0#0+minecraft:glass_bottle#2#0#1+minecraft:glass_bottle#2#0#2+minecraft:glass_bottle#2#0#3+minecraft:glass_bottle#2#0#4-2
rule21=0,100,IInventory;HopperDuctMod:gratedHopper;minecraft:redstone#6#0#0+minecraft:redstone#6#0#1+minecraft:glass_bottle#1#0#2+minecraft:glowstone_dust#6#0#3+minecraft:glowstone_dust#6#0#4-2
rule22=0,100,BiomesOPlenty:hell_blood-1
rule23=0,100,chisel:laboratoryblock-13
rule24=0,100,VeganOption:plantMilk-1
rule25=0,100,chisel:laboratoryblock-3
rule26=0,100,IInventory;minecraft:chest;GardenCore:soil_test_kit_used#{RepairCost:2,display:{Name:"Used Test Kit",},}#0#0+minecraft:potion#1#8264#2+minecraft:potion#1#8270#4+minecraft:potion#1#8269#6+GardenCore:soil_test_kit#{RepairCost:2,display:{Name:"Test Kit",},}#0#8+BiblioCraft:item.TesterItem#{containerUpdate:0b,RepairCost:2,display:{Name:"Tester Journal",},Inventory:[],}#0#9+minecraft:potion#1#8266#10+minecraft:potion#1#8260#12+minecraft:potion#1#8258#14+minecraft:potion#1#8236#16+BiblioCraft:item.BiblioClipboard#{page1:{title:"",taskStates:[0,0,0,0,0,0,0,0,0,],tasks:{task1:"",task2:"",task3:"",task4:"",task6:"",task5:"",task8:"",task7:"",task9:"",},},currentPage:1,totalPages:1,}#0#17+GardenCore:soil_test_kit_used#{RepairCost:2,display:{Name:"Used Test Kit",},}#63#18+GardenCore:soil_test_kit_used#{RepairCost:2,display:{Name:"Used Test Kit",},}#127#20+GardenCore:soil_test_kit_used#{RepairCost:2,display:{Name:"Used Test Kit",},}#8127#22+GardenCore:soil_test_kit_used#{RepairCost:2,display:{Name:"Used Test Kit",},}#8191#24+GardenCore:soil_test_kit_used#{RepairCost:2,display:{Name:"Used Test Kit",},}#16383#26-5
rule27=0,100,minecraft:cauldron-3
rule28=0,100,chisel:nation-3
rule29=0,100,chisel:warningSign-9
rule30=0,100,GardenStuff:lattice-0
rule31=0,100,chisel:technical-13
rule32=0,100,chisel:warningSign-7
rule33=0,100,chisel:technical-12
rule34=0,100,chisel:laboratoryblock-15
rule35=0,100,ExtrabiomesXL:fencegate_cypress-6
rule36=0,100,BiomesOPlenty:poison-1
rule37=2,100,minecraft:stone_button-4
rule38=0,100,CommandBlock:/summon Villager ~ ~1 ~ {CustomName:"I Need More Powah!!",CustomNameVisible:1,Profession:1,Offers:{Recipes:[{rewardExp:0b,maxUses:2147483647,uses:0,buy:{id:1491,Count:12},sell:{id:376,Count:1}},{rewardExp:0b,maxUses:2147483647,uses:0,buy:{id:1491,Count:12},sell:{id:378,Count:1}},{rewardExp:0b,maxUses:2147483647,uses:0,buy:{id:1491,Count:12},sell:{id:377,Count:1}},{rewardExp:0b,maxUses:2147483647,uses:0,buy:{id:1491,Count:12},sell:{id:382,Count:1}},{rewardExp:0b,maxUses:2147483647,uses:0,buy:{id:1491,Count:16},sell:{id:370,Count:1}},{rewardExp:0b,maxUses:2147483647,uses:0,buy:{id:5072,Count:6},sell:{id:4175,Count:1}},{rewardExp:0b,maxUses:2147483647,uses:0,buy:{id:5073,Count:6},sell:{Count:1,id:403,tag:{StoredEnchantments:[{id:51,lvl:1}]}}}]}}:@
rule39=0,100,minecraft:water-8
rule40=0,100,chisel:steelblock-2
rule41=0,100,chisel:gold2-0
rule42=0,100,chisel:warningSign-13
rule43=0,100,chisel:laboratoryblock-1
rule44=0,100,IInventory;minecraft:chest;UndergroundBiomes:fossilPiece#{RepairCost:2,display:{Name:"ribs",},}#3#0+BiomesOPlenty:jarFilled#{RepairCost:2,display:{Name:"sour",},}#1#1+harvestcraft:cabbageItem#{RepairCost:2,display:{Name:"rotting brain",},}#0#2+plantmegapack:desertKangarooPaw#{RepairCost:2,display:{Name:"veins",},}#0#3+BiomesOPlenty:misc#1#3#4+BiomesOPlenty:food#{RepairCost:2,display:{Name:"muscle",},}#1#5+BiomesOPlenty:misc#1#10#6+BiomesOPlenty:jarFilled#{RepairCost:2,display:{Name:"sweet",},}#0#7+harvestcraft:porksausageItem#{RepairCost:2,display:{Name:"intestines",},}#0#8+BiomesOPlenty:hardIce#{RepairCost:2,display:{Name:"Dry Ice",},}#0#9+BiomesOPlenty:hardIce#{RepairCost:2,display:{Name:"Dry Ice",},}#0#10+BiomesOPlenty:hardIce#{RepairCost:2,display:{Name:"Dry Ice",},}#0#11+BiomesOPlenty:hardIce#{RepairCost:2,display:{Name:"Dry Ice",},}#0#12+BiomesOPlenty:hardIce#{RepairCost:2,display:{Name:"Dry Ice",},}#0#13+BiomesOPlenty:hardIce#{RepairCost:2,display:{Name:"Dry Ice",},}#0#14+BiomesOPlenty:hardIce#{RepairCost:2,display:{Name:"Dry Ice",},}#0#15+BiomesOPlenty:hardIce#{RepairCost:2,display:{Name:"Dry Ice",},}#0#16+BiomesOPlenty:hardIce#{RepairCost:2,display:{Name:"Dry Ice",},}#0#17+BiomesOPlenty:hardIce#{RepairCost:2,display:{Name:"Dry Ice",},}#0#18+BiomesOPlenty:hardIce#{RepairCost:2,display:{Name:"Dry Ice",},}#0#19+BiomesOPlenty:hardIce#{RepairCost:2,display:{Name:"Dry Ice",},}#0#20+BiomesOPlenty:hardIce#{RepairCost:2,display:{Name:"Dry Ice",},}#0#21+BiomesOPlenty:hardIce#{RepairCost:2,display:{Name:"Dry Ice",},}#0#22+BiomesOPlenty:hardIce#{RepairCost:2,display:{Name:"Dry Ice",},}#0#23+BiomesOPlenty:hardIce#{RepairCost:2,display:{Name:"Dry Ice",},}#0#24+BiomesOPlenty:hardIce#{RepairCost:2,display:{Name:"Dry Ice",},}#0#25+BiomesOPlenty:hardIce#{RepairCost:2,display:{Name:"Dry Ice",},}#0#26-4
rule45=0,100,chisel:laboratoryblock-14
rule46=0,100,chisel:laboratoryblock-4
rule47=0,100,chisel:technical2-1
rule48=0,100,chisel:technical-14
rule49=0,100,BiomesOPlenty:hell_blood-0
rule50=0,100,minecraft:brewing_stand-0
rule51=0,100,BiomesOPlenty:bones-3
rule52=0,100,minecraft:unpowered_comparator-6
rule53=0,100,BiomesOPlenty:bones-4
rule54=0,100,HopperDuctMod:hopperDuct-5
rule55=0,100,chisel:rebel-4
rule56=0,100,minecraft:unpowered_repeater-14
rule57=0,100,Skull:2:0-1
rule58=0,100,chisel:futura-2
rule59=0,100,HopperDuctMod:hopperDuct-4
rule60=0,100,BiomesOPlenty:hardIce-0
rule61=0,100,minecraft:water-0
rule62=0,100,BiblioCraft:BiblioStuffs-0
rule63=0,100,BiomesOPlenty:poison-0
rule64=0,100,VeganOption:plantMilk-0
rule65=0,100,HopperDuctMod:hopperDuct-3
rule66=0,100,minecraft:hopper-0
rule67=0,100,HopperDuctMod:hopperDuct-2
rule68=0,100,chisel:warningSign-1
rule69=0,100,chisel:iron2-0
rule70=0,100,IInventory;BiblioWoodsBoP:BiblioWoodcase;minecraft:skull#{RepairCost:2,ench:[0:{id:19s,lvl:5s,},],display:{Name:"hard head",},type:4,}#0#0+minecraft:carpet#1#4#1-8
rule71=0,100,VeganOption:rawEnder-7
rule72=0,100,VeganOption:rawEnder-6
rule73=0,100,VeganOption:lyeWater-0
rule74=0,100,VeganOption:lyeWater-1
rule75=0,100,chisel:antiBlock-15
rule76=0,100,GardenStuff:heavy_chain-0
rule77=0,100,chisel:cloud-0

layer
1,1,1,1,1,1,1,1,1,1,1,1,1,1,1,1,1,1,1,1,1,1,1,1,1,1,1,1
1,1,1,1,1,1,1,1,1,1,1,1,1,1,1,1,1,1,1,1,1,1,1,1,1,1,1,1
1,1,1,1,1,1,1,1,1,1,1,1,1,1,1,1,1,1,1,1,1,1,1,1,1,1,1,1
1,1,1,1,1,1,1,1,1,1,1,1,1,1,1,1,1,1,1,1,1,1,1,1,1,1,1,1
1,1,1,1,1,1,1,1,1,1,1,1,1,1,1,1,1,1,1,1,1,1,1,1,1,1,1,1
1,1,1,1,1,1,1,1,1,1,1,1,1,1,1,1,1,1,1,1,1,1,1,1,1,1,1,1
1,1,1,1,1,1,1,1,1,1,1,1,1,1,1,1,1,1,1,1,1,1,1,1,1,1,1,1
1,1,1,1,1,1,1,1,1,1,1,1,1,1,1,1,1,1,1,1,1,1,1,1,1,1,1,1
1,1,1,1,1,1,1,1,1,1,1,1,1,1,1,1,1,1,1,1,1,1,1,1,1,1,1,1
1,1,1,1,1,1,1,1,1,1,1,1,1,1,1,1,1,1,1,1,1,1,1,1,1,1,1,1
1,1,1,1,1,1,1,1,1,1,1,1,1,1,2,1,1,1,1,1,1,1,1,1,1,1,1,1
1,1,1,1,1,1,1,1,1,1,1,1,1,1,1,1,1,1,1,1,1,1,1,1,1,1,1,1
1,1,1,1,1,1,1,1,1,1,1,1,1,1,1,1,1,1,1,1,1,1,1,1,1,1,1,1
1,1,1,1,1,1,1,1,1,1,1,1,1,1,1,1,1,1,1,1,1,1,1,1,1,1,1,1
1,1,1,1,1,1,1,1,1,1,1,1,1,1,1,1,1,1,1,1,1,1,1,1,1,1,1,1
1,1,1,1,1,1,1,1,1,1,1,1,1,1,1,1,1,1,1,1,1,1,1,1,1,1,1,1
1,1,1,1,1,1,1,1,1,1,1,1,1,1,1,1,1,1,1,1,1,1,1,1,1,1,1,1
1,1,1,1,1,1,1,1,1,1,1,1,1,1,1,1,1,1,1,1,1,1,1,1,1,1,1,1
1,1,1,1,1,1,1,1,1,1,1,1,1,1,1,1,1,1,1,1,1,1,1,1,1,1,1,1
1,1,1,1,1,1,1,1,1,1,1,1,1,1,1,1,1,1,1,1,1,1,1,1,1,1,1,1
1,1,1,1,1,1,1,1,1,1,1,1,1,1,1,1,1,1,1,1,1,1,1,1,1,1,1,1
endlayer

layer
1,1,1,1,1,1,1,1,1,1,1,1,1,1,1,1,1,1,1,1,1,1,1,1,1,1,1,1
1,1,1,1,1,1,1,1,1,1,1,1,1,1,1,1,1,1,1,1,1,1,1,1,1,1,1,1
1,1,1,1,1,1,1,1,1,1,1,1,1,1,1,1,1,1,1,1,1,1,1,1,1,1,1,1
1,1,1,1,1,1,1,1,1,1,1,1,1,1,1,1,1,1,1,1,1,1,1,1,1,1,1,1
1,1,1,1,1,1,1,1,1,1,1,1,1,1,1,1,1,1,1,1,1,1,1,1,1,1,1,1
1,1,1,1,1,1,1,1,1,1,1,1,1,1,1,1,1,1,1,1,1,1,1,1,1,1,1,1
1,1,1,1,1,1,1,1,1,1,1,1,1,1,1,1,1,1,1,1,1,1,1,1,1,1,1,1
1,1,1,1,1,1,1,1,1,1,0,1,1,1,1,1,1,1,1,1,1,1,1,1,1,1,1,1
1,1,1,1,1,1,1,1,1,1,1,2,2,2,2,2,1,1,1,1,1,1,1,1,1,1,1,1
1,1,1,1,1,1,1,1,1,1,1,2,2,2,2,2,1,1,1,1,1,1,1,1,1,1,1,1
1,1,1,1,1,1,1,1,1,1,1,2,2,2,0,2,1,1,1,1,1,1,1,1,1,1,1,1
1,0,0,1,1,1,1,1,1,1,1,2,2,2,2,2,1,1,1,1,1,1,1,1,1,1,1,1
1,1,1,1,1,1,1,1,1,1,1,2,2,2,2,2,1,1,1,1,1,1,1,1,1,1,1,1
1,1,1,1,1,1,1,1,1,1,1,1,1,1,1,1,1,1,1,1,1,1,1,1,1,1,1,1
1,1,1,1,1,1,1,1,1,1,1,1,1,1,1,1,1,1,1,1,1,1,1,1,1,1,1,1
1,1,1,1,1,1,1,1,1,1,1,1,1,1,1,1,1,1,1,1,1,1,1,1,1,1,1,1
1,1,1,1,1,1,1,1,1,1,1,1,1,1,1,1,1,1,1,1,1,1,1,1,1,1,1,1
1,1,1,1,1,1,1,1,1,1,1,1,1,1,1,1,1,1,1,1,1,1,1,1,1,1,1,1
1,1,1,1,1,1,1,1,1,1,1,1,1,1,1,1,1,1,1,1,1,1,1,1,1,1,1,1
1,1,1,1,1,1,1,1,1,1,1,1,1,1,1,1,1,1,1,1,1,1,1,1,1,1,1,1
1,1,1,1,1,1,1,1,1,1,1,1,1,1,1,1,1,1,1,1,1,1,1,1,1,1,1,1
endlayer

layer
1,1,1,1,1,1,1,1,1,1,1,1,1,1,1,1,1,1,1,1,1,1,1,1,1,1,1,1
1,1,1,1,1,1,1,1,1,1,1,1,1,1,1,1,1,1,1,1,1,1,1,1,1,1,1,1
1,1,1,1,1,1,1,1,1,1,1,1,1,1,1,1,1,1,1,0,1,1,1,1,1,1,1,1
1,1,1,1,1,1,1,1,1,1,1,1,1,1,1,1,1,1,1,0,1,1,1,1,1,1,1,1
1,1,1,1,1,1,1,1,1,1,1,1,1,1,1,1,1,1,1,1,1,1,1,1,1,1,1,1
1,1,1,1,1,1,1,1,1,1,1,1,1,1,1,0,1,1,1,1,1,0,1,1,1,1,1,1
1,1,1,1,1,1,1,1,1,1,0,1,1,1,1,1,1,1,1,1,1,0,1,1,1,1,1,1
1,1,1,1,1,1,1,1,1,1,1,2,2,2,2,2,1,1,1,1,1,1,1,1,1,1,1,1
1,1,1,1,1,1,1,1,1,1,2,6,5,4,3,0,2,1,1,1,1,1,1,1,1,1,1,1
1,1,1,1,1,1,1,1,1,1,2,8,0,0,7,0,2,1,1,1,1,1,1,1,1,1,1,1
1,1,1,1,1,1,1,1,1,1,2,10,0,2,9,0,2,0,1,1,1,1,1,1,1,1,1,1
1,1,1,1,1,1,1,1,1,1,2,12,0,7,11,0,2,1,1,1,1,1,1,1,1,1,1,1
1,1,1,1,1,1,1,1,1,1,2,16,15,14,13,0,2,1,1,1,1,1,1,1,1,1,1,1
1,1,1,1,1,1,1,1,1,1,2,2,2,2,2,2,1,1,1,1,1,1,1,1,1,1,1,1
1,1,1,1,1,1,1,1,1,1,1,1,1,1,1,1,1,1,1,1,1,1,1,1,1,1,1,1
1,1,1,1,1,1,1,1,1,1,1,1,1,1,1,1,1,1,1,1,1,1,1,1,1,1,1,1
1,1,1,1,1,1,1,1,1,1,1,1,1,1,1,1,1,1,1,1,1,1,1,1,1,1,1,1
1,1,1,1,1,1,1,1,1,1,1,1,1,1,1,1,1,1,1,1,1,1,1,1,1,1,1,1
1,1,1,1,1,1,1,1,1,1,1,1,1,1,1,1,1,1,1,1,1,1,1,1,1,1,1,1
1,1,1,1,1,1,1,1,1,1,1,1,1,1,1,1,1,1,1,1,1,1,1,1,1,1,1,1
1,1,1,1,1,1,1,1,1,1,1,1,1,1,1,1,1,1,1,1,1,1,1,1,1,1,1,1
endlayer

layer
1,1,1,1,1,1,1,1,1,1,1,1,1,1,1,1,1,1,1,1,1,1,1,1,1,1,1,1
1,1,1,1,1,1,1,1,1,1,1,1,1,1,1,1,1,1,1,1,1,1,1,1,1,1,1,1
1,1,1,1,1,1,1,1,1,1,1,1,1,1,1,1,1,1,1,1,1,1,1,1,1,1,1,1
1,1,1,1,1,1,1,1,1,1,1,1,1,1,1,1,1,1,1,1,1,1,1,1,1,1,1,1
1,1,1,1,1,1,1,1,1,1,1,1,1,1,1,1,1,1,1,1,1,1,1,1,1,1,1,1
1,1,1,1,1,1,1,1,1,1,1,1,1,1,1,1,1,1,1,1,1,1,1,1,1,1,1,1
1,1,1,1,1,1,1,1,1,1,1,1,1,1,1,1,1,1,1,1,1,1,1,1,1,1,1,1
1,1,1,1,1,1,1,1,1,1,1,2,2,2,2,2,1,1,1,1,1,1,1,1,1,1,1,1
1,1,1,1,1,1,1,1,0,1,2,0,0,17,0,0,2,1,1,1,1,1,1,1,1,1,1,1
1,1,1,1,1,1,1,1,1,1,2,6,0,0,0,0,2,1,1,1,1,1,1,1,1,1,1,1
1,1,1,1,1,1,1,1,1,1,2,6,0,0,0,0,2,1,1,1,1,1,1,1,1,1,1,1
1,1,1,1,1,1,1,1,1,1,2,0,0,0,0,0,2,1,1,1,1,1,1,1,1,1,1,1
1,1,1,1,1,1,1,0,1,1,2,0,0,18,0,0,2,1,1,1,1,1,1,1,1,1,1,1
1,1,1,1,1,1,1,1,1,1,1,2,2,2,2,2,1,1,1,1,1,1,1,1,1,1,1,1
1,1,1,1,0,1,1,1,1,1,1,1,1,1,1,1,1,1,1,1,1,1,1,1,1,1,1,1
1,1,1,1,1,1,1,1,1,1,1,1,1,1,1,1,1,1,1,1,1,1,1,1,1,1,1,1
1,1,1,1,1,1,1,1,1,1,1,1,1,1,1,1,1,1,1,1,1,1,1,1,1,1,1,1
1,1,1,1,1,1,1,1,1,1,1,1,1,1,1,1,1,1,1,1,1,1,1,1,1,1,1,1
1,1,1,1,1,1,1,1,1,1,1,1,1,1,1,1,1,1,1,1,1,1,1,1,1,1,1,1
1,1,1,1,1,1,1,1,1,1,1,1,1,1,1,1,1,1,1,1,1,1,1,1,1,1,1,1
1,1,1,1,1,1,1,1,1,1,1,1,1,1,1,1,1,1,1,1,1,1,1,1,1,1,1,1
endlayer

layer
1,1,1,1,1,1,1,1,1,1,1,1,1,1,1,1,1,1,1,1,1,1,1,1,1,1,1,1
1,1,1,1,1,1,1,1,1,1,1,1,1,1,1,1,1,1,1,1,1,1,1,1,1,1,1,1
1,1,1,1,1,1,1,1,1,1,1,1,1,1,1,1,1,1,1,1,1,1,1,1,1,1,1,1
1,1,1,1,1,1,1,1,1,1,1,1,1,1,1,1,1,1,1,1,1,1,1,1,1,1,1,1
1,1,1,1,1,1,1,1,1,1,1,1,1,1,1,1,1,1,1,1,1,1,1,1,1,1,1,1
1,1,1,1,1,1,1,1,1,1,1,1,1,1,1,1,1,1,1,1,1,1,1,1,1,1,1,1
1,1,1,1,1,1,1,1,1,1,1,1,1,1,1,1,1,1,1,1,1,1,1,1,1,1,1,1
1,1,1,0,1,1,1,1,1,1,1,1,1,1,1,1,1,1,1,1,1,1,1,1,1,1,1,1
1,1,1,1,1,1,1,1,1,1,1,2,2,2,2,2,1,1,1,1,1,1,1,1,1,1,1,1
1,1,1,1,1,0,1,1,1,1,1,2,2,2,2,2,1,1,1,1,1,1,1,1,1,1,1,1
1,1,1,1,1,1,1,1,1,1,1,2,2,2,2,2,1,1,1,1,1,1,1,1,1,1,1,1
1,1,1,1,1,1,1,1,1,1,1,2,2,2,2,2,1,1,1,1,1,1,1,1,1,1,1,1
1,1,1,1,1,0,1,1,1,1,1,2,2,2,2,2,1,1,1,1,1,1,1,1,1,1,1,1
1,1,1,1,1,1,1,1,1,1,1,1,1,1,1,1,1,1,1,1,1,1,1,1,1,1,1,1
1,1,1,1,0,1,1,1,1,1,1,1,1,1,1,1,1,1,1,1,1,1,1,1,1,1,1,1
1,1,1,1,1,1,1,1,1,1,1,1,1,1,1,1,1,1,1,1,1,1,1,1,1,1,1,1
1,1,1,1,1,1,1,1,1,1,1,1,1,1,1,1,1,1,1,1,1,1,1,1,1,1,1,1
1,1,1,1,1,1,1,1,1,1,1,1,1,1,1,1,1,1,1,1,1,1,1,1,1,1,1,1
1,1,1,1,1,1,1,1,1,1,1,1,1,1,1,1,1,1,1,1,1,1,1,1,1,1,1,1
1,1,1,1,1,1,1,1,1,1,1,1,1,1,1,1,1,1,1,1,1,1,1,1,1,1,1,1
1,1,1,1,1,1,1,1,1,1,1,1,1,1,1,1,1,1,1,1,1,1,1,1,1,1,1,1
endlayer

layer
1,1,1,1,1,1,1,1,1,1,1,1,1,1,1,1,1,1,1,1,1,1,1,1,1,1,1,1
1,1,1,1,1,1,1,1,1,1,1,1,1,1,1,1,1,1,1,1,1,1,1,1,1,1,1,1
1,1,1,1,1,1,1,1,1,1,1,1,1,1,1,1,1,1,1,1,1,1,1,1,1,1,1,1
1,1,1,1,1,1,1,1,1,1,1,1,1,1,1,1,1,1,1,1,1,1,1,1,1,1,1,1
1,1,1,1,1,1,1,1,1,1,1,1,1,1,1,1,1,1,1,1,1,1,1,1,1,1,1,1
1,1,1,1,1,1,1,1,1,1,1,1,1,1,1,1,1,1,1,1,1,1,1,1,1,1,1,1
1,1,1,1,1,1,1,1,1,1,1,1,1,1,1,1,1,1,1,1,1,1,1,1,1,1,1,1
1,1,1,1,1,1,1,1,1,1,1,1,1,1,1,1,1,1,1,1,1,1,1,1,1,1,1,1
1,1,1,1,1,1,1,1,1,1,1,1,1,1,1,1,1,1,1,1,1,1,1,1,1,1,1,1
1,1,1,1,1,1,1,1,1,1,1,1,1,1,1,1,1,1,1,1,1,1,1,1,1,1,1,1
1,1,1,1,1,1,1,1,1,1,1,1,1,1,1,1,1,1,1,1,1,1,1,1,1,1,1,1
1,1,1,1,1,1,1,1,1,1,1,1,1,1,1,1,1,1,1,1,1,1,1,1,1,1,1,1
1,1,1,1,1,1,1,1,1,1,1,1,1,1,1,1,1,1,1,1,1,1,1,1,1,1,1,1
1,1,1,1,1,1,1,1,1,1,1,1,1,1,1,1,1,1,1,1,1,1,1,1,1,1,1,1
1,1,1,1,1,1,1,1,1,1,1,1,1,1,1,1,1,1,1,1,1,1,1,1,1,1,1,1
1,1,1,1,1,1,1,1,1,1,1,1,1,1,1,1,1,1,1,1,1,1,1,1,1,1,1,1
1,1,1,1,1,1,1,1,1,1,1,1,1,1,1,1,1,1,1,1,1,1,1,1,1,1,1,1
1,1,1,1,1,1,1,1,1,1,1,1,1,1,1,1,1,1,1,1,1,1,1,1,1,1,1,1
1,1,1,1,1,1,1,1,1,1,1,1,1,1,1,1,1,1,1,1,1,1,1,1,1,1,1,1
1,1,1,1,1,1,1,1,1,1,1,1,1,1,1,1,1,1,1,1,1,1,1,1,1,1,1,1
1,1,1,1,1,1,1,1,1,1,1,1,1,1,1,1,1,1,1,1,1,1,1,1,1,1,1,1
endlayer

layer
0,0,0,0,0,0,0,0,0,0,0,0,0,19,19,19,19,19,19,19,0,0,0,0,0,0,0,0
0,0,0,0,0,0,0,0,0,0,0,19,19,19,19,19,19,19,19,19,19,19,0,0,0,0,0,0
0,0,0,0,0,0,0,0,0,0,19,19,19,19,19,19,19,19,19,19,19,19,19,0,0,0,0,0
0,0,0,0,0,0,0,0,0,19,19,19,19,19,19,21,20,20,19,19,19,19,19,19,0,0,0,0
0,0,0,0,0,0,0,0,19,19,19,19,19,19,19,19,19,19,19,19,19,19,19,19,19,0,0,0
0,0,0,0,0,0,0,19,19,19,19,19,19,19,19,19,19,19,19,19,19,19,19,19,19,19,0,0
0,0,0,0,0,0,0,19,19,19,19,19,19,19,19,19,19,19,19,19,19,19,19,19,19,19,0,0
0,0,0,0,0,0,19,19,19,19,19,19,19,19,19,19,19,19,19,19,19,19,19,19,19,19,19,0
0,0,0,0,0,0,19,19,19,19,19,19,19,19,19,19,19,19,19,19,19,19,19,19,19,19,19,0
0,0,0,0,0,0,19,19,19,19,19,19,19,19,19,19,19,19,19,19,19,19,19,19,19,19,19,19
0,0,0,0,0,0,19,19,19,19,19,19,19,19,19,19,19,19,19,19,19,19,19,19,19,19,19,19
0,0,0,0,0,0,19,19,19,19,19,19,19,19,19,19,19,19,19,19,19,19,19,19,19,19,19,19
0,0,0,0,0,0,19,19,19,19,19,19,19,19,19,19,19,19,19,19,19,19,19,19,19,19,19,0
0,0,0,0,0,0,19,19,19,19,19,19,19,19,19,19,19,19,19,19,19,19,19,19,19,19,19,0
0,0,0,0,0,0,0,19,19,19,19,19,19,19,19,19,19,19,19,19,19,19,19,19,19,19,0,0
0,0,0,0,0,0,0,19,19,19,19,19,19,19,19,19,19,19,19,19,19,19,19,19,19,19,0,0
0,0,0,0,0,0,0,0,19,19,19,19,19,19,19,19,19,19,19,19,19,19,19,19,19,0,0,0
0,0,0,0,0,0,0,0,0,19,19,19,19,19,19,19,19,19,19,19,19,19,19,19,0,0,0,0
0,0,0,0,0,0,0,0,0,0,19,19,19,19,19,19,19,19,19,19,19,19,19,0,0,0,0,0
0,0,0,0,0,0,0,0,0,0,0,19,19,19,19,19,19,19,19,19,19,19,0,0,0,0,0,0
0,0,0,0,0,0,0,0,0,0,0,0,0,19,19,19,19,19,19,19,0,0,0,0,0,0,0,0
endlayer

layer
0,0,0,0,0,0,0,0,0,0,0,0,0,19,19,19,19,19,19,19,0,0,0,0,0,0,0,0
0,0,0,0,0,0,0,0,0,0,0,19,19,24,19,23,23,23,19,22,19,19,0,0,0,0,0,0
0,0,0,0,0,0,0,0,0,0,19,24,24,19,25,0,26,0,25,19,22,22,19,0,0,0,0,0
0,0,0,0,0,0,0,0,0,19,24,24,19,0,28,0,0,0,27,0,19,22,22,19,0,0,0,0
0,0,0,0,0,0,0,0,19,24,24,19,0,0,28,28,29,28,28,0,0,19,22,22,19,0,0,0
0,0,0,0,0,0,0,19,24,24,19,0,0,0,0,0,0,0,0,0,0,0,19,22,22,19,0,0
0,0,0,0,0,0,0,19,24,19,0,0,0,0,0,0,0,0,0,0,0,0,0,19,22,19,0,0
0,0,0,0,0,0,19,24,19,0,0,0,0,0,0,0,0,0,0,0,0,0,0,19,22,22,19,0
0,0,0,0,0,0,19,19,31,0,0,0,0,0,30,30,30,30,0,0,0,0,0,0,19,22,19,0
0,0,0,0,0,0,19,34,0,0,0,0,0,30,32,33,33,32,30,0,0,0,0,0,0,19,19,19
0,0,0,0,0,0,19,34,0,0,0,0,0,30,33,33,33,33,30,0,0,0,0,0,0,35,0,35
0,0,0,0,0,0,19,34,0,0,0,0,0,30,32,33,33,32,30,0,0,0,0,0,0,19,19,19
0,0,0,0,0,0,19,19,31,0,0,0,0,0,30,30,30,30,0,0,0,0,0,0,19,36,19,0
0,0,0,0,0,0,19,39,19,0,0,0,0,0,0,0,0,0,37,0,0,0,0,19,36,36,19,0
0,0,0,0,0,0,0,19,39,19,0,0,0,0,0,0,0,0,0,0,0,0,0,19,36,19,0,0
0,0,0,0,0,0,0,19,39,39,19,0,0,0,0,0,0,0,0,0,0,0,19,36,36,19,0,0
0,0,0,0,0,0,0,0,19,39,39,19,40,40,41,41,42,41,41,40,40,19,36,36,19,0,0,0
0,0,0,0,0,0,0,0,0,19,39,39,19,40,41,0,0,0,41,40,19,36,36,19,0,0,0,0
0,0,0,0,0,0,0,0,0,0,19,39,39,19,43,0,44,0,43,19,36,36,19,0,0,0,0,0
0,0,0,0,0,0,0,0,0,0,0,19,19,39,19,45,45,45,19,36,19,19,0,0,0,0,0,0
0,0,0,0,0,0,0,0,0,0,0,0,0,19,19,19,19,19,19,19,0,0,0,0,0,0,0,0
endlayer

layer
0,0,0,0,0,0,0,0,0,0,0,0,0,19,19,46,46,46,19,19,0,0,0,0,0,0,0,0
0,0,0,0,0,0,0,0,0,0,0,19,19,24,19,47,48,47,19,22,19,19,0,0,0,0,0,0
0,0,0,0,0,0,0,0,0,0,19,24,24,19,25,0,0,0,25,19,22,22,19,0,0,0,0,0
0,0,0,0,0,0,0,0,0,19,24,24,19,0,0,0,0,0,0,0,19,22,49,19,0,0,0,0
0,0,0,0,0,0,0,0,19,24,24,19,0,0,0,50,0,50,0,0,0,19,22,22,19,0,0,0
0,0,0,0,0,0,0,19,24,24,19,0,0,0,0,0,0,0,0,0,0,0,19,22,22,19,0,0
0,0,0,0,0,0,0,19,24,19,0,0,0,0,0,0,0,0,0,0,0,0,0,19,22,19,0,0
0,0,0,0,0,0,19,24,19,0,0,0,0,0,0,0,0,0,0,0,0,0,0,19,22,22,19,0
0,0,0,0,0,0,19,19,31,0,0,0,0,0,0,0,0,0,0,0,0,0,0,0,19,22,19,0
0,0,0,0,0,0,19,55,0,0,0,0,0,0,54,53,52,51,0,0,0,0,0,0,0,19,19,19
0,0,0,0,0,0,19,58,0,0,0,0,0,0,57,56,0,0,0,0,0,0,0,0,0,35,0,35
0,0,0,0,0,0,19,55,0,0,0,0,0,0,59,53,52,51,0,0,0,0,0,0,0,19,19,19
0,0,0,0,0,0,19,19,31,0,0,0,0,0,0,0,0,0,0,0,0,0,0,0,19,36,19,0
0,0,0,0,0,0,19,39,19,0,0,0,0,0,0,0,0,0,0,0,0,0,0,19,36,36,19,0
0,0,0,0,0,0,0,19,39,19,0,0,0,0,0,0,0,0,0,0,0,0,0,19,36,19,0,0
0,0,0,0,0,0,0,19,39,39,19,0,0,0,0,0,0,0,0,0,0,0,19,36,36,19,0,0
0,0,0,0,0,0,0,0,19,61,39,19,40,40,0,0,0,0,0,60,40,19,36,36,19,0,0,0
0,0,0,0,0,0,0,0,0,19,39,39,19,40,62,0,0,0,62,40,19,36,36,19,0,0,0,0
0,0,0,0,0,0,0,0,0,0,19,39,39,19,43,0,0,0,43,19,36,36,19,0,0,0,0,0
0,0,0,0,0,0,0,0,0,0,0,19,19,39,19,48,47,48,19,63,19,19,0,0,0,0,0,0
0,0,0,0,0,0,0,0,0,0,0,0,0,19,19,19,19,19,19,19,0,0,0,0,0,0,0,0
endlayer

layer
0,0,0,0,0,0,0,0,0,0,0,0,0,19,19,19,19,19,19,19,0,0,0,0,0,0,0,0
0,0,0,0,0,0,0,0,0,0,0,19,19,64,19,23,23,23,19,49,19,19,0,0,0,0,0,0
0,0,0,0,0,0,0,0,0,0,19,64,64,19,25,0,0,0,25,19,49,49,19,0,0,0,0,0
0,0,0,0,0,0,0,0,0,19,64,64,19,0,0,0,0,0,0,0,19,49,49,19,0,0,0,0
0,0,0,0,0,0,0,0,19,64,64,19,0,0,67,66,0,66,65,0,0,19,49,49,19,0,0,0
0,0,0,0,0,0,0,19,64,64,19,0,0,0,0,0,0,0,0,0,0,0,19,49,49,19,0,0
0,0,0,0,0,0,0,19,64,19,0,0,0,0,0,0,0,0,0,0,0,0,0,19,49,19,0,0
0,0,0,0,0,0,19,64,19,0,0,0,0,0,0,0,0,0,0,0,0,0,0,19,49,49,19,0
0,0,0,0,0,0,19,19,31,0,0,0,0,0,0,0,0,0,0,0,0,0,0,0,19,49,19,0
0,0,0,0,0,0,19,34,0,0,0,0,0,0,0,0,0,0,0,0,0,0,0,0,0,19,19,19
0,0,0,0,0,0,19,34,0,0,0,0,0,0,0,0,0,0,0,0,0,0,0,0,0,19,31,19
0,0,0,0,0,0,19,34,0,0,0,0,0,0,0,0,0,0,0,0,0,0,0,0,0,19,19,19
0,0,0,0,0,0,19,19,31,0,0,0,0,0,0,0,0,0,0,0,0,0,0,0,19,63,19,0
0,0,0,0,0,0,19,61,19,0,0,0,0,0,0,0,0,0,0,0,0,0,0,19,63,63,19,0
0,0,0,0,0,0,0,19,61,19,0,0,0,0,0,0,0,0,0,0,0,0,0,19,63,19,0,0
0,0,0,0,0,0,0,19,61,61,19,0,0,0,0,0,0,0,0,0,0,0,19,63,63,19,0,0
0,0,0,0,0,0,0,0,19,61,61,19,0,60,0,0,0,0,0,40,0,19,63,63,19,0,0,0
0,0,0,0,0,0,0,0,0,19,61,61,19,40,0,0,0,0,0,40,19,63,63,19,0,0,0,0
0,0,0,0,0,0,0,0,0,0,19,61,61,19,43,0,0,0,43,19,63,63,19,0,0,0,0,0
0,0,0,0,0,0,0,0,0,0,0,19,19,61,19,45,45,45,19,63,19,19,0,0,0,0,0,0
0,0,0,0,0,0,0,0,0,0,0,0,0,19,19,19,19,19,19,19,0,0,0,0,0,0,0,0
endlayer

layer
0,0,0,0,0,0,0,0,0,0,0,0,0,0,0,0,0,0,0,0,0,0,0,0,0,0,0,0
0,0,0,0,0,0,0,0,0,0,0,19,19,19,19,19,19,19,19,19,19,19,0,0,0,0,0,0
0,0,0,0,0,0,0,0,0,0,19,19,19,19,25,25,25,25,25,19,19,19,19,0,0,0,0,0
0,0,0,0,0,0,0,0,0,19,19,19,19,19,19,19,19,19,19,19,19,19,19,19,0,0,0,0
0,0,0,0,0,0,0,0,19,19,19,0,19,19,19,19,19,19,19,19,19,0,19,19,19,0,0,0
0,0,0,0,0,0,0,19,19,19,0,0,68,69,69,69,69,69,69,69,68,0,0,19,19,19,0,0
0,0,0,0,0,0,0,19,19,0,0,0,0,0,0,0,0,0,0,0,0,0,0,0,19,19,0,0
0,0,0,0,0,0,0,19,0,0,0,0,0,0,0,0,0,0,0,0,0,0,0,0,19,19,0,0
0,0,0,0,0,0,0,19,31,0,0,0,0,0,0,0,0,0,0,0,0,0,0,0,0,19,0,0
0,0,0,0,0,0,0,19,31,0,0,0,0,0,0,0,0,0,0,0,0,0,0,0,0,19,0,0
0,0,0,0,0,0,0,19,31,0,0,0,0,0,0,0,0,0,0,0,0,0,0,0,0,19,0,0
0,0,0,0,0,0,0,19,31,0,0,0,0,0,0,0,0,0,0,0,0,0,0,0,0,19,0,0
0,0,0,0,0,0,0,19,31,0,0,0,0,0,0,0,0,0,0,0,0,0,0,0,0,19,0,0
0,0,0,0,0,0,0,19,0,0,0,0,0,0,0,0,0,0,0,0,0,0,0,0,19,19,0,0
0,0,0,0,0,0,0,19,19,0,0,0,0,0,0,0,0,0,0,0,0,0,0,0,19,19,0,0
0,0,0,0,0,0,0,19,19,19,0,0,0,0,0,0,0,0,0,0,0,0,0,19,19,19,0,0
0,0,0,0,0,0,0,0,19,19,19,0,0,40,40,40,70,60,40,40,0,0,19,19,19,0,0,0
0,0,0,0,0,0,0,0,0,19,19,19,0,40,40,40,40,40,40,40,0,19,19,19,0,0,0,0
0,0,0,0,0,0,0,0,0,0,19,19,19,40,43,43,43,43,43,40,19,19,19,0,0,0,0,0
0,0,0,0,0,0,0,0,0,0,0,19,19,19,19,19,19,19,19,19,19,19,0,0,0,0,0,0
0,0,0,0,0,0,0,0,0,0,0,0,0,0,0,0,0,0,0,0,0,0,0,0,0,0,0,0
endlayer

layer
0,0,0,0,0,0,0,0,0,0,0,0,0,0,0,0,0,0,0,0,0,0,0,0,0,0,0,0
0,0,0,0,0,0,0,0,0,0,0,0,19,19,19,19,19,19,19,19,19,0,0,0,0,0,0,0
0,0,0,0,0,0,0,0,0,0,0,19,19,19,19,19,19,19,19,19,19,19,0,0,0,0,0,0
0,0,0,0,0,0,0,0,0,0,19,0,19,72,72,72,71,72,71,71,19,0,19,0,0,0,0,0
0,0,0,0,0,0,0,0,0,19,0,0,19,72,72,72,71,72,71,71,19,0,0,19,0,0,0,0
0,0,0,0,0,0,0,0,19,0,0,0,69,19,19,19,19,19,19,19,69,0,0,0,19,0,0,0
0,0,0,0,0,0,0,19,0,0,0,0,0,0,0,0,0,0,0,0,0,0,0,0,0,19,0,0
0,0,0,0,0,0,0,19,0,0,0,0,0,0,0,0,0,0,0,0,0,0,0,0,0,19,0,0
0,0,0,0,0,0,0,19,0,0,0,0,0,0,0,0,0,0,0,0,0,0,0,0,0,19,0,0
0,0,0,0,0,0,0,19,0,0,0,0,0,0,0,0,0,0,0,0,0,0,0,0,0,19,0,0
0,0,0,0,0,0,0,19,0,0,0,0,0,0,0,0,0,0,0,0,0,0,0,0,0,19,0,0
0,0,0,0,0,0,0,19,0,0,0,0,0,0,0,0,0,0,0,0,0,0,0,0,0,19,0,0
0,0,0,0,0,0,0,19,0,0,0,0,0,0,0,0,0,0,0,0,0,0,0,0,0,19,0,0
0,0,0,0,0,0,0,19,0,0,0,0,0,0,0,0,0,0,0,0,0,0,0,0,0,19,0,0
0,0,0,0,0,0,0,19,0,0,0,0,0,0,0,0,0,0,0,0,0,0,0,0,0,19,0,0
0,0,0,0,0,0,0,0,19,0,0,0,0,0,0,0,0,0,0,0,0,0,0,0,19,0,0,0
0,0,0,0,0,0,0,0,0,19,0,0,0,60,19,19,19,19,19,40,0,0,0,19,0,0,0,0
0,0,0,0,0,0,0,0,0,0,19,0,0,40,49,49,49,49,49,40,0,0,19,0,0,0,0,0
0,0,0,0,0,0,0,0,0,0,0,19,0,40,40,40,40,40,40,40,0,19,0,0,0,0,0,0
0,0,0,0,0,0,0,0,0,0,0,0,19,19,19,19,19,19,19,19,19,0,0,0,0,0,0,0
0,0,0,0,0,0,0,0,0,0,0,0,0,0,0,0,0,0,0,0,0,0,0,0,0,0,0,0
endlayer

layer
0,0,0,0,0,0,0,0,0,0,0,0,0,0,0,0,0,0,0,0,0,0,0,0,0,0,0,0
0,0,0,0,0,0,0,0,0,0,0,0,0,0,0,0,0,0,0,0,0,0,0,0,0,0,0,0
0,0,0,0,0,0,0,0,0,0,0,0,19,19,19,19,19,19,19,19,19,0,0,0,0,0,0,0
0,0,0,0,0,0,0,0,0,0,0,19,19,63,63,36,63,36,63,63,19,19,0,0,0,0,0,0
0,0,0,0,0,0,0,0,0,0,19,0,19,63,36,63,36,63,63,63,19,0,19,0,0,0,0,0
0,0,0,0,0,0,0,0,0,19,0,0,69,19,19,19,19,19,19,19,69,0,0,19,0,0,0,0
0,0,0,0,0,0,0,0,19,0,0,0,0,0,0,0,0,0,0,0,0,0,19,19,19,0,0,0
0,0,0,0,0,0,0,0,19,0,0,0,0,0,0,0,0,0,0,0,0,0,19,19,19,0,0,0
0,0,0,0,0,0,0,0,19,0,0,0,0,0,0,0,0,0,0,0,0,0,19,19,19,0,0,0
0,0,0,0,0,0,0,0,19,0,0,0,0,0,0,0,0,0,0,0,0,0,19,19,19,0,0,0
0,0,0,0,0,0,0,0,19,0,0,0,0,0,0,0,0,0,0,0,0,0,19,19,19,0,0,0
0,0,0,0,0,0,0,0,19,0,0,0,0,0,0,0,0,0,0,0,0,0,19,19,19,0,0,0
0,0,0,0,0,0,0,0,19,0,0,0,0,0,0,0,0,0,0,0,0,0,19,19,19,0,0,0
0,0,0,0,0,0,0,0,19,0,0,0,0,0,0,0,0,0,0,0,0,0,19,19,19,0,0,0
0,0,0,0,0,0,0,0,19,0,0,0,0,0,0,0,0,0,0,0,0,0,19,19,19,0,0,0
0,0,0,0,0,0,0,0,0,19,0,0,0,0,0,0,0,0,0,0,0,0,0,19,0,0,0,0
0,0,0,0,0,0,0,0,0,0,19,0,0,40,19,19,19,19,19,60,0,0,19,0,0,0,0,0
0,0,0,0,0,0,0,0,0,0,0,19,0,40,73,73,74,73,73,40,0,19,0,0,0,0,0,0
0,0,0,0,0,0,0,0,0,0,0,0,19,19,19,19,19,19,19,19,19,0,0,0,0,0,0,0
0,0,0,0,0,0,0,0,0,0,0,0,0,0,0,0,0,0,0,0,0,0,0,0,0,0,0,0
0,0,0,0,0,0,0,0,0,0,0,0,0,0,0,0,0,0,0,0,0,0,0,0,0,0,0,0
endlayer

layer
0,0,0,0,0,0,0,0,0,0,0,0,0,0,0,0,0,0,0,0,0,0,0,0,0,0,0,0
0,0,0,0,0,0,0,0,0,0,0,0,0,0,0,0,0,0,0,0,0,0,0,0,0,0,0,0
0,0,0,0,0,0,0,0,0,0,0,0,19,19,19,19,19,19,19,19,19,0,0,0,0,0,0,0
0,0,0,0,0,0,0,0,0,0,0,19,19,19,19,19,19,19,19,19,19,19,0,0,0,0,0,0
0,0,0,0,0,0,0,0,0,0,19,0,19,19,19,19,19,19,19,19,19,0,19,0,0,0,0,0
0,0,0,0,0,0,0,0,0,19,0,0,68,69,69,69,69,69,69,69,68,0,0,19,0,0,0,0
0,0,0,0,0,0,0,0,19,0,0,0,0,0,0,0,0,0,0,0,0,0,19,19,19,0,0,0
0,0,0,0,0,0,0,0,19,0,0,0,0,0,0,0,0,0,0,0,0,0,19,63,19,0,0,0
0,0,0,0,0,0,0,0,19,0,0,0,0,0,0,0,0,0,0,0,0,0,19,19,19,0,0,0
0,0,0,0,0,0,0,0,19,0,0,0,0,0,30,30,30,30,0,0,0,0,19,61,19,0,0,0
0,0,0,0,0,0,0,0,19,0,0,0,0,0,0,75,75,0,0,0,0,0,19,19,19,0,0,0
0,0,0,0,0,0,0,0,19,0,0,0,0,0,30,30,30,30,0,0,0,0,19,71,19,0,0,0
0,0,0,0,0,0,0,0,19,0,0,0,0,0,0,0,0,0,0,0,0,0,19,19,19,0,0,0
0,0,0,0,0,0,0,0,19,0,0,0,0,0,0,0,0,0,0,0,0,0,19,49,19,0,0,0
0,0,0,0,0,0,0,0,19,0,0,0,0,0,0,0,0,0,0,0,0,0,19,19,19,0,0,0
0,0,0,0,0,0,0,0,0,19,0,0,0,0,0,0,0,0,0,0,0,0,0,19,0,0,0,0
0,0,0,0,0,0,0,0,0,0,19,0,0,0,60,40,0,40,40,0,0,0,19,0,0,0,0,0
0,0,0,0,0,0,0,0,0,0,0,19,0,0,40,40,40,40,40,0,0,19,0,0,0,0,0,0
0,0,0,0,0,0,0,0,0,0,0,0,19,19,19,19,19,19,19,19,19,0,0,0,0,0,0,0
0,0,0,0,0,0,0,0,0,0,0,0,0,0,0,0,0,0,0,0,0,0,0,0,0,0,0,0
0,0,0,0,0,0,0,0,0,0,0,0,0,0,0,0,0,0,0,0,0,0,0,0,0,0,0,0
endlayer

layer
0,0,0,0,0,0,0,0,0,0,0,0,0,0,0,0,0,0,0,0,0,0,0,0,0,0,0,0
0,0,0,0,0,0,0,0,0,0,0,0,0,0,0,0,0,0,0,0,0,0,0,0,0,0,0,0
0,0,0,0,0,0,0,0,0,0,0,0,0,0,0,0,0,0,0,0,0,0,0,0,0,0,0,0
0,0,0,0,0,0,0,0,0,0,0,0,19,19,19,19,19,19,19,19,19,0,0,0,0,0,0,0
0,0,0,0,0,0,0,0,0,0,0,19,0,0,0,0,0,0,0,0,0,19,0,0,0,0,0,0
0,0,0,0,0,0,0,0,0,0,19,0,0,0,0,0,0,0,0,0,0,0,19,0,0,0,0,0
0,0,0,0,0,0,0,0,0,19,0,0,0,0,0,0,0,0,0,0,0,0,19,19,0,0,0,0
0,0,0,0,0,0,0,0,0,19,0,0,0,0,0,0,0,0,0,0,0,0,19,19,0,0,0,0
0,0,0,0,0,0,0,0,0,19,0,0,0,0,0,0,0,0,0,0,0,0,19,19,0,0,0,0
0,0,0,0,0,0,0,0,0,19,0,0,0,0,30,30,30,30,0,0,0,0,19,19,0,0,0,0
0,0,0,0,0,0,0,0,0,19,0,0,0,0,30,30,30,30,0,0,0,0,19,19,0,0,0,0
0,0,0,0,0,0,0,0,0,19,0,0,0,0,30,30,30,30,0,0,0,0,19,19,0,0,0,0
0,0,0,0,0,0,0,0,0,19,0,0,0,0,0,0,0,0,0,0,0,0,19,19,0,0,0,0
0,0,0,0,0,0,0,0,0,19,0,0,0,0,0,0,0,0,0,0,0,0,19,19,0,0,0,0
0,0,0,0,0,0,0,0,0,19,0,0,0,0,0,0,0,0,0,0,0,0,19,19,0,0,0,0
0,0,0,0,0,0,0,0,0,0,19,0,0,0,0,0,0,0,0,0,0,0,19,0,0,0,0,0
0,0,0,0,0,0,0,0,0,0,0,19,0,0,0,40,40,40,0,0,0,19,0,0,0,0,0,0
0,0,0,0,0,0,0,0,0,0,0,0,19,19,19,19,19,19,19,19,19,0,0,0,0,0,0,0
0,0,0,0,0,0,0,0,0,0,0,0,0,0,0,0,0,0,0,0,0,0,0,0,0,0,0,0
0,0,0,0,0,0,0,0,0,0,0,0,0,0,0,0,0,0,0,0,0,0,0,0,0,0,0,0
0,0,0,0,0,0,0,0,0,0,0,0,0,0,0,0,0,0,0,0,0,0,0,0,0,0,0,0
endlayer

layer
0,0,0,0,0,0,0,0,0,0,0,0,0,0,0,0,0,0,0,0,0,0,0,0,0,0,0,0
0,0,0,0,0,0,0,0,0,0,0,0,0,0,0,0,0,0,0,0,0,0,0,0,0,0,0,0
0,0,0,0,0,0,0,0,0,0,0,0,0,0,0,0,0,0,0,0,0,0,0,0,0,0,0,0
0,0,0,0,0,0,0,0,0,0,0,0,19,19,19,19,19,19,19,19,19,0,0,0,0,0,0,0
0,0,0,0,0,0,0,0,0,0,0,19,0,0,0,0,0,0,0,0,0,19,0,0,0,0,0,0
0,0,0,0,0,0,0,0,0,0,19,0,0,0,0,0,0,0,0,0,0,0,19,0,0,0,0,0
0,0,0,0,0,0,0,0,0,19,0,0,0,0,0,0,0,0,0,0,0,0,19,19,0,0,0,0
0,0,0,0,0,0,0,0,0,19,0,0,0,0,0,0,0,0,0,0,0,0,19,19,0,0,0,0
0,0,0,0,0,0,0,0,0,19,0,0,0,0,0,0,0,0,0,0,0,0,19,19,0,0,0,0
0,0,0,0,0,0,0,0,0,19,0,0,0,0,0,0,0,0,0,0,0,0,19,19,0,0,0,0
0,0,0,0,0,0,0,0,0,19,0,0,0,0,0,76,76,0,0,0,0,0,19,19,0,0,0,0
0,0,0,0,0,0,0,0,0,19,0,0,0,0,0,0,0,0,0,0,0,0,19,19,0,0,0,0
0,0,0,0,0,0,0,0,0,19,0,0,0,0,0,0,0,0,0,0,0,0,19,19,0,0,0,0
0,0,0,0,0,0,0,0,0,19,0,0,0,0,0,0,0,0,0,0,0,0,19,19,0,0,0,0
0,0,0,0,0,0,0,0,0,19,0,0,0,0,0,0,0,0,0,0,0,0,19,19,0,0,0,0
0,0,0,0,0,0,0,0,0,0,19,0,0,0,0,0,0,0,0,0,0,0,19,0,0,0,0,0
0,0,0,0,0,0,0,0,0,0,0,19,0,0,0,0,0,0,0,0,0,19,0,0,0,0,0,0
0,0,0,0,0,0,0,0,0,0,0,0,19,19,19,19,19,19,19,19,19,0,0,0,0,0,0,0
0,0,0,0,0,0,0,0,0,0,0,0,0,0,0,0,0,0,0,0,0,0,0,0,0,0,0,0
0,0,0,0,0,0,0,0,0,0,0,0,0,0,0,0,0,0,0,0,0,0,0,0,0,0,0,0
0,0,0,0,0,0,0,0,0,0,0,0,0,0,0,0,0,0,0,0,0,0,0,0,0,0,0,0
endlayer

layer
0,0,0,0,0,0,0,0,0,0,0,0,0,0,0,0,0,0,0,0,0,0,0,0,0,0,0,0
0,0,0,0,0,0,0,0,0,0,0,0,0,0,0,0,0,0,0,0,0,0,0,0,0,0,0,0
0,0,0,0,0,0,0,0,0,0,0,0,0,0,0,0,0,0,0,0,0,0,0,0,0,0,0,0
0,0,0,0,0,0,0,0,0,0,0,0,0,0,0,0,0,0,0,0,0,0,0,0,0,0,0,0
0,0,0,0,0,0,0,0,0,0,0,0,19,19,19,19,19,19,19,19,19,0,0,0,0,0,0,0
0,0,0,0,0,0,0,0,0,0,0,19,19,0,0,0,0,0,0,0,19,19,0,0,0,0,0,0
0,0,0,0,0,0,0,0,0,0,19,19,0,0,0,0,0,0,0,0,0,19,19,0,0,0,0,0
0,0,0,0,0,0,0,0,0,0,19,0,0,0,0,0,0,0,0,0,0,0,19,0,0,0,0,0
0,0,0,0,0,0,0,0,0,0,19,0,0,0,0,0,0,0,0,0,0,0,19,0,0,0,0,0
0,0,0,0,0,0,0,0,0,0,19,0,0,0,0,0,0,0,0,0,0,0,19,0,0,0,0,0
0,0,0,0,0,0,0,0,0,0,19,0,0,0,0,76,76,0,0,0,0,0,19,0,0,0,0,0
0,0,0,0,0,0,0,0,0,0,19,0,0,0,0,0,0,0,0,0,0,0,19,0,0,0,0,0
0,0,0,0,0,0,0,0,0,0,19,0,0,0,0,0,0,0,0,0,0,0,19,0,0,0,0,0
0,0,0,0,0,0,0,0,0,0,19,0,0,0,0,0,0,0,0,0,0,0,19,0,0,0,0,0
0,0,0,0,0,0,0,0,0,0,19,19,0,0,0,0,0,0,0,0,0,19,19,0,0,0,0,0
0,0,0,0,0,0,0,0,0,0,0,19,19,0,0,0,0,0,0,0,19,19,0,0,0,0,0,0
0,0,0,0,0,0,0,0,0,0,0,0,19,19,19,19,19,19,19,19,19,0,0,0,0,0,0,0
0,0,0,0,0,0,0,0,0,0,0,0,0,0,0,0,0,0,0,0,0,0,0,0,0,0,0,0
0,0,0,0,0,0,0,0,0,0,0,0,0,0,0,0,0,0,0,0,0,0,0,0,0,0,0,0
0,0,0,0,0,0,0,0,0,0,0,0,0,0,0,0,0,0,0,0,0,0,0,0,0,0,0,0
0,0,0,0,0,0,0,0,0,0,0,0,0,0,0,0,0,0,0,0,0,0,0,0,0,0,0,0
endlayer

layer
0,0,0,0,0,0,0,0,0,0,0,0,0,0,0,0,0,0,0,0,0,0,0,0,0,0,0,0
0,0,0,0,0,0,0,0,0,0,0,0,0,0,0,0,0,0,0,0,0,0,0,0,0,0,0,0
0,0,0,0,0,0,0,0,0,0,0,0,0,0,0,0,0,0,0,0,0,0,0,0,0,0,0,0
0,0,0,0,0,0,0,0,0,0,0,0,0,0,0,0,0,0,0,0,0,0,0,0,0,0,0,0
0,0,0,0,0,0,0,0,0,0,0,0,0,19,19,19,19,19,19,19,0,0,0,0,0,0,0,0
0,0,0,0,0,0,0,0,0,0,0,0,19,0,0,0,0,0,0,0,19,0,0,0,0,0,0,0
0,0,0,0,0,0,0,0,0,0,0,19,0,0,0,0,0,0,0,0,0,19,0,0,0,0,0,0
0,0,0,0,0,0,0,0,0,0,19,0,0,0,0,0,0,0,0,0,0,0,19,0,0,0,0,0
0,0,0,0,0,0,0,0,0,0,19,0,0,0,0,0,0,0,0,0,0,0,19,0,0,0,0,0
0,0,0,0,0,0,0,0,0,0,19,0,0,0,0,0,0,0,0,0,0,0,19,0,0,0,0,0
0,0,0,0,0,0,0,0,0,0,19,0,0,0,0,76,76,0,0,0,0,0,19,0,0,0,0,0
0,0,0,0,0,0,0,0,0,0,19,0,0,0,0,0,0,0,0,0,0,0,19,0,0,0,0,0
0,0,0,0,0,0,0,0,0,0,19,0,0,0,0,0,0,0,0,0,0,0,19,0,0,0,0,0
0,0,0,0,0,0,0,0,0,0,19,0,0,0,0,0,0,0,0,0,0,0,19,0,0,0,0,0
0,0,0,0,0,0,0,0,0,0,0,19,0,0,0,0,0,0,0,0,0,19,0,0,0,0,0,0
0,0,0,0,0,0,0,0,0,0,0,0,19,0,0,0,0,0,0,0,19,0,0,0,0,0,0,0
0,0,0,0,0,0,0,0,0,0,0,0,0,19,19,19,19,19,19,19,0,0,0,0,0,0,0,0
0,0,0,0,0,0,0,0,0,0,0,0,0,0,0,0,0,0,0,0,0,0,0,0,0,0,0,0
0,0,0,0,0,0,0,0,0,0,0,0,0,0,0,0,0,0,0,0,0,0,0,0,0,0,0,0
0,0,0,0,0,0,0,0,0,0,0,0,0,0,0,0,0,0,0,0,0,0,0,0,0,0,0,0
0,0,0,0,0,0,0,0,0,0,0,0,0,0,0,0,0,0,0,0,0,0,0,0,0,0,0,0
endlayer

layer
0,0,0,0,0,0,0,0,0,0,0,0,0,0,0,0,0,0,0,0,0,0,0,0,0,0,0,0
0,0,0,0,0,0,0,0,0,0,0,0,0,0,0,0,0,0,0,0,0,0,0,0,0,0,0,0
0,0,0,0,0,0,0,0,0,0,0,0,0,0,0,0,0,0,0,0,0,0,0,0,0,0,0,0
0,0,0,0,0,0,0,0,0,0,0,0,0,0,0,0,0,0,0,0,0,0,0,0,0,0,0,0
0,0,0,0,0,0,0,0,0,0,0,0,0,0,0,0,0,0,0,0,0,0,0,0,0,0,0,0
0,0,0,0,0,0,0,0,0,0,0,0,0,19,19,19,19,19,19,19,0,0,0,0,0,0,0,0
0,0,0,0,0,0,0,0,0,0,0,0,19,19,0,0,0,0,0,19,19,0,0,0,0,0,0,0
0,0,0,0,0,0,0,0,0,0,0,19,19,0,0,0,0,0,0,0,19,19,0,0,0,0,0,0
0,0,0,0,0,0,0,0,0,0,0,19,0,0,0,0,0,0,0,0,0,19,0,0,0,0,0,0
0,0,0,0,0,0,0,0,0,0,0,19,0,0,0,0,0,0,0,0,0,19,0,0,0,0,0,0
0,0,0,0,0,0,0,0,0,0,0,19,0,0,0,76,76,0,0,0,0,19,0,0,0,0,0,0
0,0,0,0,0,0,0,0,0,0,0,19,0,0,0,0,0,0,0,0,0,19,0,0,0,0,0,0
0,0,0,0,0,0,0,0,0,0,0,19,0,0,0,0,0,0,0,0,0,19,0,0,0,0,0,0
0,0,0,0,0,0,0,0,0,0,0,19,19,0,0,0,0,0,0,0,19,19,0,0,0,0,0,0
0,0,0,0,0,0,0,0,0,0,0,0,19,19,0,0,0,0,0,19,19,0,0,0,0,0,0,0
0,0,0,0,0,0,0,0,0,0,0,0,0,19,19,19,19,19,19,19,0,0,0,0,0,0,0,0
0,0,0,0,0,0,0,0,0,0,0,0,0,0,0,0,0,0,0,0,0,0,0,0,0,0,0,0
0,0,0,0,0,0,0,0,0,0,0,0,0,0,0,0,0,0,0,0,0,0,0,0,0,0,0,0
0,0,0,0,0,0,0,0,0,0,0,0,0,0,0,0,0,0,0,0,0,0,0,0,0,0,0,0
0,0,0,0,0,0,0,0,0,0,0,0,0,0,0,0,0,0,0,0,0,0,0,0,0,0,0,0
0,0,0,0,0,0,0,0,0,0,0,0,0,0,0,0,0,0,0,0,0,0,0,0,0,0,0,0
endlayer

layer
0,0,0,0,0,0,0,0,0,0,0,0,0,0,0,0,0,0,0,0,0,0,0,0,0,0,0,0
0,0,0,0,0,0,0,0,0,0,0,0,0,0,0,0,0,0,0,0,0,0,0,0,0,0,0,0
0,0,0,0,0,0,0,0,0,0,0,0,0,0,0,0,0,0,0,0,0,0,0,0,0,0,0,0
0,0,0,0,0,0,0,0,0,0,0,0,0,0,0,0,0,0,0,0,0,0,0,0,0,0,0,0
0,0,0,0,0,0,0,0,0,0,0,0,0,0,0,0,0,0,0,0,0,0,0,0,0,0,0,0
0,0,0,0,0,0,0,0,0,0,0,0,0,0,0,0,0,0,0,0,0,0,0,0,0,0,0,0
0,0,0,0,0,0,0,0,0,0,0,0,0,0,19,19,19,19,19,0,0,0,0,0,0,0,0,0
0,0,0,0,0,0,0,0,0,0,0,0,0,19,19,0,0,0,19,19,0,0,0,0,0,0,0,0
0,0,0,0,0,0,0,0,0,0,0,0,19,19,0,0,0,0,0,19,19,0,0,0,0,0,0,0
0,0,0,0,0,0,0,0,0,0,0,0,19,0,0,0,0,0,0,0,19,0,0,0,0,0,0,0
0,0,0,0,0,0,0,0,0,0,0,0,19,0,0,76,76,0,0,0,19,0,0,0,0,0,0,0
0,0,0,0,0,0,0,0,0,0,0,0,19,0,0,0,0,0,0,0,19,0,0,0,0,0,0,0
0,0,0,0,0,0,0,0,0,0,0,0,19,19,0,0,0,0,0,19,19,0,0,0,0,0,0,0
0,0,0,0,0,0,0,0,0,0,0,0,0,19,19,0,0,0,19,19,0,0,0,0,0,0,0,0
0,0,0,0,0,0,0,0,0,0,0,0,0,0,19,19,19,19,19,0,0,0,0,0,0,0,0,0
0,0,0,0,0,0,0,0,0,0,0,0,0,0,0,0,0,0,0,0,0,0,0,0,0,0,0,0
0,0,0,0,0,0,0,0,0,0,0,0,0,0,0,0,0,0,0,0,0,0,0,0,0,0,0,0
0,0,0,0,0,0,0,0,0,0,0,0,0,0,0,0,0,0,0,0,0,0,0,0,0,0,0,0
0,0,0,0,0,0,0,0,0,0,0,0,0,0,0,0,0,0,0,0,0,0,0,0,0,0,0,0
0,0,0,0,0,0,0,0,0,0,0,0,0,0,0,0,0,0,0,0,0,0,0,0,0,0,0,0
0,0,0,0,0,0,0,0,0,0,0,0,0,0,0,0,0,0,0,0,0,0,0,0,0,0,0,0
endlayer

layer
0,0,0,0,0,0,0,0,0,0,0,0,0,0,0,0,0,0,0,0,0,0,0,0,0,0,0,0
0,0,0,0,0,0,0,0,0,0,0,0,0,0,0,0,0,0,0,0,0,0,0,0,0,0,0,0
0,0,0,0,0,0,0,0,0,0,0,0,0,0,0,0,0,0,0,0,0,0,0,0,0,0,0,0
0,0,0,0,0,0,0,0,0,0,0,0,0,0,0,0,0,0,0,0,0,0,0,0,0,0,0,0
0,0,0,0,0,0,0,0,0,0,0,0,0,0,0,0,0,0,0,0,0,0,0,0,0,0,0,0
0,0,0,0,0,0,0,0,0,0,0,0,0,0,0,0,0,0,0,0,0,0,0,0,0,0,0,0
0,0,0,0,0,0,0,0,0,0,0,0,0,0,0,0,0,0,0,0,0,0,0,0,0,0,0,0
0,0,0,0,0,0,0,0,0,0,0,0,0,0,19,19,19,19,19,0,0,0,0,0,0,0,0,0
0,0,0,0,0,0,0,0,0,0,0,0,0,19,19,0,0,0,19,19,0,0,0,0,0,0,0,0
0,0,0,0,0,0,0,0,0,0,0,0,0,19,0,0,0,0,0,19,0,0,0,0,0,0,0,0
0,0,0,0,0,0,0,0,0,0,0,0,0,19,0,76,76,0,0,19,0,0,0,0,0,0,0,0
0,0,0,0,0,0,0,0,0,0,0,0,0,19,0,0,0,0,0,19,0,0,0,0,0,0,0,0
0,0,0,0,0,0,0,0,0,0,0,0,0,19,19,0,0,0,19,19,0,0,0,0,0,0,0,0
0,0,0,0,0,0,0,0,0,0,0,0,0,0,19,19,19,19,19,0,0,0,0,0,0,0,0,0
0,0,0,0,0,0,0,0,0,0,0,0,0,0,0,0,0,0,0,0,0,0,0,0,0,0,0,0
0,0,0,0,0,0,0,0,0,0,0,0,0,0,0,0,0,0,0,0,0,0,0,0,0,0,0,0
0,0,0,0,0,0,0,0,0,0,0,0,0,0,0,0,0,0,0,0,0,0,0,0,0,0,0,0
0,0,0,0,0,0,0,0,0,0,0,0,0,0,0,0,0,0,0,0,0,0,0,0,0,0,0,0
0,0,0,0,0,0,0,0,0,0,0,0,0,0,0,0,0,0,0,0,0,0,0,0,0,0,0,0
0,0,0,0,0,0,0,0,0,0,0,0,0,0,0,0,0,0,0,0,0,0,0,0,0,0,0,0
0,0,0,0,0,0,0,0,0,0,0,0,0,0,0,0,0,0,0,0,0,0,0,0,0,0,0,0
endlayer

layer
0,0,0,0,0,0,0,0,0,0,0,0,0,0,0,0,0,0,0,0,0,0,0,0,0,0,0,0
0,0,0,0,0,0,0,0,0,0,0,0,0,0,0,0,0,0,0,0,0,0,0,0,0,0,0,0
0,0,0,0,0,0,0,0,0,0,0,0,0,0,0,0,0,0,0,0,0,0,0,0,0,0,0,0
0,0,0,0,0,0,0,0,0,0,0,0,0,0,0,0,0,0,0,0,0,0,0,0,0,0,0,0
0,0,0,0,0,0,0,0,0,0,0,0,0,0,0,0,0,0,0,0,0,0,0,0,0,0,0,0
0,0,0,0,0,0,0,0,0,0,0,0,0,0,0,0,0,0,0,0,0,0,0,0,0,0,0,0
0,0,0,0,0,0,0,0,0,0,0,0,0,0,0,0,0,0,0,0,0,0,0,0,0,0,0,0
0,0,0,0,0,0,0,0,0,0,0,0,0,0,0,19,19,19,0,0,0,0,0,0,0,0,0,0
0,0,0,0,0,0,0,0,0,0,0,0,0,0,19,0,0,19,19,0,0,0,0,0,0,0,0,0
0,0,0,0,0,0,0,0,0,0,0,0,0,19,0,0,0,0,19,19,0,0,0,0,0,0,0,0
0,0,0,0,0,0,0,0,0,0,0,0,0,19,0,76,76,0,19,19,0,0,0,0,0,0,0,0
0,0,0,0,0,0,0,0,0,0,0,0,0,19,0,0,0,0,19,19,0,0,0,0,0,0,0,0
0,0,0,0,0,0,0,0,0,0,0,0,0,0,19,0,0,0,19,0,0,0,0,0,0,0,0,0
0,0,0,0,0,0,0,0,0,0,0,0,0,0,0,19,19,19,0,0,0,0,0,0,0,0,0,0
0,0,0,0,0,0,0,0,0,0,0,0,0,0,0,0,0,0,0,0,0,0,0,0,0,0,0,0
0,0,0,0,0,0,0,0,0,0,0,0,0,0,0,0,0,0,0,0,0,0,0,0,0,0,0,0
0,0,0,0,0,0,0,0,0,0,0,0,0,0,0,0,0,0,0,0,0,0,0,0,0,0,0,0
0,0,0,0,0,0,0,0,0,0,0,0,0,0,0,0,0,0,0,0,0,0,0,0,0,0,0,0
0,0,0,0,0,0,0,0,0,0,0,0,0,0,0,0,0,0,0,0,0,0,0,0,0,0,0,0
0,0,0,0,0,0,0,0,0,0,0,0,0,0,0,0,0,0,0,0,0,0,0,0,0,0,0,0
0,0,0,0,0,0,0,0,0,0,0,0,0,0,0,0,0,0,0,0,0,0,0,0,0,0,0,0
endlayer

layer
0,0,0,0,0,0,0,0,0,0,0,0,0,0,0,0,0,0,0,0,0,0,0,0,0,0,0,0
0,0,0,0,0,0,0,0,0,0,0,0,0,0,0,0,0,0,0,0,0,0,0,0,0,0,0,0
0,0,0,0,0,0,0,0,0,0,0,0,0,0,0,0,0,0,0,0,0,0,0,0,0,0,0,0
0,0,0,0,0,0,0,0,0,0,0,0,0,0,0,0,0,0,0,0,0,0,0,0,0,0,0,0
0,0,0,0,0,0,0,0,0,0,0,0,0,0,0,0,0,0,0,0,0,0,0,0,0,0,0,0
0,0,0,0,0,0,0,0,0,0,0,0,0,0,0,0,0,0,0,0,0,0,0,0,0,0,0,0
0,0,0,0,0,0,0,0,0,0,0,0,0,0,0,0,0,0,0,0,0,0,0,0,0,0,0,0
0,0,0,0,0,0,0,0,0,0,0,0,0,0,0,0,19,0,0,0,0,0,0,0,0,0,0,0
0,0,0,0,0,0,0,0,0,0,0,0,0,0,19,19,0,19,19,0,0,0,0,0,0,0,0,0
0,0,0,0,0,0,0,0,0,0,0,0,0,0,19,0,0,0,19,0,0,0,0,0,0,0,0,0
0,0,0,0,0,0,0,0,0,0,0,0,0,19,0,76,76,0,0,19,0,0,0,0,0,0,0,0
0,0,0,0,0,0,0,0,0,0,0,0,0,0,19,0,0,0,19,0,0,0,0,0,0,0,0,0
0,0,0,0,0,0,0,0,0,0,0,0,0,0,19,19,0,19,19,0,0,0,0,0,0,0,0,0
0,0,0,0,0,0,0,0,0,0,0,0,0,0,0,0,19,0,0,0,0,0,0,0,0,0,0,0
0,0,0,0,0,0,0,0,0,0,0,0,0,0,0,0,0,0,0,0,0,0,0,0,0,0,0,0
0,0,0,0,0,0,0,0,0,0,0,0,0,0,0,0,0,0,0,0,0,0,0,0,0,0,0,0
0,0,0,0,0,0,0,0,0,0,0,0,0,0,0,0,0,0,0,0,0,0,0,0,0,0,0,0
0,0,0,0,0,0,0,0,0,0,0,0,0,0,0,0,0,0,0,0,0,0,0,0,0,0,0,0
0,0,0,0,0,0,0,0,0,0,0,0,0,0,0,0,0,0,0,0,0,0,0,0,0,0,0,0
0,0,0,0,0,0,0,0,0,0,0,0,0,0,0,0,0,0,0,0,0,0,0,0,0,0,0,0
0,0,0,0,0,0,0,0,0,0,0,0,0,0,0,0,0,0,0,0,0,0,0,0,0,0,0,0
endlayer

layer
0,0,0,0,0,0,0,0,0,0,0,0,0,0,0,0,0,0,0,0,0,0,0,0,0,0,0,0
0,0,0,0,0,0,0,0,0,0,0,0,0,0,0,0,0,0,0,0,0,0,0,0,0,0,0,0
0,0,0,0,0,0,0,0,0,0,0,0,0,0,0,0,0,0,0,0,0,0,0,0,0,0,0,0
0,0,0,0,0,0,0,0,0,0,0,0,0,0,0,0,0,0,0,0,0,0,0,0,0,0,0,0
0,0,0,0,0,0,0,0,0,0,0,0,0,0,0,0,0,0,0,0,0,0,0,0,0,0,0,0
0,0,0,0,0,0,0,0,0,0,0,0,0,0,0,0,0,0,0,0,0,0,0,0,0,0,0,0
0,0,0,0,0,0,0,0,0,0,0,0,0,0,0,0,0,0,0,0,0,0,0,0,0,0,0,0
0,0,0,0,0,0,0,0,0,0,0,0,0,0,0,0,19,0,0,0,0,0,0,0,0,0,0,0
0,0,0,0,0,0,0,0,0,0,0,0,0,0,19,19,0,19,19,0,0,0,0,0,0,0,0,0
0,0,0,0,0,0,0,0,0,0,0,0,0,0,19,0,0,0,19,0,0,0,0,0,0,0,0,0
0,0,0,0,0,0,0,0,0,0,0,0,0,19,30,30,30,30,30,19,0,0,0,0,0,0,0,0
0,0,0,0,0,0,0,0,0,0,0,0,0,0,19,0,0,0,19,0,0,0,0,0,0,0,0,0
0,0,0,0,0,0,0,0,0,0,0,0,0,0,19,19,0,19,19,0,0,0,0,0,0,0,0,0
0,0,0,0,0,0,0,0,0,0,0,0,0,0,0,0,19,0,0,0,0,0,0,0,0,0,0,0
0,0,0,0,0,0,0,0,0,0,0,0,0,0,0,0,0,0,0,0,0,0,0,0,0,0,0,0
0,0,0,0,0,0,0,0,0,0,0,0,0,0,0,0,0,0,0,0,0,0,0,0,0,0,0,0
0,0,0,0,0,0,0,0,0,0,0,0,0,0,0,0,0,0,0,0,0,0,0,0,0,0,0,0
0,0,0,0,0,0,0,0,0,0,0,0,0,0,0,0,0,0,0,0,0,0,0,0,0,0,0,0
0,0,0,0,0,0,0,0,0,0,0,0,0,0,0,0,0,0,0,0,0,0,0,0,0,0,0,0
0,0,0,0,0,0,0,0,0,0,0,0,0,0,0,0,0,0,0,0,0,0,0,0,0,0,0,0
0,0,0,0,0,0,0,0,0,0,0,0,0,0,0,0,0,0,0,0,0,0,0,0,0,0,0,0
endlayer

layer
0,0,0,0,0,0,0,0,0,0,0,0,0,0,0,0,0,0,0,0,0,0,0,0,0,0,0,0
0,0,0,0,0,0,0,0,0,0,0,0,0,0,0,0,0,0,0,0,0,0,0,0,0,0,0,0
0,0,0,0,0,0,0,0,0,0,0,0,0,0,0,0,0,0,0,0,0,0,0,0,0,0,0,0
0,0,0,0,0,0,0,0,0,0,0,0,0,0,0,0,0,0,0,0,0,0,0,0,0,0,0,0
0,0,0,0,0,0,0,0,0,0,0,0,0,0,0,0,0,0,0,0,0,0,0,0,0,0,0,0
0,0,0,0,0,0,0,0,0,0,0,0,0,0,0,0,0,0,0,0,0,0,0,0,0,0,0,0
0,0,0,0,0,0,0,0,0,0,0,0,0,0,0,0,0,0,0,0,0,0,0,0,0,0,0,0
0,0,0,0,0,0,0,0,0,0,0,0,0,0,0,0,0,0,0,0,0,0,0,0,0,0,0,0
0,0,0,0,0,0,0,0,0,0,0,0,0,0,0,19,19,19,0,0,0,0,0,0,0,0,0,0
0,0,0,0,0,0,0,0,0,0,0,0,0,0,19,19,0,19,19,0,0,0,0,0,0,0,0,0
0,0,0,0,0,0,0,0,0,0,0,0,0,0,19,0,77,0,19,0,0,0,0,0,0,0,0,0
0,0,0,0,0,0,0,0,0,0,0,0,0,0,19,19,0,19,19,0,0,0,0,0,0,0,0,0
0,0,0,0,0,0,0,0,0,0,0,0,0,0,0,19,19,19,0,0,0,0,0,0,0,0,0,0
0,0,0,0,0,0,0,0,0,0,0,0,0,0,0,0,0,0,0,0,0,0,0,0,0,0,0,0
0,0,0,0,0,0,0,0,0,0,0,0,0,0,0,0,0,0,0,0,0,0,0,0,0,0,0,0
0,0,0,0,0,0,0,0,0,0,0,0,0,0,0,0,0,0,0,0,0,0,0,0,0,0,0,0
0,0,0,0,0,0,0,0,0,0,0,0,0,0,0,0,0,0,0,0,0,0,0,0,0,0,0,0
0,0,0,0,0,0,0,0,0,0,0,0,0,0,0,0,0,0,0,0,0,0,0,0,0,0,0,0
0,0,0,0,0,0,0,0,0,0,0,0,0,0,0,0,0,0,0,0,0,0,0,0,0,0,0,0
0,0,0,0,0,0,0,0,0,0,0,0,0,0,0,0,0,0,0,0,0,0,0,0,0,0,0,0
0,0,0,0,0,0,0,0,0,0,0,0,0,0,0,0,0,0,0,0,0,0,0,0,0,0,0,0
endlayer

layer
0,0,0,0,0,0,0,0,0,0,0,0,0,0,0,0,0,0,0,0,0,0,0,0,0,0,0,0
0,0,0,0,0,0,0,0,0,0,0,0,0,0,0,0,0,0,0,0,0,0,0,0,0,0,0,0
0,0,0,0,0,0,0,0,0,0,0,0,0,0,0,0,0,0,0,0,0,0,0,0,0,0,0,0
0,0,0,0,0,0,0,0,0,0,0,0,0,0,0,0,0,0,0,0,0,0,0,0,0,0,0,0
0,0,0,0,0,0,0,0,0,0,0,0,0,0,0,0,0,0,0,0,0,0,0,0,0,0,0,0
0,0,0,0,0,0,0,0,0,0,0,0,0,0,0,0,0,0,0,0,0,0,0,0,0,0,0,0
0,0,0,0,0,0,0,0,0,0,0,0,0,0,0,0,0,0,0,0,0,0,0,0,0,0,0,0
0,0,0,0,0,0,0,0,0,0,0,0,0,0,0,0,0,0,0,0,0,0,0,0,0,0,0,0
0,0,0,0,0,0,0,0,0,0,0,0,0,0,0,19,19,19,0,0,0,0,0,0,0,0,0,0
0,0,0,0,0,0,0,0,0,0,0,0,0,0,19,19,0,19,19,0,0,0,0,0,0,0,0,0
0,0,0,0,0,0,0,0,0,0,0,0,0,0,19,0,77,0,19,0,0,0,0,0,0,0,0,0
0,0,0,0,0,0,0,0,0,0,0,0,0,0,19,19,0,19,19,0,0,0,0,0,0,0,0,0
0,0,0,0,0,0,0,0,0,0,0,0,0,0,0,19,19,19,0,0,0,0,0,0,0,0,0,0
0,0,0,0,0,0,0,0,0,0,0,0,0,0,0,0,0,0,0,0,0,0,0,0,0,0,0,0
0,0,0,0,0,0,0,0,0,0,0,0,0,0,0,0,0,0,0,0,0,0,0,0,0,0,0,0
0,0,0,0,0,0,0,0,0,0,0,0,0,0,0,0,0,0,0,0,0,0,0,0,0,0,0,0
0,0,0,0,0,0,0,0,0,0,0,0,0,0,0,0,0,0,0,0,0,0,0,0,0,0,0,0
0,0,0,0,0,0,0,0,0,0,0,0,0,0,0,0,0,0,0,0,0,0,0,0,0,0,0,0
0,0,0,0,0,0,0,0,0,0,0,0,0,0,0,0,0,0,0,0,0,0,0,0,0,0,0,0
0,0,0,0,0,0,0,0,0,0,0,0,0,0,0,0,0,0,0,0,0,0,0,0,0,0,0,0
0,0,0,0,0,0,0,0,0,0,0,0,0,0,0,0,0,0,0,0,0,0,0,0,0,0,0,0
endlayer

layer
0,0,0,0,0,0,0,0,0,0,0,0,0,0,0,0,0,0,0,0,0,0,0,0,0,0,0,0
0,0,0,0,0,0,0,0,0,0,0,0,0,0,0,0,0,0,0,0,0,0,0,0,0,0,0,0
0,0,0,0,0,0,0,0,0,0,0,0,0,0,0,0,0,0,0,0,0,0,0,0,0,0,0,0
0,0,0,0,0,0,0,0,0,0,0,0,0,0,0,0,0,0,0,0,0,0,0,0,0,0,0,0
0,0,0,0,0,0,0,0,0,0,0,0,0,0,0,0,0,0,0,0,0,0,0,0,0,0,0,0
0,0,0,0,0,0,0,0,0,0,0,0,0,0,0,0,0,0,0,0,0,0,0,0,0,0,0,0
0,0,0,0,0,0,0,0,0,0,0,0,0,0,0,0,0,0,0,0,0,0,0,0,0,0,0,0
0,0,0,0,0,0,0,0,0,0,0,0,0,0,0,0,0,0,0,0,0,0,0,0,0,0,0,0
0,0,0,0,0,0,0,0,0,0,0,0,0,0,0,0,19,0,0,0,0,0,0,0,0,0,0,0
0,0,0,0,0,0,0,0,0,0,0,0,0,0,0,19,77,19,0,0,0,0,0,0,0,0,0,0
0,0,0,0,0,0,0,0,0,0,0,0,0,0,19,77,77,77,19,0,0,0,0,0,0,0,0,0
0,0,0,0,0,0,0,0,0,0,0,0,0,0,0,19,77,19,0,0,0,0,0,0,0,0,0,0
0,0,0,0,0,0,0,0,0,0,0,0,0,0,0,0,19,0,0,0,0,0,0,0,0,0,0,0
0,0,0,0,0,0,0,0,0,0,0,0,0,0,0,0,0,0,0,0,0,0,0,0,0,0,0,0
0,0,0,0,0,0,0,0,0,0,0,0,0,0,0,0,0,0,0,0,0,0,0,0,0,0,0,0
0,0,0,0,0,0,0,0,0,0,0,0,0,0,0,0,0,0,0,0,0,0,0,0,0,0,0,0
0,0,0,0,0,0,0,0,0,0,0,0,0,0,0,0,0,0,0,0,0,0,0,0,0,0,0,0
0,0,0,0,0,0,0,0,0,0,0,0,0,0,0,0,0,0,0,0,0,0,0,0,0,0,0,0
0,0,0,0,0,0,0,0,0,0,0,0,0,0,0,0,0,0,0,0,0,0,0,0,0,0,0,0
0,0,0,0,0,0,0,0,0,0,0,0,0,0,0,0,0,0,0,0,0,0,0,0,0,0,0,0
0,0,0,0,0,0,0,0,0,0,0,0,0,0,0,0,0,0,0,0,0,0,0,0,0,0,0,0
endlayer

layer
0,0,0,0,0,0,0,0,0,0,0,0,0,0,0,0,0,0,0,0,0,0,0,0,0,0,0,0
0,0,0,0,0,0,0,0,0,0,0,0,0,0,0,0,0,0,0,0,0,0,0,0,0,0,0,0
0,0,0,0,0,0,0,0,0,0,0,0,0,0,0,0,0,0,0,0,0,0,0,0,0,0,0,0
0,0,0,0,0,0,0,0,0,0,0,0,0,0,0,0,0,0,0,0,0,0,0,0,0,0,0,0
0,0,0,0,0,0,0,0,0,0,0,0,0,0,0,0,0,0,0,0,0,0,0,0,0,0,0,0
0,0,0,0,0,0,0,0,0,0,0,0,0,0,0,0,0,0,0,0,0,0,0,0,0,0,0,0
0,0,0,0,0,0,0,0,0,0,0,0,0,0,0,0,0,0,0,0,0,0,0,0,0,0,0,0
0,0,0,0,0,0,0,0,0,0,0,0,0,0,0,0,0,0,0,0,0,0,0,0,0,0,0,0
0,0,0,0,0,0,0,0,0,0,0,0,0,0,0,0,19,0,0,0,0,0,0,0,0,0,0,0
0,0,0,0,0,0,0,0,0,0,0,0,0,0,0,19,77,19,0,0,0,0,0,0,0,0,0,0
0,0,0,0,0,0,0,0,0,0,0,0,0,0,19,77,77,77,19,0,0,0,0,0,0,0,0,0
0,0,0,0,0,0,0,0,0,0,0,0,0,0,0,19,77,19,0,0,0,0,0,0,0,0,0,0
0,0,0,0,0,0,0,0,0,0,0,0,0,0,0,0,19,0,0,0,0,0,0,0,0,0,0,0
0,0,0,0,0,0,0,0,0,0,0,0,0,0,0,0,0,0,0,0,0,0,0,0,0,0,0,0
0,0,0,0,0,0,0,0,0,0,0,0,0,0,0,0,0,0,0,0,0,0,0,0,0,0,0,0
0,0,0,0,0,0,0,0,0,0,0,0,0,0,0,0,0,0,0,0,0,0,0,0,0,0,0,0
0,0,0,0,0,0,0,0,0,0,0,0,0,0,0,0,0,0,0,0,0,0,0,0,0,0,0,0
0,0,0,0,0,0,0,0,0,0,0,0,0,0,0,0,0,0,0,0,0,0,0,0,0,0,0,0
0,0,0,0,0,0,0,0,0,0,0,0,0,0,0,0,0,0,0,0,0,0,0,0,0,0,0,0
0,0,0,0,0,0,0,0,0,0,0,0,0,0,0,0,0,0,0,0,0,0,0,0,0,0,0,0
0,0,0,0,0,0,0,0,0,0,0,0,0,0,0,0,0,0,0,0,0,0,0,0,0,0,0,0
endlayer

layer
0,0,0,0,0,0,0,0,0,0,0,0,0,0,0,0,0,0,0,0,0,0,0,0,0,0,0,0
0,0,0,0,0,0,0,0,0,0,0,0,0,0,0,0,0,0,0,0,0,0,0,0,0,0,0,0
0,0,0,0,0,0,0,0,0,0,0,0,0,0,0,0,0,0,0,0,0,0,0,0,0,0,0,0
0,0,0,0,0,0,0,0,0,0,0,0,0,0,0,0,0,0,0,0,0,0,0,0,0,0,0,0
0,0,0,0,0,0,0,0,0,0,0,0,0,0,0,0,0,0,0,0,0,0,0,0,0,0,0,0
0,0,0,0,0,0,0,0,0,0,0,0,0,0,0,0,0,0,0,0,0,0,0,0,0,0,0,0
0,0,0,0,0,0,0,0,0,0,0,0,0,0,0,0,0,0,0,0,0,0,0,0,0,0,0,0
0,0,0,0,0,0,0,0,0,0,0,0,0,0,0,0,0,0,0,0,0,0,0,0,0,0,0,0
0,0,0,0,0,0,0,0,0,0,0,0,0,0,0,0,19,0,0,0,0,0,0,0,0,0,0,0
0,0,0,0,0,0,0,0,0,0,0,0,0,0,0,19,77,19,0,0,0,0,0,0,0,0,0,0
0,0,0,0,0,0,0,0,0,0,0,0,0,0,19,77,77,77,19,0,0,0,0,0,0,0,0,0
0,0,0,0,0,0,0,0,0,0,0,0,0,0,0,19,77,19,0,0,0,0,0,0,0,0,0,0
0,0,0,0,0,0,0,0,0,0,0,0,0,0,0,0,19,0,0,0,0,0,0,0,0,0,0,0
0,0,0,0,0,0,0,0,0,0,0,0,0,0,0,0,0,0,0,0,0,0,0,0,0,0,0,0
0,0,0,0,0,0,0,0,0,0,0,0,0,0,0,0,0,0,0,0,0,0,0,0,0,0,0,0
0,0,0,0,0,0,0,0,0,0,0,0,0,0,0,0,0,0,0,0,0,0,0,0,0,0,0,0
0,0,0,0,0,0,0,0,0,0,0,0,0,0,0,0,0,0,0,0,0,0,0,0,0,0,0,0
0,0,0,0,0,0,0,0,0,0,0,0,0,0,0,0,0,0,0,0,0,0,0,0,0,0,0,0
0,0,0,0,0,0,0,0,0,0,0,0,0,0,0,0,0,0,0,0,0,0,0,0,0,0,0,0
0,0,0,0,0,0,0,0,0,0,0,0,0,0,0,0,0,0,0,0,0,0,0,0,0,0,0,0
0,0,0,0,0,0,0,0,0,0,0,0,0,0,0,0,0,0,0,0,0,0,0,0,0,0,0,0
endlayer

layer
0,0,0,0,0,0,0,0,0,0,0,0,0,0,0,0,0,0,0,0,0,0,0,0,0,0,0,0
0,0,0,0,0,0,0,0,0,0,0,0,0,0,0,0,0,0,0,0,0,0,0,0,0,0,0,0
0,0,0,0,0,0,0,0,0,0,0,0,0,0,0,0,0,0,0,0,0,0,0,0,0,0,0,0
0,0,0,0,0,0,0,0,0,0,0,0,0,0,0,0,0,0,0,0,0,0,0,0,0,0,0,0
0,0,0,0,0,0,0,0,0,0,0,0,0,0,0,0,0,0,0,0,0,0,0,0,0,0,0,0
0,0,0,0,0,0,0,0,0,0,0,0,0,0,0,0,0,0,0,0,0,0,0,0,0,0,0,0
0,0,0,0,0,0,0,0,0,0,0,0,0,0,0,0,0,0,0,0,0,0,0,0,0,0,0,0
0,0,0,0,0,0,0,0,0,0,0,0,0,0,0,0,0,0,0,0,0,0,0,0,0,0,0,0
0,0,0,0,0,0,0,0,0,0,0,0,0,0,0,0,19,0,0,0,0,0,0,0,0,0,0,0
0,0,0,0,0,0,0,0,0,0,0,0,0,0,0,19,19,19,0,0,0,0,0,0,0,0,0,0
0,0,0,0,0,0,0,0,0,0,0,0,0,0,19,19,77,19,19,0,0,0,0,0,0,0,0,0
0,0,0,0,0,0,0,0,0,0,0,0,0,0,0,19,19,19,0,0,0,0,0,0,0,0,0,0
0,0,0,0,0,0,0,0,0,0,0,0,0,0,0,0,19,0,0,0,0,0,0,0,0,0,0,0
0,0,0,0,0,0,0,0,0,0,0,0,0,0,0,0,0,0,0,0,0,0,0,0,0,0,0,0
0,0,0,0,0,0,0,0,0,0,0,0,0,0,0,0,0,0,0,0,0,0,0,0,0,0,0,0
0,0,0,0,0,0,0,0,0,0,0,0,0,0,0,0,0,0,0,0,0,0,0,0,0,0,0,0
0,0,0,0,0,0,0,0,0,0,0,0,0,0,0,0,0,0,0,0,0,0,0,0,0,0,0,0
0,0,0,0,0,0,0,0,0,0,0,0,0,0,0,0,0,0,0,0,0,0,0,0,0,0,0,0
0,0,0,0,0,0,0,0,0,0,0,0,0,0,0,0,0,0,0,0,0,0,0,0,0,0,0,0
0,0,0,0,0,0,0,0,0,0,0,0,0,0,0,0,0,0,0,0,0,0,0,0,0,0,0,0
0,0,0,0,0,0,0,0,0,0,0,0,0,0,0,0,0,0,0,0,0,0,0,0,0,0,0,0
endlayer

layer
0,0,0,0,0,0,0,0,0,0,0,0,0,0,0,0,0,0,0,0,0,0,0,0,0,0,0,0
0,0,0,0,0,0,0,0,0,0,0,0,0,0,0,0,0,0,0,0,0,0,0,0,0,0,0,0
0,0,0,0,0,0,0,0,0,0,0,0,0,0,0,0,0,0,0,0,0,0,0,0,0,0,0,0
0,0,0,0,0,0,0,0,0,0,0,0,0,0,0,0,0,0,0,0,0,0,0,0,0,0,0,0
0,0,0,0,0,0,0,0,0,0,0,0,0,0,0,0,0,0,0,0,0,0,0,0,0,0,0,0
0,0,0,0,0,0,0,0,0,0,0,0,0,0,0,0,0,0,0,0,0,0,0,0,0,0,0,0
0,0,0,0,0,0,0,0,0,0,0,0,0,0,0,0,0,0,0,0,0,0,0,0,0,0,0,0
0,0,0,0,0,0,0,0,0,0,0,0,0,0,0,0,0,0,0,0,0,0,0,0,0,0,0,0
0,0,0,0,0,0,0,0,0,0,0,0,0,0,0,0,0,0,0,0,0,0,0,0,0,0,0,0
0,0,0,0,0,0,0,0,0,0,0,0,0,0,0,0,19,0,0,0,0,0,0,0,0,0,0,0
0,0,0,0,0,0,0,0,0,0,0,0,0,0,0,19,77,19,0,0,0,0,0,0,0,0,0,0
0,0,0,0,0,0,0,0,0,0,0,0,0,0,0,0,19,0,0,0,0,0,0,0,0,0,0,0
0,0,0,0,0,0,0,0,0,0,0,0,0,0,0,0,0,0,0,0,0,0,0,0,0,0,0,0
0,0,0,0,0,0,0,0,0,0,0,0,0,0,0,0,0,0,0,0,0,0,0,0,0,0,0,0
0,0,0,0,0,0,0,0,0,0,0,0,0,0,0,0,0,0,0,0,0,0,0,0,0,0,0,0
0,0,0,0,0,0,0,0,0,0,0,0,0,0,0,0,0,0,0,0,0,0,0,0,0,0,0,0
0,0,0,0,0,0,0,0,0,0,0,0,0,0,0,0,0,0,0,0,0,0,0,0,0,0,0,0
0,0,0,0,0,0,0,0,0,0,0,0,0,0,0,0,0,0,0,0,0,0,0,0,0,0,0,0
0,0,0,0,0,0,0,0,0,0,0,0,0,0,0,0,0,0,0,0,0,0,0,0,0,0,0,0
0,0,0,0,0,0,0,0,0,0,0,0,0,0,0,0,0,0,0,0,0,0,0,0,0,0,0,0
0,0,0,0,0,0,0,0,0,0,0,0,0,0,0,0,0,0,0,0,0,0,0,0,0,0,0,0
endlayer

layer
0,0,0,0,0,0,0,0,0,0,0,0,0,0,0,0,0,0,0,0,0,0,0,0,0,0,0,0
0,0,0,0,0,0,0,0,0,0,0,0,0,0,0,0,0,0,0,0,0,0,0,0,0,0,0,0
0,0,0,0,0,0,0,0,0,0,0,0,0,0,0,0,0,0,0,0,0,0,0,0,0,0,0,0
0,0,0,0,0,0,0,0,0,0,0,0,0,0,0,0,0,0,0,0,0,0,0,0,0,0,0,0
0,0,0,0,0,0,0,0,0,0,0,0,0,0,0,0,0,0,0,0,0,0,0,0,0,0,0,0
0,0,0,0,0,0,0,0,0,0,0,0,0,0,0,0,0,0,0,0,0,0,0,0,0,0,0,0
0,0,0,0,0,0,0,0,0,0,0,0,0,0,0,0,0,0,0,0,0,0,0,0,0,0,0,0
0,0,0,0,0,0,0,0,0,0,0,0,0,0,0,0,0,0,0,0,0,0,0,0,0,0,0,0
0,0,0,0,0,0,0,0,0,0,0,0,0,0,0,0,0,0,0,0,0,0,0,0,0,0,0,0
0,0,0,0,0,0,0,0,0,0,0,0,0,0,0,0,19,0,0,0,0,0,0,0,0,0,0,0
0,0,0,0,0,0,0,0,0,0,0,0,0,0,0,19,77,19,0,0,0,0,0,0,0,0,0,0
0,0,0,0,0,0,0,0,0,0,0,0,0,0,0,0,19,0,0,0,0,0,0,0,0,0,0,0
0,0,0,0,0,0,0,0,0,0,0,0,0,0,0,0,0,0,0,0,0,0,0,0,0,0,0,0
0,0,0,0,0,0,0,0,0,0,0,0,0,0,0,0,0,0,0,0,0,0,0,0,0,0,0,0
0,0,0,0,0,0,0,0,0,0,0,0,0,0,0,0,0,0,0,0,0,0,0,0,0,0,0,0
0,0,0,0,0,0,0,0,0,0,0,0,0,0,0,0,0,0,0,0,0,0,0,0,0,0,0,0
0,0,0,0,0,0,0,0,0,0,0,0,0,0,0,0,0,0,0,0,0,0,0,0,0,0,0,0
0,0,0,0,0,0,0,0,0,0,0,0,0,0,0,0,0,0,0,0,0,0,0,0,0,0,0,0
0,0,0,0,0,0,0,0,0,0,0,0,0,0,0,0,0,0,0,0,0,0,0,0,0,0,0,0
0,0,0,0,0,0,0,0,0,0,0,0,0,0,0,0,0,0,0,0,0,0,0,0,0,0,0,0
0,0,0,0,0,0,0,0,0,0,0,0,0,0,0,0,0,0,0,0,0,0,0,0,0,0,0,0
endlayer

layer
0,0,0,0,0,0,0,0,0,0,0,0,0,0,0,0,0,0,0,0,0,0,0,0,0,0,0,0
0,0,0,0,0,0,0,0,0,0,0,0,0,0,0,0,0,0,0,0,0,0,0,0,0,0,0,0
0,0,0,0,0,0,0,0,0,0,0,0,0,0,0,0,0,0,0,0,0,0,0,0,0,0,0,0
0,0,0,0,0,0,0,0,0,0,0,0,0,0,0,0,0,0,0,0,0,0,0,0,0,0,0,0
0,0,0,0,0,0,0,0,0,0,0,0,0,0,0,0,0,0,0,0,0,0,0,0,0,0,0,0
0,0,0,0,0,0,0,0,0,0,0,0,0,0,0,0,0,0,0,0,0,0,0,0,0,0,0,0
0,0,0,0,0,0,0,0,0,0,0,0,0,0,0,0,0,0,0,0,0,0,0,0,0,0,0,0
0,0,0,0,0,0,0,0,0,0,0,0,0,0,0,0,77,77,0,0,0,0,0,0,0,0,0,0
0,0,0,0,0,0,0,0,0,0,0,0,0,0,77,77,77,77,0,0,0,0,0,0,0,0,0,0
0,0,0,0,0,0,0,0,0,0,0,0,0,0,0,0,77,77,0,0,0,0,0,0,0,0,0,0
0,0,0,0,0,0,0,0,0,0,0,0,0,0,77,77,77,0,0,0,0,0,0,0,0,0,0,0
0,0,0,0,0,0,0,0,0,0,0,0,0,0,77,77,77,0,0,0,0,0,0,0,0,0,0,0
0,0,0,0,0,0,0,0,0,0,0,0,0,0,0,0,77,0,0,0,0,0,0,0,0,0,0,0
0,0,0,0,0,0,0,0,0,0,0,0,0,0,0,77,77,0,0,0,0,0,0,0,0,0,0,0
0,0,0,0,0,0,0,0,0,0,0,0,0,0,0,0,77,0,0,0,0,0,0,0,0,0,0,0
0,0,0,0,0,0,0,0,0,0,0,0,0,0,0,0,0,0,0,0,0,0,0,0,0,0,0,0
0,0,0,0,0,0,0,0,0,0,0,0,0,0,0,0,0,0,0,0,0,0,0,0,0,0,0,0
0,0,0,0,0,0,0,0,0,0,0,0,0,0,0,0,0,0,0,0,0,0,0,0,0,0,0,0
0,0,0,0,0,0,0,0,0,0,0,0,0,0,0,0,0,0,0,0,0,0,0,0,0,0,0,0
0,0,0,0,0,0,0,0,0,0,0,0,0,0,0,0,0,0,0,0,0,0,0,0,0,0,0,0
0,0,0,0,0,0,0,0,0,0,0,0,0,0,0,0,0,0,0,0,0,0,0,0,0,0,0,0
endlayer

layer
0,0,0,0,0,0,0,0,0,0,0,0,0,0,0,0,0,0,0,0,0,0,0,0,0,0,0,0
0,0,0,0,0,0,0,0,0,0,0,0,0,0,0,0,0,0,0,0,0,0,0,0,0,0,0,0
0,0,0,0,0,0,0,0,0,0,0,0,0,0,0,0,0,0,0,0,0,0,0,0,0,0,0,0
0,0,0,0,0,0,0,0,0,0,0,0,0,0,0,0,0,0,0,0,0,0,0,0,0,0,0,0
0,0,0,0,0,0,0,0,0,0,0,0,0,0,0,0,0,0,0,0,0,0,0,0,0,0,0,0
0,0,0,0,0,0,0,0,0,0,0,0,0,0,0,0,0,0,0,0,0,0,0,0,0,0,0,0
0,0,0,0,0,0,0,0,0,0,0,0,0,0,0,0,0,0,0,0,0,0,0,0,0,0,0,0
0,0,0,0,0,0,0,0,0,0,0,0,0,0,0,0,77,77,0,0,0,0,0,0,0,0,0,0
0,0,0,0,0,0,0,0,0,0,0,0,0,0,0,0,77,77,0,0,0,0,0,0,0,0,0,0
0,0,0,0,0,0,0,0,0,0,0,0,0,0,0,77,77,77,77,0,0,0,0,0,0,0,0,0
0,0,0,0,0,0,0,0,0,0,0,0,77,77,77,77,77,0,0,0,0,0,0,0,0,0,0,0
0,0,0,0,0,0,0,0,0,0,0,0,77,77,77,77,77,0,0,0,0,0,0,0,0,0,0,0
0,0,0,0,0,0,0,0,0,0,0,0,0,0,0,77,77,0,0,0,0,0,0,0,0,0,0,0
0,0,0,0,0,0,0,0,0,0,0,0,0,0,0,0,77,0,0,0,0,0,0,0,0,0,0,0
0,0,0,0,0,0,0,0,0,0,0,0,0,0,0,0,0,0,0,0,0,0,0,0,0,0,0,0
0,0,0,0,0,0,0,0,0,0,0,0,0,0,0,0,0,0,0,0,0,0,0,0,0,0,0,0
0,0,0,0,0,0,0,0,0,0,0,0,0,0,0,0,0,0,0,0,0,0,0,0,0,0,0,0
0,0,0,0,0,0,0,0,0,0,0,0,0,0,0,0,0,0,0,0,0,0,0,0,0,0,0,0
0,0,0,0,0,0,0,0,0,0,0,0,0,0,0,0,0,0,0,0,0,0,0,0,0,0,0,0
0,0,0,0,0,0,0,0,0,0,0,0,0,0,0,0,0,0,0,0,0,0,0,0,0,0,0,0
0,0,0,0,0,0,0,0,0,0,0,0,0,0,0,0,0,0,0,0,0,0,0,0,0,0,0,0
endlayer

layer
0,0,0,0,0,0,0,0,0,0,0,0,0,0,0,0,0,0,0,0,0,0,0,0,0,0,0,0
0,0,0,0,0,0,0,0,0,0,0,0,0,0,0,0,0,0,0,0,0,0,0,0,0,0,0,0
0,0,0,0,0,0,0,0,0,0,0,0,0,0,0,0,0,0,0,0,0,0,0,0,0,0,0,0
0,0,0,0,0,0,0,0,0,0,0,0,0,0,0,0,0,0,0,0,0,0,0,0,0,0,0,0
0,0,0,0,0,0,0,0,0,0,0,0,0,0,0,0,0,0,0,0,0,0,0,0,0,0,0,0
0,0,0,0,0,0,0,0,0,0,0,0,0,0,0,0,0,0,0,0,0,0,0,0,0,0,0,0
0,0,0,0,0,0,0,0,0,0,0,0,0,0,0,0,0,0,0,0,0,0,0,0,0,0,0,0
0,0,0,0,0,0,0,0,0,0,0,0,0,0,0,0,0,0,0,0,0,0,0,0,0,0,0,0
0,0,0,0,0,0,0,0,0,0,0,0,0,0,0,0,0,0,0,0,0,0,0,0,0,0,0,0
0,0,0,0,0,0,0,0,0,0,0,0,0,0,0,77,77,77,77,0,0,0,0,0,0,0,0,0
0,0,0,0,0,0,0,0,0,0,0,0,0,0,77,0,0,0,0,0,0,0,0,0,0,0,0,0
0,0,0,0,0,0,0,0,0,0,0,0,0,77,77,0,0,0,0,0,0,0,0,0,0,0,0,0
0,0,0,0,0,0,0,0,0,0,0,0,0,0,0,0,0,0,0,0,0,0,0,0,0,0,0,0
0,0,0,0,0,0,0,0,0,0,0,0,0,0,0,0,0,0,0,0,0,0,0,0,0,0,0,0
0,0,0,0,0,0,0,0,0,0,0,0,0,0,0,0,0,0,0,0,0,0,0,0,0,0,0,0
0,0,0,0,0,0,0,0,0,0,0,0,0,0,0,0,0,0,0,0,0,0,0,0,0,0,0,0
0,0,0,0,0,0,0,0,0,0,0,0,0,0,0,0,0,0,0,0,0,0,0,0,0,0,0,0
0,0,0,0,0,0,0,0,0,0,0,0,0,0,0,0,0,0,0,0,0,0,0,0,0,0,0,0
0,0,0,0,0,0,0,0,0,0,0,0,0,0,0,0,0,0,0,0,0,0,0,0,0,0,0,0
0,0,0,0,0,0,0,0,0,0,0,0,0,0,0,0,0,0,0,0,0,0,0,0,0,0,0,0
0,0,0,0,0,0,0,0,0,0,0,0,0,0,0,0,0,0,0,0,0,0,0,0,0,0,0,0
endlayer

