
# Created by Ruins mod version 15.0 Ingame Parser
# authoring Player: SunsOfOld

weight=100
embed_into_distance=6
acceptable_target_blocks=
unacceptable_target_blocks=flowing_water,water,flowing_lava,lava
dimensions=15,18,11
allowable_overhang=4
max_leveling=2
leveling_buffer=0
preserve_water=0
preserve_lava=0
uniqueMinDistance=1000000
preventRotation=1

rule1=0,100,preserveBlock
rule2=0,100,minecraft:bedrock-0
rule3=0,100,CommandBlock:/testfor @p[r=16]:@
rule4=0,100,minecraft:unpowered_comparator-2
rule5=0,100,minecraft:unpowered_repeater-2
rule6=0,100,minecraft:redstone_wire-0
rule7=0,100,minecraft:unpowered_repeater-3
rule8=0,100,CommandBlock:/summon Villager ~ ~5 ~ {CustomName:"I'm bringin' back the railroads!",CustomNameVisible:1,Profession:0,Offers:{Recipes:[{rewardExp:0b,maxUses:2147483647,uses:0,buy:{id:328,Count:1},sell:{id:265,Count:4}},{rewardExp:0b,maxUses:2147483647,uses:0,buy:{id:266,Count:16},sell:{id:343,Count:2}},{rewardExp:0b,maxUses:2147483647,uses:0,buy:{id:66,Count:16},sell:{id:27,Count:4}},{rewardExp:0b,maxUses:2147483647,uses:0,buy:{id:66,Count:6},sell:{id:66,Count:7}}]}}:@
rule9=2,100,minecraft:stone_button-3
rule10=0,100,CommandBlock:/setblock ~ ~ ~ 152:@
rule11=0,100,minecraft:unpowered_repeater-1
rule12=2,100,minecraft:torch-1
rule13=2,100,minecraft:torch-2
rule14=0,100,chisel:concrete-8
rule15=0,100,chisel:concrete-0
rule16=0,100,chisel:concrete-4
rule17=0,100,chisel:limestone_stairs.5-0
rule18=0,100,minecraft:rail-1
rule19=0,100,minecraft:brick_block-0
rule20=0,100,minecraft:rail-0
rule21=0,100,chisel:brickCustom-3
rule22=0,100,chisel:brickCustom-5
rule23=0,100,GardenStuff:lattice-1
rule24=0,100,minecraft:stained_glass_pane-1
rule25=0,100,minecraft:stained_glass_pane-12
rule26=0,100,minecraft:stained_glass_pane-0
rule27=0,100,minecraft:stained_glass_pane-10
rule28=0,100,minecraft:dark_oak_stairs-3
rule29=0,100,minecraft:dark_oak_stairs-2
rule30=0,100,minecraft:dark_oak_stairs-7
rule31=0,100,minecraft:dark_oak_stairs-6
rule32=0,100,minecraft:log2-5
rule33=0,100,minecraft:wooden_slab-13
rule34=0,100,minecraft:wooden_slab-5

layer
1,1,1,1,1,1,1,1,1,1,1
1,1,1,1,1,1,1,1,1,1,1
1,1,1,1,1,1,1,1,1,1,1
1,1,1,1,1,1,1,1,1,1,1
1,1,1,1,1,1,1,1,1,1,1
1,1,1,1,1,1,1,1,1,1,1
1,1,1,1,1,1,1,1,1,1,1
1,1,1,1,1,1,1,1,1,1,1
1,1,1,1,1,1,1,2,1,1,1
1,1,1,1,1,1,1,1,1,1,1
1,1,1,1,1,1,1,1,1,1,1
1,1,1,1,1,1,1,1,1,1,1
1,1,1,1,1,1,1,1,1,1,1
1,1,1,1,1,1,1,1,1,1,1
1,1,1,1,1,1,1,1,1,1,1
1,1,1,1,1,1,1,1,1,1,1
1,1,1,1,1,1,1,1,1,1,1
1,1,1,1,1,1,1,1,1,1,1
endlayer

layer
1,1,1,1,1,1,1,1,1,1,1
1,1,1,1,1,1,1,1,1,1,1
1,1,1,1,1,1,1,1,1,1,1
1,1,1,1,1,1,1,1,1,1,1
1,1,1,1,1,1,1,1,1,1,1
1,1,1,1,1,1,1,1,1,1,1
1,1,1,2,2,2,2,2,2,1,1
1,1,1,2,2,2,2,2,2,1,1
1,1,1,2,2,2,2,0,2,1,1
1,1,1,2,2,2,2,2,2,1,1
1,1,1,2,2,2,2,2,2,1,1
1,1,1,1,1,1,1,1,1,1,1
1,1,1,1,1,1,1,1,1,1,1
1,1,1,1,1,1,1,1,1,1,1
1,1,1,1,1,1,1,1,1,1,1
1,1,1,1,1,1,1,1,1,1,1
1,1,1,1,1,1,1,1,1,1,1
1,1,1,1,1,1,1,1,1,1,1
endlayer

layer
1,1,1,1,1,1,1,1,1,1,1
1,1,1,1,1,1,1,1,1,1,1
1,1,1,1,1,1,1,1,1,1,1
1,1,1,1,1,1,1,1,1,1,1
1,1,1,1,1,1,1,1,1,1,1
1,1,2,2,2,2,2,2,2,1,1
1,1,2,0,6,5,4,3,0,2,1
1,1,2,9,8,0,0,7,0,2,1
1,1,2,0,10,0,2,0,0,2,1
1,1,2,0,11,0,7,11,0,2,1
1,1,2,0,6,6,6,6,0,2,1
1,1,2,2,2,2,2,2,2,1,1
1,1,1,1,1,1,1,1,1,1,1
1,1,1,1,1,1,1,1,1,1,1
1,1,1,1,1,1,1,1,1,1,1
1,1,1,1,1,1,1,1,1,1,1
1,1,1,1,1,1,1,1,1,1,1
1,1,1,1,1,1,1,1,1,1,1
endlayer

layer
1,1,1,1,1,1,1,1,1,1,1
1,1,1,1,1,1,1,1,1,1,1
1,1,1,1,1,1,1,1,1,1,1
1,1,1,1,1,1,1,1,1,1,1
1,1,1,1,1,1,1,1,1,1,1
1,1,2,2,2,2,2,2,2,2,1
1,1,2,0,12,0,0,0,0,2,1
1,1,2,0,6,0,0,0,0,2,1
1,1,2,0,6,0,0,0,0,2,1
1,1,2,0,0,0,0,0,0,2,1
1,1,2,0,0,0,13,0,0,2,1
1,1,2,2,2,2,2,2,2,1,1
1,1,1,1,1,1,1,1,1,1,1
1,1,1,1,1,1,1,1,1,1,1
1,1,1,1,1,1,1,1,1,1,1
1,1,1,1,1,1,1,1,1,1,1
1,1,1,1,1,1,1,1,1,1,1
1,1,1,1,1,1,1,1,1,1,1
endlayer

layer
1,1,1,1,1,1,1,1,1,1,1
1,1,1,1,1,1,1,1,1,1,1
1,1,1,1,1,1,1,1,1,1,1
1,1,1,1,1,1,1,1,1,1,1
1,1,1,1,1,1,1,1,1,1,1
1,1,1,1,1,1,1,1,1,1,1
1,1,1,2,2,2,2,2,2,1,1
1,1,1,2,2,2,2,2,2,1,1
1,1,1,2,2,2,2,2,2,1,1
1,1,1,2,2,2,2,2,2,1,1
1,1,1,2,2,2,2,2,2,1,1
1,1,1,1,1,1,1,1,1,1,1
1,1,1,1,1,1,1,1,1,1,1
1,1,1,1,1,1,1,1,1,1,1
1,1,1,1,1,1,1,1,1,1,1
1,1,1,1,1,1,1,1,1,1,1
1,1,1,1,1,1,1,1,1,1,1
1,1,1,1,1,1,1,1,1,1,1
endlayer

layer
1,1,1,1,1,1,1,1,1,1,1
1,1,1,1,1,1,1,1,1,1,1
1,1,1,1,1,1,1,1,1,1,1
1,1,1,1,1,1,1,1,1,1,1
1,1,1,1,1,1,1,1,1,1,1
1,1,1,1,1,1,1,1,1,1,1
1,1,1,1,1,1,1,1,1,1,1
1,1,1,1,1,1,1,1,1,1,1
1,1,1,1,1,1,1,1,1,1,1
1,1,1,1,1,1,1,1,1,1,1
1,1,1,1,1,1,1,1,1,1,1
1,1,1,1,1,1,1,1,1,1,1
1,1,1,1,1,1,1,1,1,1,1
1,1,1,1,1,1,1,1,1,1,1
1,1,1,1,1,1,1,1,1,1,1
1,1,1,1,1,1,1,1,1,1,1
1,1,1,1,1,1,1,1,1,1,1
1,1,1,1,1,1,1,1,1,1,1
endlayer

layer
14,14,14,14,14,14,14,14,14,14,14
14,14,15,15,15,15,15,15,15,15,14
14,14,15,15,15,15,15,15,15,15,14
14,14,15,15,16,16,16,15,15,15,14
14,15,15,15,16,16,16,15,15,15,14
14,15,15,15,16,16,16,14,15,15,14
14,15,15,15,16,16,16,14,15,15,14
14,15,15,15,16,16,16,14,15,15,14
14,15,15,15,16,16,16,14,15,15,14
14,15,15,15,16,16,16,14,15,15,14
14,15,15,15,16,16,16,14,15,15,14
14,15,15,15,16,16,16,14,15,15,14
14,15,15,15,16,16,16,14,15,15,14
14,15,15,15,16,16,16,14,15,15,14
14,15,15,15,16,16,16,14,15,15,14
14,15,15,15,16,16,16,14,15,15,14
14,15,15,15,16,16,16,14,15,15,14
14,16,16,16,16,16,16,16,16,16,14
endlayer

layer
0,15,15,15,15,15,15,15,15,15,0
0,15,15,15,15,15,15,15,15,15,0
0,15,15,15,14,14,14,15,15,15,0
0,15,15,14,0,0,0,14,15,15,0
0,15,15,14,0,17,0,14,15,15,0
0,15,15,14,0,18,0,14,15,15,0
0,15,15,14,0,18,0,14,15,15,0
0,15,15,14,0,18,0,14,15,15,0
0,15,15,14,0,0,0,14,15,15,0
0,15,15,14,0,0,0,14,15,15,19
0,15,15,14,0,18,0,14,15,15,0
0,15,15,14,0,18,20,14,15,15,0
0,15,15,14,0,18,0,14,15,15,0
0,15,15,14,0,18,0,14,15,15,0
0,15,15,14,0,18,0,14,15,15,0
0,15,15,14,0,18,0,14,15,15,0
0,15,15,14,0,0,0,14,15,15,0
0,15,14,14,0,18,0,14,14,15,0
endlayer

layer
0,21,21,21,21,21,21,21,21,21,0
0,21,0,0,0,0,0,0,0,22,0
0,21,0,0,0,0,0,0,0,22,0
0,21,0,0,0,0,0,0,0,21,0
0,21,0,0,0,0,0,0,0,21,0
0,0,0,0,0,0,0,0,0,21,0
0,22,0,0,0,0,0,0,0,0,0
0,22,0,0,0,0,0,0,0,19,0
0,21,0,0,0,0,0,0,0,21,0
0,21,0,0,0,0,0,0,0,21,0
0,22,0,0,0,0,0,0,0,22,0
0,21,0,0,0,0,0,0,0,19,0
0,21,19,0,0,0,0,0,0,21,0
0,21,0,0,0,0,0,0,0,21,0
0,21,0,0,0,0,0,0,0,19,0
0,22,0,0,0,0,0,0,0,22,0
0,21,0,0,0,0,0,0,0,22,0
0,21,23,23,0,0,0,23,23,21,0
endlayer

layer
0,21,21,27,26,25,0,24,21,21,0
0,21,0,0,0,0,0,0,0,21,0
0,22,0,0,0,0,0,0,0,19,0
0,19,0,0,0,0,0,0,0,22,0
0,21,0,0,0,0,0,0,0,21,0
0,0,0,0,0,0,0,0,0,19,0
0,21,0,0,0,0,0,0,0,0,0
0,19,0,0,0,0,0,0,0,21,0
0,19,0,0,0,0,0,0,0,22,0
0,21,0,0,0,0,0,0,0,0,0
0,21,0,0,0,0,0,0,0,22,0
0,21,0,0,0,0,0,0,0,19,0
0,0,0,0,0,0,0,0,0,21,0
0,21,0,0,0,0,0,0,0,22,0
0,21,0,0,0,0,0,0,0,21,0
0,19,0,0,0,0,0,0,0,19,0
0,19,0,0,0,0,0,0,0,21,0
0,21,23,23,0,0,0,23,23,21,0
endlayer

layer
0,21,21,24,27,24,25,26,21,21,0
0,21,0,0,0,0,0,0,0,21,0
0,22,0,0,0,0,0,0,0,19,0
0,21,0,0,0,0,0,0,0,21,0
0,21,0,0,0,0,0,0,0,21,0
0,0,0,0,0,0,0,0,0,22,0
0,21,0,0,0,0,0,0,0,0,0
0,21,0,0,0,0,0,0,0,21,0
0,22,0,0,0,0,0,0,0,21,0
0,21,0,0,0,0,0,0,0,19,0
0,19,0,0,0,0,0,0,0,21,0
0,19,0,0,0,0,0,0,0,21,0
0,21,0,0,0,0,0,0,0,21,0
0,21,0,0,0,0,0,0,0,22,0
0,22,0,0,0,0,0,0,0,22,0
0,19,0,0,0,0,0,0,0,21,0
0,21,0,0,0,0,0,0,0,21,0
0,21,23,23,23,0,23,23,23,22,0
endlayer

layer
0,28,21,21,21,21,21,22,21,0,0
0,28,31,0,0,0,0,0,30,29,0
0,28,31,0,0,0,0,0,30,29,0
0,28,31,0,0,0,0,0,30,29,0
0,28,31,0,0,0,0,0,30,29,0
0,28,31,0,0,0,0,0,30,29,0
0,28,31,0,0,0,0,0,30,29,0
0,28,31,0,0,0,0,0,30,0,0
0,28,31,0,0,0,0,0,30,29,0
0,28,31,0,0,0,0,0,30,29,0
0,28,31,0,0,0,0,0,30,29,0
0,28,31,0,0,0,0,0,30,29,0
0,0,0,0,0,0,0,0,30,29,0
0,0,0,0,0,0,0,0,30,29,0
0,28,31,0,0,0,0,0,0,29,0
0,28,31,0,0,0,0,0,30,29,0
0,28,31,0,0,0,0,0,30,29,0
0,28,23,23,23,23,23,23,23,29,0
endlayer

layer
0,0,28,21,27,26,25,21,29,0,0
0,0,0,0,0,0,0,30,29,0,0
0,0,28,31,0,0,0,30,29,0,0
0,0,28,31,0,0,0,0,29,0,0
0,0,28,31,0,0,0,0,29,0,0
0,0,28,31,0,0,0,30,29,0,0
0,0,28,31,0,0,0,30,29,0,0
0,0,0,0,0,0,0,30,29,0,0
0,0,0,0,0,0,0,30,29,0,0
0,0,28,31,0,0,0,30,29,0,0
0,0,28,31,0,0,0,0,0,0,0
0,0,28,31,0,0,0,30,29,0,0
0,0,28,31,0,0,0,30,29,0,0
0,0,28,31,0,0,0,30,29,0,0
0,0,28,0,0,0,0,0,0,0,0
0,0,28,31,0,0,0,30,29,0,0
0,0,0,0,0,0,0,30,29,0,0
0,0,28,23,23,23,23,23,29,0,0
endlayer

layer
0,0,0,28,21,21,21,29,0,0,0
0,0,0,28,33,32,0,29,0,0,0
0,0,0,28,33,32,33,29,0,0,0
0,0,0,28,0,32,33,0,0,0,0
0,0,0,0,33,32,33,0,0,0,0
0,0,0,28,33,32,33,29,0,0,0
0,0,0,28,33,32,33,29,0,0,0
0,0,0,28,33,32,33,29,0,0,0
0,0,0,28,33,32,33,29,0,0,0
0,0,0,28,33,32,33,29,0,0,0
0,0,0,28,33,32,33,0,0,0,0
0,0,0,28,33,32,33,29,0,0,0
0,0,0,28,33,32,33,29,0,0,0
0,0,0,28,33,32,33,29,0,0,0
0,0,0,0,33,32,33,29,0,0,0
0,0,0,28,33,32,0,29,0,0,0
0,0,0,28,33,32,33,29,0,0,0
0,0,0,28,33,32,33,29,0,0,0
endlayer

layer
0,0,0,0,34,34,34,0,0,0,0
0,0,0,0,34,34,0,0,0,0,0
0,0,0,0,34,34,34,0,0,0,0
0,0,0,0,0,34,34,0,0,0,0
0,0,0,0,34,34,34,0,0,0,0
0,0,0,0,34,0,34,0,0,0,0
0,0,0,0,34,0,34,0,0,0,0
0,0,0,0,34,34,34,0,0,0,0
0,0,0,0,34,34,34,0,0,0,0
0,0,0,0,0,34,34,0,0,0,0
0,0,0,0,34,34,34,0,0,0,0
0,0,0,0,34,34,34,0,0,0,0
0,0,0,0,34,34,34,0,0,0,0
0,0,0,0,0,0,34,0,0,0,0
0,0,0,0,0,34,34,0,0,0,0
0,0,0,0,34,34,0,0,0,0,0
0,0,0,0,34,34,0,0,0,0,0
0,0,0,0,34,34,34,0,0,0,0
endlayer

