
# Created by Ruins mod version 15.0 Ingame Parser
# authoring Player: SunsOfOld

weight=10
embed_into_distance=8
acceptable_target_blocks=
unacceptable_target_blocks=flowing_water,water,flowing_lava,lava
dimensions=20,22,15
allowable_overhang=0
max_leveling=5
leveling_buffer=0
preserve_water=0
preserve_lava=0
uniqueMinDistance=1000000
preventRotation=1

rule1=0,100,preserveBlock
rule2=0,100,UndergroundBiomes:metamorphicCobblestone-1
rule3=0,100,UndergroundBiomes:metamorphicCobblestone-7
rule4=0,100,minecraft:gravel-0
rule5=0,100,minecraft:crafting_table-0
rule6=0,100,minecraft:jukebox-1
rule7=0,100,minecraft:water-0
rule8=0,100,minecraft:ender_chest-4
rule9=0,100,minecraft:fence-0
rule10=0,100,minecraft:carpet-14
rule11=0,100,IInventory;minecraft:trapped_chest;minecraft:potion#1#0#0+minecraft:potion#1#0#1+minecraft:potion#1#0#2+minecraft:potion#1#0#3+minecraft:potion#1#0#4+minecraft:potion#1#0#5+minecraft:potion#1#0#6+minecraft:potion#1#0#7+minecraft:potion#1#0#8+minecraft:speckled_melon#7#0#9+minecraft:fermented_spider_eye#64#0#10+minecraft:blaze_powder#7#0#11+minecraft:magma_cream#7#0#12+minecraft:glass_bottle#64#0#13+minecraft:glowstone_dust#64#0#14+minecraft:redstone#64#0#15+minecraft:sugar#64#0#16+minecraft:gunpowder#64#0#17+harvestcraft:soybeanseedItem#1#0#18+minecraft:bread#8#0#19+minecraft:cooked_beef#4#0#20+minecraft:book#32#0#21+minecraft:iron_helmet#1#0#22+minecraft:book#32#0#23+minecraft:cookie#4#0#24+minecraft:golden_carrot#16#0#25+harvestcraft:bambooshootseedItem#1#0#26-5
rule12=0,100,IInventory;minecraft:trapped_chest;harvestcraft:whitemushroomseedItem#1#0#0+minecraft:carrot#5#0#1+minecraft:cooked_beef#4#0#2+minecraft:water_bucket#1#0#3+minecraft:iron_chestplate#1#0#4+minecraft:milk_bucket#1#0#5+minecraft:cookie#4#0#6+minecraft:potato#5#0#7+harvestcraft:candleberryseedItem#1#0#8+harvestcraft:ryeseedItem#1#0#9+minecraft:carrot#5#0#10+minecraft:cooked_beef#4#0#11+minecraft:arrow#32#0#12+minecraft:iron_leggings#1#0#13+minecraft:arrow#32#0#14+minecraft:cookie#4#0#15+minecraft:potato#5#0#16+harvestcraft:spinachseedItem#1#0#17+harvestcraft:pamappleSapling#1#0#18+minecraft:carrot#5#0#19+minecraft:cooked_beef#4#0#20+minecraft:diamond_sword#1#0#21+minecraft:iron_boots#1#0#22+minecraft:bow#1#0#23+minecraft:cookie#4#0#24+minecraft:potato#5#0#25+harvestcraft:pamcherrySapling#1#0#26-5
rule13=0,100,IInventory;minecraft:furnace;minecraft:coal#64#0#1-2
rule14=0,100,minecraft:trapdoor-9
rule15=0,100,minecraft:cauldron-3
rule16=0,100,minecraft:bed-10
rule17=0,100,minecraft:bed-2
rule18=0,100,minecraft:ladder-2
rule19=0,100,minecraft:bookshelf-0
rule20=0,100,minecraft:enchanting_table-0
rule21=2,100,minecraft:torch-3
rule22=0,100,minecraft:anvil-6
rule23=0,100,minecraft:trapdoor-2
rule24=2,100,minecraft:torch-2
rule25=0,100,minecraft:wooden_pressure_plate-0
rule26=0,100,minecraft:brewing_stand-0
rule27=0,100,minecraft:dirt-0
rule28=0,100,IInventory;minecraft:chest;minecraft:bone#7#0#4+minecraft:bow#1#7#13+minecraft:spider_eye#1#0#22-2
rule29=0,100,minecraft:vine-4
rule30=0,100,IInventory;minecraft:chest;minecraft:arrow#5#0#2+minecraft:carrot#1#0#4+minecraft:arrow#5#0#6+minecraft:arrow#5#0#12+minecraft:reeds#1#0#13+minecraft:arrow#5#0#14+minecraft:arrow#5#0#22-2
rule31=0,100,minecraft:vine-8
rule32=0,100,minecraft:vine-2
rule33=0,100,minecraft:vine-6
rule34=0,100,minecraft:vine-1
rule35=2,100,minecraft:torch-4
rule36=0,100,minecraft:vine-9
rule37=0,100,minecraft:log-0
rule38=0,100,minecraft:deadbush-0
rule39=0,100,minecraft:leaves-12
rule40=0,100,minecraft:vine-10
rule41=0,100,minecraft:leaves-0
rule42=0,100,minecraft:iron_bars-0
rule43=0,100,minecraft:vine-5
rule44=0,100,minecraft:leaves-4
rule45=0,100,harvestcraft:pamApple-1
rule46=0,100,harvestcraft:pamApple-2
rule47=2,100,minecraft:torch-1
rule48=0,100,minecraft:vine-0

layer
1,1,1,1,1,1,1,1,1,1,1,1,1,1,1
1,1,2,2,2,2,2,2,3,2,2,2,1,1,1
1,1,2,2,2,2,4,4,2,2,2,2,1,1,1
1,1,2,2,2,2,2,2,2,5,2,2,1,1,1
1,1,2,2,2,2,2,2,2,2,2,2,1,1,1
1,1,2,2,2,2,2,2,2,2,2,2,1,1,1
1,1,2,6,2,2,2,2,2,2,2,2,1,1,1
1,1,2,2,2,2,2,2,2,2,2,2,1,1,1
1,1,2,2,2,2,2,2,2,2,2,2,1,1,1
1,1,2,2,2,2,2,2,2,5,2,2,1,1,1
1,1,2,2,2,2,2,8,2,2,7,7,2,1,1
1,1,2,2,2,2,2,2,2,2,7,7,2,1,1
1,1,1,1,1,1,1,1,1,1,2,2,1,1,1
1,1,1,1,1,1,1,1,1,1,1,1,1,1,1
1,1,1,1,1,1,1,1,1,1,1,1,1,1,1
1,1,1,1,1,1,1,1,1,1,1,1,1,1,1
1,1,1,1,1,1,1,1,1,1,1,1,1,1,1
1,1,1,1,1,1,1,1,1,1,1,1,1,1,1
1,1,1,1,1,1,1,1,1,1,1,1,1,1,1
1,1,1,1,1,1,1,1,1,1,1,1,1,1,1
1,1,1,1,1,1,1,1,1,1,1,1,1,1,1
1,1,1,1,1,1,1,1,1,1,1,1,1,1,1
endlayer

layer
1,1,1,1,1,1,1,1,1,1,1,1,1,1,1
1,1,2,2,2,2,2,2,2,2,2,2,1,1,1
1,1,2,13,10,10,12,11,10,9,9,2,1,1,1
1,1,2,13,10,10,10,10,10,0,9,2,1,1,1
1,1,2,13,10,10,10,10,10,10,9,2,1,1,1
1,1,2,13,10,10,10,10,10,10,14,2,1,1,1
1,1,2,18,10,10,10,17,16,10,15,2,1,1,1
1,1,2,19,10,10,10,10,10,10,14,2,1,1,1
1,1,2,19,10,20,10,10,10,10,9,2,1,1,1
1,1,2,19,10,10,10,10,10,0,9,2,1,1,1
1,1,2,19,19,19,19,23,22,9,0,21,2,1,1
1,1,2,2,2,2,2,2,2,2,24,0,2,1,1
1,1,1,1,1,1,1,1,1,1,2,2,1,1,1
1,1,1,1,1,1,1,1,1,1,1,1,1,1,1
1,1,1,1,1,1,1,1,1,1,1,1,1,1,1
1,1,1,1,1,1,1,1,1,1,1,1,1,1,1
1,1,1,1,1,1,1,1,1,1,1,1,1,1,1
1,1,1,1,1,1,1,1,1,1,1,1,1,1,1
1,1,1,1,1,1,1,1,1,1,1,1,1,1,1
1,1,1,1,1,1,1,1,1,1,1,1,1,1,1
1,1,1,1,1,1,1,1,1,1,1,1,1,1,1
1,1,1,1,1,1,1,1,1,1,1,1,1,1,1
endlayer

layer
1,1,1,1,1,1,1,1,1,1,1,1,1,1,1
1,1,2,2,2,2,2,2,2,2,2,2,1,1,1
1,1,2,13,0,0,0,0,0,25,25,2,1,1,1
1,1,2,13,0,0,0,0,0,0,25,2,1,1,1
1,1,2,13,0,0,0,0,0,0,25,2,1,1,1
1,1,2,13,0,0,0,0,0,0,26,2,1,1,1
1,1,2,18,0,0,0,0,0,0,0,2,1,1,1
1,1,2,0,0,0,0,0,0,0,26,2,1,1,1
1,1,2,19,0,0,0,0,0,0,25,2,1,1,1
1,1,2,19,0,0,0,0,0,0,25,2,1,1,1
1,1,2,19,19,19,0,0,0,25,0,2,1,1,1
1,1,2,2,2,2,2,2,2,2,2,2,2,1,1
1,1,1,1,1,1,1,1,1,1,2,2,1,1,1
1,1,1,1,1,1,1,1,1,1,1,1,1,1,1
1,1,1,1,1,1,1,1,1,1,1,1,1,1,1
1,1,1,1,1,1,1,1,1,1,1,1,1,1,1
1,1,1,1,1,1,1,1,1,1,1,1,1,1,1
1,1,1,1,1,1,1,1,1,1,1,1,1,1,1
1,1,1,1,1,1,1,1,1,1,1,1,1,1,1
1,1,1,1,1,1,1,1,1,1,1,1,1,1,1
1,1,1,1,1,1,1,1,1,1,1,1,1,1,1
1,1,1,1,1,1,1,1,1,1,1,1,1,1,1
endlayer

layer
1,1,1,1,1,1,1,1,1,1,1,1,1,1,1
1,1,2,2,2,2,2,2,2,2,2,2,1,1,1
1,1,2,13,0,0,0,0,0,0,0,2,1,1,1
1,1,2,13,0,0,0,0,0,0,0,2,1,1,1
1,1,2,13,0,0,0,0,0,0,0,2,1,1,1
1,1,2,13,0,0,0,0,0,0,0,2,1,1,1
1,1,2,18,0,0,0,0,0,0,0,2,1,1,1
1,1,2,0,0,0,0,0,0,0,0,2,1,1,1
1,1,2,0,0,0,0,0,0,0,0,2,1,1,1
1,1,2,0,0,0,0,0,0,0,0,2,1,1,1
1,1,2,0,0,0,0,0,0,0,0,2,1,1,1
1,1,2,2,2,2,2,2,2,2,2,2,1,1,1
1,1,1,1,1,1,1,1,1,1,2,1,1,1,1
1,1,1,1,1,1,1,1,1,1,1,1,1,1,1
1,1,1,1,1,1,1,1,1,1,1,1,1,1,1
1,1,1,1,1,1,1,1,1,1,1,1,1,1,1
1,1,1,1,1,1,1,1,1,1,1,1,1,1,1
1,1,1,1,1,1,1,1,1,1,1,1,1,1,1
1,1,1,1,1,1,1,1,1,1,1,1,1,1,1
1,1,1,1,1,1,1,1,1,1,1,1,1,1,1
1,1,1,1,1,1,1,1,1,1,1,1,1,1,1
1,1,1,1,1,1,1,1,1,1,1,1,1,1,1
endlayer

layer
1,1,1,1,1,1,1,1,1,1,1,1,1,1,1
1,1,2,2,2,2,2,2,2,2,2,2,1,1,1
1,1,2,2,2,2,2,2,2,2,2,2,1,1,1
1,1,2,2,2,2,2,2,2,2,2,2,1,1,1
1,1,2,2,2,2,2,2,2,2,2,2,1,1,1
1,1,2,2,2,2,2,2,2,2,2,2,1,1,1
1,1,2,18,2,2,2,2,2,2,2,2,1,1,1
1,1,2,2,2,2,2,2,2,2,2,2,1,1,1
1,1,2,2,2,2,2,2,2,2,2,2,1,1,1
1,1,2,2,2,2,2,2,2,2,2,2,1,1,1
1,1,2,2,2,2,2,2,2,2,2,2,1,1,1
1,1,2,2,2,2,2,2,2,2,2,2,1,1,1
1,1,1,1,1,1,1,1,1,1,1,1,1,1,1
1,1,1,1,1,1,1,1,1,1,1,1,1,1,1
1,1,1,1,1,1,1,1,1,1,1,1,1,1,1
1,1,1,1,1,1,1,1,1,1,1,1,1,1,1
1,1,1,1,1,1,1,1,1,1,1,1,1,1,1
1,1,1,1,1,1,1,1,1,1,1,1,1,1,1
1,1,1,1,1,1,1,1,1,1,1,1,1,1,1
1,1,1,1,1,1,1,1,1,1,1,1,1,1,1
1,1,1,1,1,1,1,1,1,1,1,1,1,1,1
1,1,1,1,1,1,1,1,1,1,1,1,1,1,1
endlayer

layer
1,1,1,1,1,1,1,1,1,1,1,1,1,1,1
1,1,27,27,27,27,27,27,27,27,27,27,1,1,1
1,1,27,27,27,27,27,27,27,27,27,27,1,1,1
1,1,27,27,27,27,27,27,27,27,27,27,1,1,1
1,1,2,2,2,2,2,2,2,2,2,27,1,1,1
1,1,2,28,27,27,2,4,4,4,2,27,1,1,1
1,1,2,30,2,0,4,2,29,2,2,27,1,1,1
1,1,2,2,4,4,4,4,31,4,2,27,1,1,1
1,1,2,2,2,2,2,2,2,2,2,27,1,1,1
1,1,27,27,27,27,27,27,27,27,27,27,1,1,1
1,1,27,27,27,27,27,27,27,27,27,27,1,1,1
1,1,27,27,27,27,27,27,27,27,27,27,1,1,1
1,1,1,1,1,1,1,1,1,1,1,1,1,1,1
1,1,1,1,1,1,1,1,1,1,1,1,1,1,1
1,1,1,1,1,1,1,1,1,1,1,1,1,1,1
1,1,1,1,1,1,1,1,1,1,1,1,1,1,1
1,1,1,1,1,1,1,1,1,1,1,1,1,1,1
1,1,1,1,1,1,1,1,1,1,1,1,1,1,1
1,1,1,1,1,1,1,1,1,1,1,1,1,1,1
1,1,1,1,1,1,1,1,1,1,1,1,1,1,1
1,1,1,1,1,1,1,1,1,1,1,1,1,1,1
1,1,1,1,1,1,1,1,1,1,1,1,1,1,1
endlayer

layer
1,1,1,1,1,1,1,1,1,1,1,1,1,1,1
1,1,27,27,27,27,27,27,27,27,27,27,1,1,1
1,1,27,27,27,27,27,27,27,27,27,27,1,1,1
1,1,27,27,27,27,27,27,27,27,27,27,1,1,1
1,1,2,2,2,2,2,2,2,2,2,27,1,1,1
1,1,2,2,0,0,31,32,32,4,2,27,1,1,1
1,1,2,0,0,0,4,34,0,33,2,27,1,1,1
1,1,2,34,31,2,0,31,31,4,2,27,1,1,1
1,1,2,2,2,2,2,2,2,2,2,27,1,1,1
1,1,27,27,27,27,27,27,27,27,27,27,1,1,1
1,1,27,27,27,0,27,27,27,27,27,27,1,1,1
1,1,27,27,27,27,27,27,27,27,27,27,1,1,1
1,1,1,1,1,1,1,1,1,1,1,1,1,1,1
1,1,1,1,1,1,1,1,1,1,1,1,1,1,1
1,1,1,1,1,1,1,1,1,1,1,1,1,1,1
1,1,1,1,1,1,1,1,1,1,1,1,1,1,1
1,1,1,1,1,1,1,1,1,1,1,1,1,1,1
1,1,1,1,1,1,1,1,1,1,1,1,1,1,1
1,1,1,1,1,1,1,1,1,1,1,1,1,1,1
1,1,1,1,1,1,1,1,1,1,1,1,1,1,1
1,1,1,1,1,1,1,1,1,1,1,1,1,1,1
1,1,1,1,1,1,1,1,1,1,1,1,1,1,1
endlayer

layer
1,1,1,1,1,1,1,1,1,1,1,1,1,1,1
1,1,1,1,1,1,1,1,1,1,1,2,1,1,27
1,1,1,1,1,27,1,1,2,1,1,1,1,27,1
1,1,1,1,1,1,1,1,1,1,2,1,27,27,1
1,1,1,2,2,2,2,2,2,2,1,1,1,27,1
1,1,2,34,0,0,0,32,32,29,2,1,1,1,1
1,1,2,35,32,0,4,34,0,33,2,1,1,1,1
1,1,2,34,31,2,24,31,31,31,2,1,27,27,1
1,1,27,2,2,2,2,2,2,2,1,1,1,1,1
1,1,1,1,1,1,1,1,1,1,1,1,1,1,1
1,1,1,1,1,1,1,1,1,1,1,1,1,27,1
1,1,1,1,1,1,1,1,1,1,1,1,1,1,1
1,1,2,1,27,1,1,1,1,1,1,1,1,1,1
1,1,1,27,2,27,1,1,1,1,1,1,1,1,1
1,1,1,27,1,1,1,1,1,1,2,1,27,2,1
1,1,2,1,1,27,1,1,1,1,2,2,2,2,1
1,1,1,1,1,1,1,1,1,1,27,1,1,2,1
1,1,1,1,1,1,27,1,1,1,1,2,1,1,1
1,1,1,2,1,1,1,1,1,1,1,1,2,1,1
1,1,27,1,1,1,1,1,1,1,4,1,1,1,1
1,1,1,1,2,1,1,1,1,1,1,1,1,1,1
1,1,1,1,1,1,1,1,1,1,1,1,1,1,1
endlayer

layer
0,31,0,0,0,0,0,34,0,0,0,0,0,0,0
29,0,0,0,0,0,0,0,2,34,0,0,0,0,0
0,0,0,0,0,37,27,0,36,2,34,0,2,0,27
29,0,0,0,27,27,27,27,2,2,34,0,0,0,0
0,32,31,2,2,2,2,2,2,2,2,2,2,38,0
0,29,2,34,2,2,31,2,2,2,2,2,0,2,0
0,29,2,2,32,2,2,34,2,33,2,27,0,0,0
0,0,2,2,2,2,2,2,2,2,2,2,0,0,27
0,0,37,2,2,2,2,2,2,2,2,2,2,4,0
0,0,39,4,2,2,2,2,2,2,2,2,2,2,0
0,0,2,4,2,2,2,2,34,2,2,2,2,34,0
0,0,0,32,4,2,2,2,34,2,2,2,2,4,0
0,0,29,2,29,4,2,2,2,2,2,2,2,34,2
2,0,0,29,0,0,4,2,2,2,2,2,4,0,0
32,0,0,38,0,29,2,2,2,2,4,2,37,34,0
0,0,29,29,2,37,4,2,29,2,34,32,0,0,0
0,0,4,0,32,4,29,2,34,2,38,0,2,34,0
0,0,29,0,0,0,0,2,2,2,4,32,0,32,32
0,0,0,32,4,29,2,2,2,2,2,34,29,2,0
0,4,37,0,32,0,29,2,2,2,0,4,31,0,0
0,0,0,31,0,0,0,0,2,29,2,34,2,31,0
0,0,29,2,0,29,2,0,0,0,0,0,32,2,0
endlayer

layer
0,31,0,0,0,0,0,34,0,0,0,0,0,0,0
29,0,0,0,0,0,0,0,0,0,0,0,0,0,0
0,0,0,0,0,37,38,0,34,0,0,0,0,0,38
29,0,0,0,31,0,31,31,31,31,0,0,0,0,0
0,32,31,2,2,2,2,2,2,2,34,0,0,0,0
0,29,2,34,2,2,31,32,2,29,2,0,0,0,0
0,29,2,2,32,4,2,34,32,32,40,38,0,0,0
0,39,2,2,2,2,2,40,2,0,2,34,0,0,0
0,39,37,2,2,2,2,2,4,4,2,4,0,0,0
0,0,39,27,4,2,2,4,29,2,2,2,34,0,0
0,0,0,0,29,2,2,4,34,29,2,2,4,0,0
0,0,0,0,31,27,2,4,34,29,2,4,31,31,0
0,0,0,0,0,36,2,0,29,2,4,32,0,0,0
0,0,0,29,0,0,32,36,0,4,2,0,0,0,0
0,0,0,0,0,29,2,0,34,0,32,29,37,34,0
0,0,29,0,29,37,0,0,0,0,0,0,0,0,0
0,0,0,0,0,0,0,0,0,0,0,0,0,0,0
0,0,29,0,0,0,0,36,36,0,0,32,0,32,32
0,0,0,32,32,29,2,0,2,2,2,34,0,0,0
0,0,37,0,0,0,0,32,32,0,0,0,0,0,0
0,0,0,0,0,0,0,0,0,0,0,0,0,0,0
0,0,0,0,0,0,0,0,0,0,0,0,0,0,0
endlayer

layer
0,31,0,0,0,0,0,34,0,0,0,0,0,0,0
29,0,0,41,0,0,0,0,0,0,0,0,0,0,0
0,0,41,41,41,37,0,0,34,0,0,0,0,0,0
29,0,0,41,31,0,31,31,31,31,0,0,0,0,0
0,32,31,2,2,2,2,2,42,2,34,0,0,0,0
0,29,2,34,0,43,0,32,0,29,2,0,0,0,0
0,29,2,2,32,29,0,0,32,32,40,0,0,0,0
0,0,2,2,2,31,2,32,0,0,2,34,0,0,0
44,44,39,2,2,2,2,34,4,0,32,0,0,0,0
44,44,0,32,33,4,2,34,0,29,2,34,0,0,0
0,0,0,0,0,33,2,34,0,29,2,4,0,0,0
0,0,0,0,31,29,2,0,0,0,32,0,31,31,0
0,0,0,0,0,36,32,0,0,0,0,0,0,0,0
0,0,0,29,0,0,0,36,0,0,0,0,0,0,0
0,0,0,0,0,0,0,0,34,0,0,29,37,34,0
0,0,29,0,29,37,0,0,0,0,0,0,0,0,0
0,0,0,0,0,0,0,0,0,0,0,0,0,0,0
0,0,29,0,0,0,0,36,36,0,0,32,0,32,32
0,0,0,32,32,0,29,2,2,2,34,0,0,0,0
0,0,37,0,0,0,0,32,32,0,0,0,0,0,0
0,0,0,0,0,0,0,0,0,0,0,0,0,0,0
0,0,0,0,0,0,0,0,0,0,0,0,0,0,0
endlayer

layer
0,31,41,41,41,0,0,34,0,0,0,0,0,0,0
29,41,41,41,41,41,0,0,0,0,0,0,0,0,0
0,41,41,41,41,37,41,0,34,0,0,0,0,0,0
29,41,41,41,31,41,31,31,31,31,0,0,0,0,0
0,32,31,2,42,2,2,2,42,2,34,0,0,0,0
0,29,2,34,0,43,0,32,0,29,2,0,0,0,0
0,29,42,31,32,29,0,0,32,32,32,0,0,0,0
0,0,2,2,34,31,2,32,0,0,4,34,0,0,0
0,44,32,2,42,2,2,34,0,0,32,0,0,0,0
0,0,0,32,29,2,2,34,0,29,2,34,0,0,0
0,0,0,0,0,32,32,0,0,0,32,0,0,0,0
0,0,0,0,31,29,4,0,0,0,0,0,31,31,0
0,0,0,0,0,36,0,0,0,0,41,41,41,41,41
0,0,0,29,0,0,41,36,0,0,41,41,41,41,41
0,0,0,0,0,0,41,41,34,0,41,41,37,41,41
0,0,29,0,41,37,0,41,0,0,41,41,41,41,41
0,0,0,0,41,0,41,41,0,0,41,41,41,41,41
45,0,29,0,0,0,0,34,36,0,0,32,0,32,32
46,45,0,32,32,0,0,0,2,34,0,0,0,0,0
0,0,37,0,45,0,0,0,32,0,0,0,0,0,0
0,0,46,0,46,0,0,0,0,0,0,0,0,0,0
0,0,0,0,0,0,0,0,0,0,0,0,0,0,0
endlayer

layer
0,31,41,41,41,41,41,34,0,0,0,0,0,0,0
29,41,41,41,41,41,41,41,0,0,0,0,0,0,0
0,41,41,41,41,37,41,41,34,0,0,0,0,0,0
29,41,41,41,31,31,31,31,31,31,0,0,0,0,0
0,32,31,2,2,2,2,2,2,0,34,0,0,0,0
0,29,2,34,47,43,2,2,2,2,2,0,0,0,0
0,29,2,31,32,29,2,2,32,32,32,0,0,0,0
0,0,2,2,34,0,31,32,0,0,0,0,0,0,0
0,0,32,2,2,29,2,34,0,0,0,0,0,0,0
0,0,0,32,29,4,32,0,0,29,4,34,0,0,0
0,0,0,0,0,32,0,0,0,0,32,0,0,0,0
0,0,0,0,31,0,0,0,0,0,0,0,31,0,0
0,0,0,0,0,36,0,0,0,0,0,41,41,41,0
0,0,0,29,41,41,41,36,0,0,41,41,41,41,41
0,0,0,41,39,41,41,41,34,0,41,41,37,41,41
0,0,29,41,39,37,39,44,0,0,41,41,41,41,41
0,0,0,41,39,41,41,41,0,0,0,41,41,41,41
41,41,29,41,41,41,41,34,34,0,0,0,0,32,32
41,41,41,32,32,0,0,0,0,0,0,0,0,0,0
41,41,37,41,41,0,0,0,0,0,0,0,0,0,0
41,41,41,41,41,0,0,0,0,0,0,0,0,0,0
0,41,41,41,0,0,0,0,0,0,0,0,0,0,0
endlayer

layer
0,0,0,0,41,41,41,34,0,0,0,0,0,0,0
0,0,0,41,41,41,41,41,0,0,0,0,0,0,0
0,0,41,41,41,41,41,41,34,0,0,0,0,0,0
0,0,0,41,41,41,41,41,31,31,0,0,0,0,0
0,0,0,0,31,41,29,2,2,0,34,0,0,0,0
0,0,29,2,2,43,2,4,32,32,2,0,0,0,0
0,0,29,2,32,0,32,32,32,32,32,0,0,0,0
0,0,29,2,34,0,0,0,0,0,0,0,0,0,0
0,0,0,32,0,0,0,0,0,0,0,0,0,0,0
0,0,0,0,0,0,0,0,0,0,0,0,0,0,0
0,0,0,0,0,0,0,0,0,0,0,0,0,0,0
0,0,0,0,31,0,0,0,0,0,0,0,0,0,0
0,0,0,0,0,34,0,0,0,0,0,0,0,0,0
0,0,0,0,0,0,0,31,0,0,0,41,41,41,0
0,0,0,0,44,44,0,0,0,0,0,41,37,41,0
0,0,0,0,44,37,0,0,0,0,0,0,41,41,0
0,0,0,0,44,44,44,0,0,0,0,0,0,0,0
0,41,29,41,48,0,0,0,34,0,0,0,0,0,0
41,41,41,32,32,0,0,0,0,0,0,0,0,0,0
41,41,37,41,41,0,0,0,0,0,0,0,0,0,0
41,41,41,41,41,0,0,0,0,0,0,0,0,0,0
0,41,41,41,41,0,0,0,0,0,0,0,0,0,0
endlayer

layer
0,0,0,0,0,0,0,0,0,0,0,0,0,0,0
0,0,0,0,0,41,0,0,0,0,0,0,0,0,0
0,0,0,0,41,41,41,0,0,0,0,0,0,0,0
0,0,0,0,0,41,0,0,31,31,0,0,0,0,0
0,0,0,0,0,0,29,2,42,0,34,0,0,0,0
0,0,0,0,0,29,2,33,32,32,2,0,0,0,0
0,0,0,0,0,0,32,0,32,32,42,0,0,0,0
0,0,0,0,0,0,0,0,0,0,0,0,0,0,0
0,0,0,0,0,0,0,0,0,0,0,0,0,0,0
0,0,0,0,0,0,0,0,0,0,0,0,0,0,0
0,0,0,0,0,0,0,0,0,0,0,0,0,0,0
0,0,0,0,31,0,0,0,0,0,0,0,0,0,0
0,0,0,0,0,34,0,0,0,0,0,0,0,0,0
0,0,0,44,44,0,0,31,0,0,0,0,41,0,0
0,0,0,44,44,44,0,0,0,0,0,41,41,41,0
0,0,0,0,44,37,44,0,0,0,0,0,41,0,0
0,0,0,0,44,44,0,0,0,0,0,0,0,0,0
0,0,29,0,44,44,0,0,34,0,0,0,0,0,0
0,0,41,32,32,0,0,0,0,0,0,0,0,0,0
0,41,37,41,0,0,0,0,0,0,0,0,0,0,0
0,0,41,41,0,0,0,0,0,0,0,0,0,0,0
0,0,0,0,0,0,0,0,0,0,0,0,0,0,0
endlayer

layer
0,0,0,0,0,0,0,0,0,0,0,0,0,0,0
0,0,0,0,0,0,0,0,0,0,0,0,0,0,0
0,0,0,0,0,0,0,0,0,0,0,0,0,0,0
0,0,0,0,0,0,0,0,31,31,0,0,0,0,0
0,0,0,0,0,0,29,2,42,0,34,0,0,0,0
0,0,0,0,0,0,0,33,32,32,2,0,0,0,0
0,0,0,0,0,0,0,0,32,32,42,0,0,0,0
0,0,0,0,0,0,0,0,0,0,0,0,0,0,0
0,0,0,0,0,0,0,0,0,0,0,0,0,0,0
0,0,0,0,0,0,0,0,0,0,0,0,0,0,0
0,0,0,0,0,0,0,0,0,0,0,0,0,0,0
0,0,0,0,31,0,0,0,0,0,0,0,0,0,0
0,0,0,0,39,34,0,0,0,0,0,0,0,0,0
0,0,0,44,41,41,41,31,0,0,0,0,0,0,0
0,0,0,41,41,41,41,41,0,0,0,0,0,0,0
0,0,0,41,41,37,41,41,0,0,0,0,0,0,0
0,0,0,41,41,41,41,41,44,0,0,0,0,0,0
0,0,29,44,41,41,41,44,34,0,0,0,0,0,0
0,0,41,32,32,44,0,0,0,0,0,0,0,0,0
0,41,41,41,0,0,0,0,0,0,0,0,0,0,0
0,0,41,0,0,0,0,0,0,0,0,0,0,0,0
0,0,0,0,0,0,0,0,0,0,0,0,0,0,0
endlayer

layer
0,0,0,0,0,0,0,0,0,0,0,0,0,0,0
0,0,0,0,0,0,0,0,0,0,0,0,0,0,0
0,0,0,0,0,0,0,0,0,0,0,0,0,0,0
0,0,0,0,0,0,0,0,31,31,0,0,0,0,0
0,0,0,0,0,0,0,29,2,2,34,0,0,0,0
0,0,0,0,0,0,0,29,32,32,2,0,0,0,0
0,0,0,0,0,0,0,0,32,32,32,0,0,0,0
0,0,0,0,0,0,0,0,0,0,0,0,0,0,0
0,0,0,0,0,0,0,0,0,0,0,0,0,0,0
0,0,0,0,0,0,0,0,0,0,0,0,0,0,0
0,0,0,0,0,0,0,0,0,0,0,0,0,0,0
0,0,0,0,31,0,0,0,0,0,0,0,0,0,0
0,0,0,44,39,34,39,39,0,0,0,0,0,0,0
0,0,44,44,41,41,41,41,0,0,0,0,0,0,0
0,0,44,41,41,41,41,41,39,0,0,0,0,0,0
0,0,44,41,41,37,41,41,44,0,0,0,0,0,0
0,0,0,41,41,41,41,41,0,0,0,0,0,0,0
0,0,0,44,41,41,41,41,0,0,0,0,0,0,0
0,0,0,44,44,44,0,0,0,0,0,0,0,0,0
0,0,0,0,0,0,0,0,0,0,0,0,0,0,0
0,0,0,0,0,0,0,0,0,0,0,0,0,0,0
0,0,0,0,0,0,0,0,0,0,0,0,0,0,0
endlayer

layer
0,0,0,0,0,0,0,0,0,0,0,0,0,0,0
0,0,0,0,0,0,0,0,0,0,0,0,0,0,0
0,0,0,0,0,0,0,0,0,0,0,0,0,0,0
0,0,0,0,0,0,0,0,31,31,0,0,0,0,0
0,0,0,0,0,0,0,29,2,2,2,0,0,0,0
0,0,0,0,0,0,0,29,2,2,2,0,0,0,0
0,0,0,0,0,0,0,0,32,32,32,0,0,0,0
0,0,0,0,0,0,0,0,0,0,0,0,0,0,0
0,0,0,0,0,0,0,0,0,0,0,0,0,0,0
0,0,0,0,0,0,0,0,0,0,0,0,0,0,0
0,0,0,0,0,0,0,0,0,0,0,0,0,0,0
0,0,0,0,0,0,0,0,0,0,0,0,0,0,0
0,0,0,0,0,0,0,0,0,0,0,0,0,0,0
0,0,0,0,0,39,39,0,0,0,0,0,0,0,0
0,0,0,0,44,41,44,0,0,0,0,0,0,0,0
0,0,0,44,41,37,41,0,0,0,0,0,0,0,0
0,0,0,0,41,41,41,0,0,0,0,0,0,0,0
0,0,0,0,0,0,0,0,0,0,0,0,0,0,0
0,0,0,0,0,0,0,0,0,0,0,0,0,0,0
0,0,0,0,0,0,0,0,0,0,0,0,0,0,0
0,0,0,0,0,0,0,0,0,0,0,0,0,0,0
0,0,0,0,0,0,0,0,0,0,0,0,0,0,0
endlayer

layer
0,0,0,0,0,0,0,0,0,0,0,0,0,0,0
0,0,0,0,0,0,0,0,0,0,0,0,0,0,0
0,0,0,0,0,0,0,0,0,0,0,0,0,0,0
0,0,0,0,0,0,0,0,31,31,0,0,0,0,0
0,0,0,0,0,0,0,29,2,2,0,0,0,0,0
0,0,0,0,0,0,0,0,32,0,2,0,0,0,0
0,0,0,0,0,0,0,0,0,0,32,0,0,0,0
0,0,0,0,0,0,0,0,0,0,0,0,0,0,0
0,0,0,0,0,0,0,0,0,0,0,0,0,0,0
0,0,0,0,0,0,0,0,0,0,0,0,0,0,0
0,0,0,0,0,0,0,0,0,0,0,0,0,0,0
0,0,0,0,0,0,0,0,0,0,0,0,0,0,0
0,0,0,0,0,0,0,0,0,0,0,0,0,0,0
0,0,0,0,0,0,0,0,0,0,0,0,0,0,0
0,0,0,0,0,41,0,0,0,0,0,0,0,0,0
0,0,0,0,41,41,41,0,0,0,0,0,0,0,0
0,0,0,0,0,41,0,0,0,0,0,0,0,0,0
0,0,0,0,0,0,0,0,0,0,0,0,0,0,0
0,0,0,0,0,0,0,0,0,0,0,0,0,0,0
0,0,0,0,0,0,0,0,0,0,0,0,0,0,0
0,0,0,0,0,0,0,0,0,0,0,0,0,0,0
0,0,0,0,0,0,0,0,0,0,0,0,0,0,0
endlayer

layer
0,0,0,0,0,0,0,0,0,0,0,0,0,0,0
0,0,0,0,0,0,0,0,0,0,0,0,0,0,0
0,0,0,0,0,0,0,0,0,0,0,0,0,0,0
0,0,0,0,0,0,0,0,0,0,0,0,0,0,0
0,0,0,0,0,0,0,29,2,0,0,0,0,0,0
0,0,0,0,0,0,0,0,32,0,0,0,0,0,0
0,0,0,0,0,0,0,0,0,0,0,0,0,0,0
0,0,0,0,0,0,0,0,0,0,0,0,0,0,0
0,0,0,0,0,0,0,0,0,0,0,0,0,0,0
0,0,0,0,0,0,0,0,0,0,0,0,0,0,0
0,0,0,0,0,0,0,0,0,0,0,0,0,0,0
0,0,0,0,0,0,0,0,0,0,0,0,0,0,0
0,0,0,0,0,0,0,0,0,0,0,0,0,0,0
0,0,0,0,0,0,0,0,0,0,0,0,0,0,0
0,0,0,0,0,0,0,0,0,0,0,0,0,0,0
0,0,0,0,0,0,0,0,0,0,0,0,0,0,0
0,0,0,0,0,0,0,0,0,0,0,0,0,0,0
0,0,0,0,0,0,0,0,0,0,0,0,0,0,0
0,0,0,0,0,0,0,0,0,0,0,0,0,0,0
0,0,0,0,0,0,0,0,0,0,0,0,0,0,0
0,0,0,0,0,0,0,0,0,0,0,0,0,0,0
0,0,0,0,0,0,0,0,0,0,0,0,0,0,0
endlayer

